Workbook
Name _Buy_America: #REF!
Name _Buy_America: 'CTX Price Book'!$C$68:$C$85
Name _CTX_Category_List: #REF!
Name _CTX_Category_List: 'CTX Price Book'!$I$3:$I$16
Name _CTX_category_List2: #REF!
Name _CTX_Service_Plans: #REF!
Name _CTX_Service_Plans: 'CTX Price Book'!$C$111:$C$131
Name _CTX_Warranty: #REF!
Name _CTX_Warranty: 'CTX Price Book'!$C$95:$C$110
Name _Distributed_System: #REF!
Name _Distributed_System: 'CTX Price Book'!$C$63:$C$67
Name _kW120: #REF!
Name _kW120: 'CTX Price Book'!$C$22:$C$30
Name _kW160: #REF!
Name _kW160: 'CTX Price Book'!$C$31:$C$41
Name _kW180: #REF!
Name _kW180: 'CTX Price Book'!$C$42:$C$46
Name _kW240: #REF!
Name _kW240: 'CTX Price Book'!$C$47:$C$54
Name _kW30: #REF!
Name _kW30: 'CTX Price Book'!$C$13:$C$14
Name _kW360: #REF!
Name _kW360: 'CTX Price Book'!$C$55:$C$62
Name _kW60: #REF!
Name _kW60: 'CTX Price Book'!$C$15:$C$21
Name _L2: #REF!
Name _L2: 'CTX Price Book'!$C$3:$C$12
Name _L2_Accessories: #REF!
Name _L2_Accessories: 'CTX Price Book'!$C$90:$C$94
Name _Pick_First: 'CTX Price Book'!$J$2
Name _V2G: #REF!
Name _V2G: 'CTX Price Book'!$C$86:$C$89
Name Beg_Bal: 'DLL Schedule'!$C$18:$C$497
Name ColumnTitle1: #REF!
Name ColumnTitleRegion1..B12.1: #REF!
Name ColumnTitleRegion2..E12.1: #REF!
Name Company_Name: #REF!
Name Cum_Int: 'DLL Schedule'!$J$18:$J$497
Name cumCashCats: OFFSET('Financial Worksheet'!$D$5,0,0,'Financial Worksheet'!$B$10+1,1)
Name cumCashVals: OFFSET('Financial Worksheet'!$F$5,0,0,'Financial Worksheet'!$B$10+1,1)
Name Data: 'DLL Schedule'!$A$18:$J$497
Name End_Bal: 'DLL Schedule'!$I$18:$I$497
Name Extra_Pay: 'DLL Schedule'!$E$18:$E$497
Name Full_Print: 'DLL Schedule'!$A$1:$J$497
Name Int: 'DLL Schedule'!$H$18:$H$497
Name Interest_Rate: 'DLL Schedule'!$D$6
Name Loan_Amount: 'DLL Schedule'!$D$5
Name Loan_Start: 'DLL Schedule'!$D$9
Name Loan_Years: 'DLL Schedule'!$D$7
Name Num_Pmt_Per_Year: 'DLL Schedule'!$D$8
Name Pay_Date: 'DLL Schedule'!$B$18:$B$497
Name Pay_Num: 'DLL Schedule'!$A$18:$A$497
Name Princ: 'DLL Schedule'!$G$18:$G$497
Name RowTitleRegion1..E5: #REF!
Name Sched_Pay: 'DLL Schedule'!$D$18:$D$497
Name Scheduled_Extra_Payments: 'DLL Schedule'!$D$10
Name Scheduled_Interest_Rate: 'DLL Schedule'!$D$6
Name Scheduled_Monthly_Payment: 'DLL Schedule'!$J$5
Name Total_Interest: 'DLL Schedule'!$J$9
Name Total_Pay: 'DLL Schedule'!$F$18:$F$497

Sheet INPUT SHEET
C2: Charger Input Calculator
B5: CTX Product Selection: | M5: Financial Worksheet Inputs
B6: Start by selecting Category dropdown → (blue cells = your inputs: Category, SKU, Discount %, Qty)
C7: Item # | D7: Category | E7: SKU | F7: Description | G7: MSRP | H7: Discount % | I7: Qty | J7: MSRP Total | K7: Line Total After Discount | N7: Level 2 | O7: L3 Type 1 (DCFC) | P7: L3 Type 2 (DCFC) | Q7: L3 Type 3 (DCFC) | R7: L3 Type 4 (DCFC) | S7: L3 Type 5 (DCFC) | T7: L3 Type 6 (DCFC)
C8: =IF($E8="","",ROW()-7) | D8: _kW120 | E8: TP5-120-480-1 | F8: =IF($E8="","",IFERROR(INDEX('CTX Price Book'!$D:$D,MATCH($E8,'CTX Price Book'!$C:$C,0)),"SKU not found")) | G8: =IF($E8="","",IFERROR(INDEX('CTX Price Book'!$F:$F,MATCH($E8,'CTX Price Book'!$C:$C,0)),"")) | H8: 0.07 | I8: 6 | J8: =IF(E8="","",I8*G8) | K8: =IF(OR($G8="",$I8=""),"",J8-(H8*J8)) | M8: # Chargers (auto from line items) | N8: =SUMIF($D$8:$D$37,"_L2",$I$8:$I$37) -> 0 | O8: =SUMIF($D$8:$D$37,"_kW"&O10,$I$8:$I$37) -> 0 | P8: =SUMIF($D$8:$D$37,"_kW"&P10,$I$8:$I$37) -> 0 | Q8: =SUMIF($D$8:$D$37,"_kW"&Q10,$I$8:$I$37) -> 0 | R8: =SUMIF($D$8:$D$37,"_kW"&R10,$I$8:$I$37) -> 0 | S8: =SUMIF($D$8:$D$37,"_kW"&S10,$I$8:$I$37) -> 0 | T8: =SUMIF($D$8:$D$37,"_kW"&T10,$I$8:$I$37) -> 0
C9: =IF($E9="","",ROW()-7) | F9: =IF($E9="","",IFERROR(INDEX('CTX Price Book'!$D:$D,MATCH($E9,'CTX Price Book'!$C:$C,0)),"SKU not found")) | G9: =IF($E9="","",IFERROR(INDEX('CTX Price Book'!$F:$F,MATCH($E9,'CTX Price Book'!$C:$C,0)),"")) | J9: =IF(E9="","",I9*G9) | K9: =IF(OR($G9="",$I9=""),"",J9-(H9*J9)) | M9: EV Stall Qty (# of ports) | N9: =SUMPRODUCT(($D$8:$D$37="_L2")*(1+ISNUMBER(SEARCH("dual",$F$8:$F$37&"")))*IF($I$8:$I$37="",0,$I$8:$I$37)) -> 0 | O9: =O8*2 -> 0 | P9: =P8*2 -> 0 | Q9: =Q8*2 -> 0 | R9: =R8*2 -> 0 | S9: =S8*2 -> 0 | T9: =T8*2 -> 0
C10: =IF($E10="","",ROW()-7) | F10: =IF($E10="","",IFERROR(INDEX('CTX Price Book'!$D:$D,MATCH($E10,'CTX Price Book'!$C:$C,0)),"SKU not found")) | G10: =IF($E10="","",IFERROR(INDEX('CTX Price Book'!$F:$F,MATCH($E10,'CTX Price Book'!$C:$C,0)),"")) | J10: =IF(E10="","",I10*G10) | K10: =IF(OR($G10="",$I10=""),"",J10-(H10*J10)) | M10: Charger Rating (kW) | N10: 7.2 | O10: 60 | P10: 120 | Q10: 160 | R10: 180 | S10: 240 | T10: 360
C11: =IF($E11="","",ROW()-7) | F11: =IF($E11="","",IFERROR(INDEX('CTX Price Book'!$D:$D,MATCH($E11,'CTX Price Book'!$C:$C,0)),"SKU not found")) | G11: =IF($E11="","",IFERROR(INDEX('CTX Price Book'!$F:$F,MATCH($E11,'CTX Price Book'!$C:$C,0)),"")) | J11: =IF(E11="","",I11*G11) | K11: =IF(OR($G11="",$I11=""),"",J11-(H11*J11)) | M11: Rating de-rate factor (x) | N11: 0.98 | O11: =N11 -> 0.98 | P11: =N11 -> 0.98 | Q11: =$N$11 -> 0.98 | R11: =$N$11 -> 0.98 | S11: =$N$11 -> 0.98 | T11: =$N$11 -> 0.98
C12: =IF($E12="","",ROW()-7) | F12: =IF($E12="","",IFERROR(INDEX('CTX Price Book'!$D:$D,MATCH($E12,'CTX Price Book'!$C:$C,0)),"SKU not found")) | G12: =IF($E12="","",IFERROR(INDEX('CTX Price Book'!$F:$F,MATCH($E12,'CTX Price Book'!$C:$C,0)),"")) | J12: =IF(E12="","",I12*G12) | K12: =IF(OR($G12="",$I12=""),"",J12-(H12*J12))
C13: =IF($E13="","",ROW()-7) | F13: =IF($E13="","",IFERROR(INDEX('CTX Price Book'!$D:$D,MATCH($E13,'CTX Price Book'!$C:$C,0)),"SKU not found")) | G13: =IF($E13="","",IFERROR(INDEX('CTX Price Book'!$F:$F,MATCH($E13,'CTX Price Book'!$C:$C,0)),"")) | J13: =IF(E13="","",I13*G13) | K13: =IF(OR($G13="",$I13=""),"",J13-(H13*J13)) | M13: Tip: # Chargers auto-fills from your line item categories (_L2 and _kW*).
C14: =IF($E14="","",ROW()-7) | F14: =IF($E14="","",IFERROR(INDEX('CTX Price Book'!$D:$D,MATCH($E14,'CTX Price Book'!$C:$C,0)),"SKU not found")) | G14: =IF($E14="","",IFERROR(INDEX('CTX Price Book'!$F:$F,MATCH($E14,'CTX Price Book'!$C:$C,0)),"")) | J14: =IF(E14="","",I14*G14) | K14: =IF(OR($G14="",$I14=""),"",J14-(H14*J14)) | M14: Set the ports and kW rating per level. Revenue uses rating x de-rate factor.
C15: =IF($E15="","",ROW()-7) | F15: =IF($E15="","",IFERROR(INDEX('CTX Price Book'!$D:$D,MATCH($E15,'CTX Price Book'!$C:$C,0)),"SKU not found")) | G15: =IF($E15="","",IFERROR(INDEX('CTX Price Book'!$F:$F,MATCH($E15,'CTX Price Book'!$C:$C,0)),"")) | J15: =IF(E15="","",I15*G15) | K15: =IF(OR($G15="",$I15=""),"",J15-(H15*J15))
C16: =IF($E16="","",ROW()-7) | F16: =IF($E16="","",IFERROR(INDEX('CTX Price Book'!$D:$D,MATCH($E16,'CTX Price Book'!$C:$C,0)),"SKU not found")) | G16: =IF($E16="","",IFERROR(INDEX('CTX Price Book'!$F:$F,MATCH($E16,'CTX Price Book'!$C:$C,0)),"")) | J16: =IF(E16="","",I16*G16) | K16: =IF(OR($G16="",$I16=""),"",J16-(H16*J16)) | M16: Fill this out for CPMS
C17: =IF($E17="","",ROW()-7) | F17: =IF($E17="","",IFERROR(INDEX('CTX Price Book'!$D:$D,MATCH($E17,'CTX Price Book'!$C:$C,0)),"SKU not found")) | G17: =IF($E17="","",IFERROR(INDEX('CTX Price Book'!$F:$F,MATCH($E17,'CTX Price Book'!$C:$C,0)),"")) | J17: =IF(E17="","",I17*G17) | K17: =IF(OR($G17="",$I17=""),"",J17-(H17*J17)) | M17: Address
C18: =IF($E18="","",ROW()-7) | F18: =IF($E18="","",IFERROR(INDEX('CTX Price Book'!$D:$D,MATCH($E18,'CTX Price Book'!$C:$C,0)),"SKU not found")) | G18: =IF($E18="","",IFERROR(INDEX('CTX Price Book'!$F:$F,MATCH($E18,'CTX Price Book'!$C:$C,0)),"")) | J18: =IF(E18="","",I18*G18) | K18: =IF(OR($G18="",$I18=""),"",J18-(H18*J18)) | M18: RSM: RSM: Paul Arms / Brian Rischmann / Dan Koven
C19: =IF($E19="","",ROW()-7) | F19: =IF($E19="","",IFERROR(INDEX('CTX Price Book'!$D:$D,MATCH($E19,'CTX Price Book'!$C:$C,0)),"SKU not found")) | G19: =IF($E19="","",IFERROR(INDEX('CTX Price Book'!$F:$F,MATCH($E19,'CTX Price Book'!$C:$C,0)),"")) | J19: =IF(E19="","",I19*G19) | K19: =IF(OR($G19="",$I19=""),"",J19-(H19*J19)) | M19: Client Info:
C20: =IF($E20="","",ROW()-7) | F20: =IF($E20="","",IFERROR(INDEX('CTX Price Book'!$D:$D,MATCH($E20,'CTX Price Book'!$C:$C,0)),"SKU not found")) | G20: =IF($E20="","",IFERROR(INDEX('CTX Price Book'!$F:$F,MATCH($E20,'CTX Price Book'!$C:$C,0)),"")) | J20: =IF(E20="","",I20*G20) | K20: =IF(OR($G20="",$I20=""),"",J20-(H20*J20)) | M20: Utility
C21: =IF($E21="","",ROW()-7) | F21: =IF($E21="","",IFERROR(INDEX('CTX Price Book'!$D:$D,MATCH($E21,'CTX Price Book'!$C:$C,0)),"SKU not found")) | G21: =IF($E21="","",IFERROR(INDEX('CTX Price Book'!$F:$F,MATCH($E21,'CTX Price Book'!$C:$C,0)),"")) | J21: =IF(E21="","",I21*G21) | K21: =IF(OR($G21="",$I21=""),"",J21-(H21*J21)) | M21: Scope of Work: ie: Client Requests, Amount of chargers, if chargers are dual… Is the client a city?
C22: =IF($E22="","",ROW()-7) | F22: =IF($E22="","",IFERROR(INDEX('CTX Price Book'!$D:$D,MATCH($E22,'CTX Price Book'!$C:$C,0)),"SKU not found")) | G22: =IF($E22="","",IFERROR(INDEX('CTX Price Book'!$F:$F,MATCH($E22,'CTX Price Book'!$C:$C,0)),"")) | J22: =IF(E22="","",I22*G22) | K22: =IF(OR($G22="",$I22=""),"",J22-(H22*J22))
C23: =IF($E23="","",ROW()-7) | F23: =IF($E23="","",IFERROR(INDEX('CTX Price Book'!$D:$D,MATCH($E23,'CTX Price Book'!$C:$C,0)),"SKU not found")) | G23: =IF($E23="","",IFERROR(INDEX('CTX Price Book'!$F:$F,MATCH($E23,'CTX Price Book'!$C:$C,0)),"")) | J23: =IF(E23="","",I23*G23) | K23: =IF(OR($G23="",$I23=""),"",J23-(H23*J23))
C24: =IF($E24="","",ROW()-7) | F24: =IF($E24="","",IFERROR(INDEX('CTX Price Book'!$D:$D,MATCH($E24,'CTX Price Book'!$C:$C,0)),"SKU not found")) | G24: =IF($E24="","",IFERROR(INDEX('CTX Price Book'!$F:$F,MATCH($E24,'CTX Price Book'!$C:$C,0)),"")) | J24: =IF(E24="","",I24*G24) | K24: =IF(OR($G24="",$I24=""),"",J24-(H24*J24))
C25: =IF($E25="","",ROW()-7) | F25: =IF($E25="","",IFERROR(INDEX('CTX Price Book'!$D:$D,MATCH($E25,'CTX Price Book'!$C:$C,0)),"SKU not found")) | G25: =IF($E25="","",IFERROR(INDEX('CTX Price Book'!$F:$F,MATCH($E25,'CTX Price Book'!$C:$C,0)),"")) | J25: =IF(E25="","",I25*G25) | K25: =IF(OR($G25="",$I25=""),"",J25-(H25*J25))
C26: =IF($E26="","",ROW()-7) | F26: =IF($E26="","",IFERROR(INDEX('CTX Price Book'!$D:$D,MATCH($E26,'CTX Price Book'!$C:$C,0)),"SKU not found")) | G26: =IF($E26="","",IFERROR(INDEX('CTX Price Book'!$F:$F,MATCH($E26,'CTX Price Book'!$C:$C,0)),"")) | J26: =IF(E26="","",I26*G26) | K26: =IF(OR($G26="",$I26=""),"",J26-(H26*J26))
C27: =IF($E27="","",ROW()-7) | F27: =IF($E27="","",IFERROR(INDEX('CTX Price Book'!$D:$D,MATCH($E27,'CTX Price Book'!$C:$C,0)),"SKU not found")) | G27: =IF($E27="","",IFERROR(INDEX('CTX Price Book'!$F:$F,MATCH($E27,'CTX Price Book'!$C:$C,0)),"")) | J27: =IF(E27="","",I27*G27) | K27: =IF(OR($G27="",$I27=""),"",J27-(H27*J27)) | M27: Pictures of Site (Max 3, circle the location of the chargers) Give 2 or 3 Possible options for Charger Locations..
C28: =IF($E28="","",ROW()-7) | F28: =IF($E28="","",IFERROR(INDEX('CTX Price Book'!$D:$D,MATCH($E28,'CTX Price Book'!$C:$C,0)),"SKU not found")) | G28: =IF($E28="","",IFERROR(INDEX('CTX Price Book'!$F:$F,MATCH($E28,'CTX Price Book'!$C:$C,0)),"")) | J28: =IF(E28="","",I28*G28) | K28: =IF(OR($G28="",$I28=""),"",J28-(H28*J28))
C29: =IF($E29="","",ROW()-7) | F29: =IF($E29="","",IFERROR(INDEX('CTX Price Book'!$D:$D,MATCH($E29,'CTX Price Book'!$C:$C,0)),"SKU not found")) | G29: =IF($E29="","",IFERROR(INDEX('CTX Price Book'!$F:$F,MATCH($E29,'CTX Price Book'!$C:$C,0)),"")) | J29: =IF(E29="","",I29*G29) | K29: =IF(OR($G29="",$I29=""),"",J29-(H29*J29))
C30: =IF($E30="","",ROW()-7) | F30: =IF($E30="","",IFERROR(INDEX('CTX Price Book'!$D:$D,MATCH($E30,'CTX Price Book'!$C:$C,0)),"SKU not found")) | G30: =IF($E30="","",IFERROR(INDEX('CTX Price Book'!$F:$F,MATCH($E30,'CTX Price Book'!$C:$C,0)),"")) | J30: =IF(E30="","",I30*G30) | K30: =IF(OR($G30="",$I30=""),"",J30-(H30*J30))
C31: =IF($E31="","",ROW()-7) | F31: =IF($E31="","",IFERROR(INDEX('CTX Price Book'!$D:$D,MATCH($E31,'CTX Price Book'!$C:$C,0)),"SKU not found")) | G31: =IF($E31="","",IFERROR(INDEX('CTX Price Book'!$F:$F,MATCH($E31,'CTX Price Book'!$C:$C,0)),"")) | J31: =IF(E31="","",I31*G31) | K31: =IF(OR($G31="",$I31=""),"",J31-(H31*J31))
C32: =IF($E32="","",ROW()-7) | F32: =IF($E32="","",IFERROR(INDEX('CTX Price Book'!$D:$D,MATCH($E32,'CTX Price Book'!$C:$C,0)),"SKU not found")) | G32: =IF($E32="","",IFERROR(INDEX('CTX Price Book'!$F:$F,MATCH($E32,'CTX Price Book'!$C:$C,0)),"")) | J32: =IF(E32="","",I32*G32) | K32: =IF(OR($G32="",$I32=""),"",J32-(H32*J32))
C33: =IF($E33="","",ROW()-7) | F33: =IF($E33="","",IFERROR(INDEX('CTX Price Book'!$D:$D,MATCH($E33,'CTX Price Book'!$C:$C,0)),"SKU not found")) | G33: =IF($E33="","",IFERROR(INDEX('CTX Price Book'!$F:$F,MATCH($E33,'CTX Price Book'!$C:$C,0)),"")) | J33: =IF(E33="","",I33*G33) | K33: =IF(OR($G33="",$I33=""),"",J33-(H33*J33))
C34: =IF($E34="","",ROW()-7) | F34: =IF($E34="","",IFERROR(INDEX('CTX Price Book'!$D:$D,MATCH($E34,'CTX Price Book'!$C:$C,0)),"SKU not found")) | G34: =IF($E34="","",IFERROR(INDEX('CTX Price Book'!$F:$F,MATCH($E34,'CTX Price Book'!$C:$C,0)),"")) | J34: =IF(E34="","",I34*G34) | K34: =IF(OR($G34="",$I34=""),"",J34-(H34*J34))
C35: =IF($E35="","",ROW()-7) | F35: =IF($E35="","",IFERROR(INDEX('CTX Price Book'!$D:$D,MATCH($E35,'CTX Price Book'!$C:$C,0)),"SKU not found")) | G35: =IF($E35="","",IFERROR(INDEX('CTX Price Book'!$F:$F,MATCH($E35,'CTX Price Book'!$C:$C,0)),"")) | J35: =IF(E35="","",I35*G35) | K35: =IF(OR($G35="",$I35=""),"",J35-(H35*J35))
C36: =IF($E36="","",ROW()-7) | F36: =IF($E36="","",IFERROR(INDEX('CTX Price Book'!$D:$D,MATCH($E36,'CTX Price Book'!$C:$C,0)),"SKU not found")) | G36: =IF($E36="","",IFERROR(INDEX('CTX Price Book'!$F:$F,MATCH($E36,'CTX Price Book'!$C:$C,0)),"")) | J36: =IF(E36="","",I36*G36) | K36: =IF(OR($G36="",$I36=""),"",J36-(H36*J36))
C37: =IF($E37="","",ROW()-7) | F37: =IF($E37="","",IFERROR(INDEX('CTX Price Book'!$D:$D,MATCH($E37,'CTX Price Book'!$C:$C,0)),"SKU not found")) | G37: =IF($E37="","",IFERROR(INDEX('CTX Price Book'!$F:$F,MATCH($E37,'CTX Price Book'!$C:$C,0)),"")) | J37: =IF(E37="","",I37*G37) | K37: =IF(OR($G37="",$I37=""),"",J37-(H37*J37))
B38: Grand Total | J38: =SUM(J8:J37) -> 0 | K38: =SUM(K8:K37) -> 0
B40: Instructions
B41: How to use: Pick a Category, then a SKU, using the dropdowns (tip: select the cell and press Alt + ↓ to open a dropdown without clicking the small arrow). Then type the Discount % and Qty in the blue cells. To REMOVE a row: right-click its row number on the left → Delete (rows below shift up automatically). To CLEAR a row in place: select the blue cells in that row and press Delete. To ADD more rows: right-click a row number inside the table → Insert. Fill out CPM INFO Table

Sheet Proposal
B1: ZERO IMPACT SOLUTIONS COSTS BREAKDOWN | G1: Charger cost factor (1.05 contingency x 1.10 markup): | H1: 1
B2: Charger (Parts Only Warranty included: 1 yr AC / 2 yrs DC) | C2: Quantity | D2: Final Cost | E2: Total
B3: =IF('INPUT SHEET'!E8="","",'INPUT SHEET'!F8) | C3: =IF('INPUT SHEET'!E8="","",'INPUT SHEET'!I8) | D3: =IF('INPUT SHEET'!E8="","",'INPUT SHEET'!K8*$H$1 /'INPUT SHEET'!I8*$H$1) | E3: =IF(B3="","",C3*D3)
B4: =IF('INPUT SHEET'!E9="","",'INPUT SHEET'!F9) | C4: =IF('INPUT SHEET'!E9="","",'INPUT SHEET'!I9) | D4: =IF('INPUT SHEET'!E9="","",'INPUT SHEET'!K9*$H$1 /'INPUT SHEET'!I9*$H$1) | E4: =IF(B4="","",C4*D4)
B5: =IF('INPUT SHEET'!E10="","",'INPUT SHEET'!F10) | C5: =IF('INPUT SHEET'!E10="","",'INPUT SHEET'!I10) | D5: =IF('INPUT SHEET'!E10="","",'INPUT SHEET'!K10*$H$1 /'INPUT SHEET'!I10*$H$1) | E5: =IF(B5="","",C5*D5)
B6: =IF('INPUT SHEET'!E11="","",'INPUT SHEET'!F11) | C6: =IF('INPUT SHEET'!E11="","",'INPUT SHEET'!I11) | D6: =IF('INPUT SHEET'!E11="","",'INPUT SHEET'!K11*$H$1 /'INPUT SHEET'!I11*$H$1) | E6: =IF(B6="","",C6*D6)
B7: =IF('INPUT SHEET'!E12="","",'INPUT SHEET'!F12) | C7: =IF('INPUT SHEET'!E12="","",'INPUT SHEET'!I12) | D7: =IF('INPUT SHEET'!E12="","",'INPUT SHEET'!K12*$H$1 /'INPUT SHEET'!I12*$H$1) | E7: =IF(B7="","",C7*D7)
B8: =IF('INPUT SHEET'!E13="","",'INPUT SHEET'!F13) | C8: =IF('INPUT SHEET'!E13="","",'INPUT SHEET'!I13) | D8: =IF('INPUT SHEET'!E13="","",'INPUT SHEET'!K13*$H$1 /'INPUT SHEET'!I13*$H$1) | E8: =IF(B8="","",C8*D8)
B9: =IF('INPUT SHEET'!E14="","",'INPUT SHEET'!F14) | C9: =IF('INPUT SHEET'!E14="","",'INPUT SHEET'!I14) | D9: =IF('INPUT SHEET'!E14="","",'INPUT SHEET'!K14*$H$1 /'INPUT SHEET'!I14*$H$1) | E9: =IF(B9="","",C9*D9)
B10: =IF('INPUT SHEET'!E15="","",'INPUT SHEET'!F15) | C10: =IF('INPUT SHEET'!E15="","",'INPUT SHEET'!I15) | D10: =IF('INPUT SHEET'!E15="","",'INPUT SHEET'!K15*$H$1 /'INPUT SHEET'!I15*$H$1) | E10: =IF(B10="","",C10*D10)
B11: =IF('INPUT SHEET'!E16="","",'INPUT SHEET'!F16) | C11: =IF('INPUT SHEET'!E16="","",'INPUT SHEET'!I16) | D11: =IF('INPUT SHEET'!E16="","",'INPUT SHEET'!K16*$H$1 /'INPUT SHEET'!I16*$H$1) | E11: =IF(B11="","",C11*D11)
B12: =IF('INPUT SHEET'!E17="","",'INPUT SHEET'!F17) | C12: =IF('INPUT SHEET'!E17="","",'INPUT SHEET'!I17) | D12: =IF('INPUT SHEET'!E17="","",'INPUT SHEET'!K17*$H$1 /'INPUT SHEET'!I17*$H$1) | E12: =IF(B12="","",C12*D12)
B13: Total Cost of EVSE | E13: ='Internal Summary'!D4 -> 0
B14: Electrical Supply & Construction Management Costs | C14: Quantity | D14: Final Cost | E14: Total after Discount
B15: Wires, Conduits and Peripherals | C15: =IF(N(D15)=0,0,1) -> 0 | D15: ='Internal Summary'!D14 -> 0 | E15: =C15*D15 -> 0
B16: Main Distribution Switchgear | C16: =IF(N(D16)=0,0,1) -> 0 | D16: ='Internal Summary'!D15 -> 0 | E16: =C16*D16 -> 0
B17: Electrical Sub-Panels, Transformers, Breakers | C17: =IF(N(D17)=0,0,1) -> 0 | D17: ='Internal Summary'!D16 -> 0 | E17: =C17*D17 -> 0
B18: Striping, Bollards, Signage | C18: =IF(N(D18)=0,0,1) -> 0 | D18: ='Internal Summary'!D17 -> 0 | E18: =C18*D18 -> 0
B19: Permits | C19: =IF(N(D19)=0,0,1) -> 0 | D19: ='Internal Summary'!D22 -> 0 | E19: =C19*D19 -> 0
B20: Designs and Engineering | C20: =IF(N(D20)=0,0,1) -> 0 | D20: ='Internal Summary'!D8 -> 0 | E20: =C20*D20 -> 0
B21: Construction Equipment | C21: =IF(N(D21)=0,0,1) -> 0 | D21: ='Internal Summary'!D24 -> 0 | E21: =C21*D21 -> 0
B22: Material Costs | C22: =IF(N(D22)=0,0,1) -> 0 | D22: ='Internal Summary'!D26 -> 0 | E22: =C22*D22 -> 0
B23: Miscellaneous | C23: =IF(N(D23)=0,0,1) -> 0 | D23: =SUM('Internal Summary'!D18:D21,'Internal Summary'!D23,'Internal Summary'!D25:D27) -'Internal Summary'!D26 -> 0 | E23: =C23*D23 -> 0
B24: Total Cost of Supply & Management | E24: =SUM(E15:E23) -> 0
B25: EVOLV platform costs (Calculated Yearly) | C25: Quantity | D25: Final Cost | E25: Total
B26: Monthly Network Cloud Services Fees (Per Port) | C26: ='INPUT SHEET'!N9 -> 0 | D26: 39.99 | E26: =C26*D26*12 -> 0
B27: # of years for duration of contract | C27: ='Internal Summary'!G4 -> 5 | E27: =C27*E26 -> 0
D28: Evolv Total Cost | E28: ='Internal Summary'!D6 -> 0
D29: Subtotal | E29: ='Internal Summary'!D6 +E24+E13 -> 0
D30: Tax | E30: ='Internal Summary'!D7 -> 0
D31: Rebate | E31: =0 -> 0
D32: Total | E32: =E29+E30 -> 0
B34: ZERO IMPACT BUILDERS COSTS BREAKDOWN
B35: Labor Days | C35: ='INPUT SHEET CPM'!P11 -> 30 | D35: 2772.5 | E35: =C35*D35 -> 83175
B36: Total Labor Costs | E36: =IF('Internal Summary'!D28<>"", 'Internal Summary'!D28, E35) -> 0
B37: Servicing Fees (Yearly calculation) | C37: Quantity | D37: Final Cost | E37: Total
B38: Service Plan - all chargers (every year) | C38: ='Internal Summary'!G11 -> 5 | D38: ='Internal Summary'!H11 -> 0 | E38: =C38*D38 -> 0
B39: Warranty - AC chargers (after free period) | C39: ='Internal Summary'!G12 -> 4 | D39: ='Internal Summary'!H12 -> 0 | E39: =C39*D39 -> 0
B40: Warranty - DC chargers (after free period) | C40: ='Internal Summary'!G13 -> 3 | D40: ='Internal Summary'!H13 -> 0 | E40: =C40*D40 -> 0
B41: Total | E41: ='Internal Summary'!D5+E36 -> 0
...

Sheet Internal Summary
B2: Price | C2: Applied Discount | D2: Customer Price | F2: EVOLV platform costs (Calculated Yearly) | G2: Quantity | H2: Final Cost | I2: Total
A3: Equipment Purchase Invoice (Finance) | B3: =SUM(B4:B7) -> 0 | C3: =IF((B3)=0,0,1-D3/(B3)) -> 0 | D3: =SUM(D4:D7) -> 0 | F3: Monthly Network Cloud Services Fees (Per Port) | G3: =SUM('INPUT SHEET'!N9:T9) -> 0 | H3: 39.99 | I3: =H3*G3*12 -> 0
A4: Charger Hardware | B4: ='INPUT SHEET'!J38 -> 0 | C4: =IF(B4=0,0,(100 -('INPUT SHEET'!K38/'INPUT SHEET'!J38 *100)))*0.01 -> 0 | D4: =(B4)-((B4)*C4) -> 0 | F4: # of years for duration of contract | G4: 5
A5: 5 Year Service Agreement + Warranty | B5: =I14 -> 0 | C5: 0 | D5: =(B5)-((B5)*C5) -> 0 | H5: Subtotal | I5: =G4*I3 -> 0
A6: EVOLV & Commissioning Subtotal | B6: =I5 -> 0 | C6: 0 | D6: =(B6)-((B6)*C6) -> 0
A7: Sales Tax on Chargers | B7: =D4*7.25% -> 0 | C7: 0 | D7: =(B7)-((B7)*C7) -> 0
A8: Design Invoice (Finance) | B8: =SUM(B9:B12) -> 0 | C8: =IF((B8)=0,0,1-D8/(B8)) -> 0 | D8: =SUM(D9:D12) -> 0
A9: AutoCad Design Services | B9: 0 | C9: 0 | D9: =(B9)-((B9)*C9) -> 0 | G9: Servicing Fees
A10: Electrical Engineering Design | B10: 0 | C10: 0 | D10: =(B10)-((B10)*C10) -> 0 | G10: Quantity | H10: Cost | I10: Total
A11: Project Management | B11: 0 | C11: 0 | D11: =(B11)-((B11)*C11) -> 0 | F11: Service Plan - all chargers (every year) | G11: =$G$16 -> 5 | H11: =SUMPRODUCT('CTX Price Book'!$C$135:$C$144,'CTX Price Book'!$E$135:$E$144) -> 0 | I11: =G11*H11 -> 0
A12: Plan Check and Permit Fees | B12: 0 | C12: 0 | D12: =(B12)-((B12)*C12) -> 0 | F12: Warranty - AC chargers (after free period) | G12: =MAX(0,$G$16-'CTX Price Book'!$I$135) -> 4 | H12: =SUMPRODUCT('CTX Price Book'!$C$135:$C$138,'CTX Price Book'!$D$135:$D$138) -> 0 | I12: =G12*H12 -> 0
A13: Electrical Supply & Construction Management Costs | B13: =SUM(B14:B27) -> 0 | C13: =IF((B13)=0,0,1-D13/(B13)) -> 0 | D13: =SUM(D14:D27) -> 0 | F13: Warranty - DC chargers (after free period) | G13: =MAX(0,$G$16-'CTX Price Book'!$I$139) -> 3 | H13: =SUMPRODUCT('CTX Price Book'!$C$139:$C$144,'CTX Price Book'!$D$139:$D$144) -> 0 | I13: =G13*H13 -> 0
A14: Wires, Conduits and Peripherals | B14: =IF(ROUND('Costs Internal'!G15,2)=88919.7, 0, 'Costs Internal'!G3) -> 0 | C14: 0 | D14: =(B14)-((B14)*C14) -> 0 | F14: Total | I14: =SUM(I11:I13) -> 0
A15: Main Distribution Switchgear | B15: =IF(ROUND('Costs Internal'!G15,2)=88919.7, 0, 'Costs Internal'!G4) -> 0 | C15: 0 | D15: =(B15)-((B15)*C15) -> 0
A16: Electrical Sub-Panels, Transformers, Breakers | B16: =IF(ROUND('Costs Internal'!G15,2)=88919.7, 0, 'Costs Internal'!G5) -> 0 | C16: 0 | D16: =(B16)-((B16)*C16) -> 0 | F16: Length Of Contract (years) [INPUT] | G16: 5
A17: Striping, Bollards, Signage | B17: =IF(ROUND('Costs Internal'!G15,2)=88919.7, 0, 'Costs Internal'!G6) -> 0 | C17: 0 | D17: =(B17)-((B17)*C17) -> 0
A18: Asphalt and Paving | B18: =IF(ROUND('Costs Internal'!G15,2)=88919.7, 0, 'Costs Internal'!G7) -> 0 | C18: 0 | D18: =(B18)-((B18)*C18) -> 0
A19: Concrete Improvements | B19: =IF(ROUND('Costs Internal'!G15,2)=88919.7, 0, 'Costs Internal'!G8) -> 0 | C19: 0 | D19: =(B19)-((B19)*C19) -> 0
A20: ADA | B20: =IF(ROUND('Costs Internal'!G15,2)=88919.7, 0, 'Costs Internal'!G9) -> 0 | C20: 0 | D20: =(B20)-((B20)*C20) -> 0
A21: Environmental Cleanup Fee | B21: =IF(ROUND('Costs Internal'!G15,2)=88919.7, 0, 'Costs Internal'!G10) -> 0 | C21: 0 | D21: =(B21)-((B21)*C21) -> 0
A22: Permits | B22: =IF(ROUND('Costs Internal'!G15,2)=88919.7, 0, 'Costs Internal'!G11) -> 0 | C22: 0 | D22: =(B22)-((B22)*C22) -> 0
A23: Utility | B23: =IF(ROUND('Costs Internal'!G15,2)=88919.7, 0, 'Costs Internal'!G12) -> 0 | C23: 0 | D23: =(B23)-((B23)*C23) -> 0
A24: Construction Equipment | B24: =IF(ROUND('Costs Internal'!G15,2)=88919.7, 0, 'Costs Internal'!G13) -> 0 | C24: 0 | D24: =(B24)-((B24)*C24) -> 0 | N24: x
A25: Construction PM | B25: 0 | C25: 0 | D25: =(B25)-((B25)*C25) -> 0
A26: Materials | B26: 0 | C26: 0 | D26: =(B26)-((B26)*C26) -> 0
A27: Sales Tax on equipment | B27: 0 | C27: 0 | D27: =(B27)-((B27)*C27) -> 0
A28: Labor | B28: =IF(ROUND('Costs Internal'!G15,2)=88919.7, 0, 'Costs Internal'!G18) -> 0 | C28: 0 | D28: =(B28)-((B28)*C28) -> 0
A29: Grand Total | D29: =(B28+B13+B8+B3) -> 0
A30: Total After Discount | D30: =SUM(D3,D8,D13,D28) -> 0
A33: How to use: If you need extra costs Insert the extra costs into the Costs Row. The Values will be populated tot eh Cost Export and Financial Worksheet automatically

Sheet Financial Worksheet
L1: =B10&"-Year Cumulative Cashflow" -> 5-Year Cumulative Cashflow
A2: ="Projected Profits Over "&$B$10&" Years" -> Projected Profits Over 5 Years | D2: =$B$10&" Year Cashflow" -> 5 Year Cashflow | H2: =$B$10&" Year Charger Revenue" -> 5 Year Charger Revenue
A3: Total Costs Upfront | B3: =-B44 -> 0
A4: Carbon Credits | B4: =($B$10*SUMPRODUCT(E44:J44,E45:J45))+(G47*$B$10*12) -> 0 | D4: Year | E4: Annual Cashflow | F4: Cumulative | H4: Year | I4: Annual Charger Revenue | J4: Cumulative
A5: ITC | B5: 0 | D5: 0 | E5: =-B44 -> 0 | F5: =E5 -> 0 | H5: 0 | I5: =-B44 -> 0 | J5: =I5 -> 0
A6: EVSE Revenues | B6: =SUM(I6:I15) -> 0 | D6: =IF((ROW()-5)<=$B$10,ROW()-5,"") -> 1 | E6: =IF((ROW()-5)<=$B$10, I6+B5+(B4/$B$10), "") -> 0 | F6: =IF((ROW()-5)<=$B$10, F5+E6, "") -> 0 | H6: =IF((ROW()-5)<=$B$10,ROW()-5,"") -> 1 | I6: =IF((ROW()-5)<=$B$10,'Updated Chargers Revenue Calcul'!S95,"") -> 0 | J6: =IF((ROW()-5)<=$B$10, J5+I6, "") -> 0
A7: Net Revenues | B7: =B3+(B4+B6) -> 0 | D7: =IF((ROW()-5)<=$B$10,ROW()-5,"") -> 2 | E7: =IF((ROW()-5)<=$B$10, I7+(B4/$B$10), "") -> 0 | F7: =IF((ROW()-5)<=$B$10, F6+E7, "") -> 0 | H7: =IF((ROW()-5)<=$B$10,ROW()-5,"") -> 2 | I7: =IF((ROW()-5)<=$B$10,'Updated Chargers Revenue Calcul'!S96,"") -> 0 | J7: =IF((ROW()-5)<=$B$10, J6+I7, "") -> 0
D8: =IF((ROW()-5)<=$B$10,ROW()-5,"") -> 3 | E8: =IF((ROW()-5)<=$B$10, I8+(B4/$B$10), "") -> 0 | F8: =IF((ROW()-5)<=$B$10, F7+E8, "") -> 0 | H8: =IF((ROW()-5)<=$B$10,ROW()-5,"") -> 3 | I8: =IF((ROW()-5)<=$B$10,'Updated Chargers Revenue Calcul'!S97,"") -> 0 | J8: =IF((ROW()-5)<=$B$10, J7+I8, "") -> 0
A9: View Period | B9: 5 Year | D9: =IF((ROW()-5)<=$B$10,ROW()-5,"") -> 4 | E9: =IF((ROW()-5)<=$B$10, I9+(B4/$B$10), "") -> 0 | F9: =IF((ROW()-5)<=$B$10, F8+E9, "") -> 0 | H9: =IF((ROW()-5)<=$B$10,ROW()-5,"") -> 4 | I9: =IF((ROW()-5)<=$B$10,'Updated Chargers Revenue Calcul'!S98,"") -> 0 | J9: =IF((ROW()-5)<=$B$10, J8+I9, "") -> 0
A10: Years (auto) | B10: =IF(B9="10 Year",10,5) -> 5 | D10: =IF((ROW()-5)<=$B$10,ROW()-5,"") -> 5 | E10: =IF((ROW()-5)<=$B$10, I10+(B4/$B$10), "") -> 0 | F10: =IF((ROW()-5)<=$B$10, F9+E10, "") -> 0 | H10: =IF((ROW()-5)<=$B$10,ROW()-5,"") -> 5 | I10: =IF((ROW()-5)<=$B$10,'Updated Chargers Revenue Calcul'!S99,"") -> 0 | J10: =IF((ROW()-5)<=$B$10, J9+I10, "") -> 0
D11: =IF((ROW()-5)<=$B$10,ROW()-5,"") | E11: =IF((ROW()-5)<=$B$10, I11+(B4/$B$10), "") | F11: =IF((ROW()-5)<=$B$10, F10+E11, "") | H11: =IF((ROW()-5)<=$B$10,ROW()-5,"") | I11: =IF((ROW()-5)<=$B$10,'Updated Chargers Revenue Calcul'!S100,"") | J11: =IF((ROW()-5)<=$B$10, J10+I11, "")
D12: =IF((ROW()-5)<=$B$10,ROW()-5,"") | E12: =IF((ROW()-5)<=$B$10, I12+(B4/$B$10), "") | F12: =IF((ROW()-5)<=$B$10, F11+E12, "") | H12: =IF((ROW()-5)<=$B$10,ROW()-5,"") | I12: =IF((ROW()-5)<=$B$10,'Updated Chargers Revenue Calcul'!S101,"") | J12: =IF((ROW()-5)<=$B$10, J11+I12, "")
D13: =IF((ROW()-5)<=$B$10,ROW()-5,"") | E13: =IF((ROW()-5)<=$B$10, I13+(B4/$B$10), "") | F13: =IF((ROW()-5)<=$B$10, F12+E13, "") | H13: =IF((ROW()-5)<=$B$10,ROW()-5,"") | I13: =IF((ROW()-5)<=$B$10,'Updated Chargers Revenue Calcul'!S102,"") | J13: =IF((ROW()-5)<=$B$10, J12+I13, "")
D14: =IF((ROW()-5)<=$B$10,ROW()-5,"") | E14: =IF((ROW()-5)<=$B$10, I14+(B4/$B$10), "") | F14: =IF((ROW()-5)<=$B$10, F13+E14, "") | H14: =IF((ROW()-5)<=$B$10,ROW()-5,"") | I14: =IF((ROW()-5)<=$B$10,'Updated Chargers Revenue Calcul'!S103,"") | J14: =IF((ROW()-5)<=$B$10, J13+I14, "")
B15: Customer Total | D15: =IF((ROW()-5)<=$B$10,ROW()-5,"") | E15: =IF((ROW()-5)<=$B$10, I15+(B4/$B$10), "") | F15: =IF((ROW()-5)<=$B$10, F14+E15, "") | H15: =IF((ROW()-5)<=$B$10,ROW()-5,"") | I15: =IF((ROW()-5)<=$B$10,'Updated Chargers Revenue Calcul'!S104,"") | J15: =IF((ROW()-5)<=$B$10, J14+I15, "")
A16: Equipment Purchase Invoice | B16: ='Internal Summary'!D3 -> 0
A17: Charger Hardware | B17: ='Internal Summary'!D4 -> 0
A18: Parts Warranty | B18: ='Internal Summary'!D5 -> 0
A19: EVOLV & Commissioning Subtotal | B19: ='Internal Summary'!D6 -> 0
A20: 5 Year Service Agreement | B20: ='Internal Summary'!B5 -> 0
A21: Sales Tax on Chargers | B21: ='Internal Summary'!D7 -> 0
A22: Design Invoice | B22: ='Internal Summary'!D8 -> 0
A23: AutoCad Design Services | B23: ='Internal Summary'!D9 -> 0
A24: Electrical Engineering Design | B24: ='Internal Summary'!D10 -> 0
A25: Project Management (@$358/hour) | B25: ='Internal Summary'!D11 -> 0
A26: Plan Check and Permit Fees | B26: ='Internal Summary'!D12 -> 0
A27: Electrical Supply & Construction Management Costs | B27: ='Internal Summary'!D13 -> 0
A28: Wires, Conduits and Peripherals | B28: ='Internal Summary'!D14 -> 0
A29: Main Distribution Switchgear | B29: ='Internal Summary'!D15 -> 0
A30: Electrical Sub-Panels, Transformers, Breakers | B30: ='Internal Summary'!D16 -> 0
A31: Striping, Bollards, Signage | B31: ='Internal Summary'!D17 -> 0
A32: Asphalt and Paving | B32: ='Internal Summary'!D18 -> 0
... A41: Sales Tax on equipment | B41: ='Internal Summary'!D27 -> 0
A42: Labor | B42: ='Internal Summary'!D28 -> 0 | D42: CC Rate ($/kW/yr) | E42: 71.6667
A43: Grand Total | B43: ='Internal Summary'!D29 -> 0 | D43: L3 Rating (kW) | E43: ='INPUT SHEET'!O10 -> 60 | F43: ='INPUT SHEET'!P10 -> 120 | G43: ='INPUT SHEET'!Q10 -> 160 | H43: ='INPUT SHEET'!R10 -> 180 | I43: ='INPUT SHEET'!S10 -> 240 | J43: ='INPUT SHEET'!T10 -> 360
A44: Remaining Balance after Discount | B44: ='Internal Summary'!D30 -> 0 | D44: Qty | E44: ='INPUT SHEET'!O8 -> 0 | F44: ='INPUT SHEET'!P8 -> 0 | G44: ='INPUT SHEET'!Q8 -> 0 | H44: ='INPUT SHEET'!R8 -> 0 | I44: ='INPUT SHEET'!S8 -> 0 | J44: ='INPUT SHEET'!T8 -> 0
D45: Multiplier ($/yr) | E45: =E43*$E$42 -> 4300.002 | F45: =F43*$E$42 -> 8600.004 | G45: =G43*$E$42 -> 11466.672 | H45: =H43*$E$42 -> 12900.006 | I45: =I43*$E$42 -> 17200.008 | J45: =J43*$E$42 -> 25800.012
D46: L2 | E46: Usage | F46: Multiplier
D47: Consumption Credits/m | E47: ='Updated Chargers Revenue Calcul'!B16*30 -> 0 | F47: 0.0045 | G47: =E47*F47 -> 0

Sheet DLL Schedule
A1: Loan Amortization Schedule
B4: Enter values | H4: Loan summary
C5: Loan amount | D5: ='Financial Worksheet'!B44 -> 0 | I5: Scheduled payment | J5: =IF('DLL Schedule'!Values_Entered=1,-PMT('DLL Schedule'!Interest_Rate/'DLL Schedule'!Num_Pmt_Per_Year,'DLL Schedule'!Loan_Years*'DLL Schedule'!Num_Pmt_Per_Year,'DLL Schedule'!Loan_Amount),"")
C6: Annual interest rate | D6: 0.0839 | I6: Scheduled number of payments | J6: =IF('DLL Schedule'!Values_Entered=1,'DLL Schedule'!Loan_Years*'DLL Schedule'!Num_Pmt_Per_Year,"")
C7: Loan period in years | D7: 5 | I7: Actual number of payments | J7: =IF('DLL Schedule'!Values_Entered=1,MATCH(0.01,'DLL Schedule'!End_Bal,-1)+1,"")
C8: Number of payments per year | D8: 12 | I8: Total early payments | J8: =IF('DLL Schedule'!Values_Entered=1,SUMIF('DLL Schedule'!Beg_Bal,">0",'DLL Schedule'!Extra_Pay),"")
C9: Start date of loan | D9: 46235 | I9: Total interest | J9: =IF('DLL Schedule'!Values_Entered=1,SUMIF('DLL Schedule'!Beg_Bal,">0",'DLL Schedule'!Int),"")
C10: Optional extra payments | D10: 0
B12: Lender name:
A16: Pmt. No. | B16: Payment Date | C16: Beginning Balance | D16: Scheduled Payment | E16: Extra Payment | F16: Total Payment | G16: Principal | H16: Interest | I16: Ending Balance | J16: Cumulative Interest
A18: =IF('DLL Schedule'!Values_Entered=1,1,"") | B18: =IF('DLL Schedule'!Pay_Num<>"",DATE(YEAR('DLL Schedule'!Loan_Start),MONTH('DLL Schedule'!Loan_Start)+('DLL Schedule'!Pay_Num)*12/'DLL Schedule'!Num_Pmt_Per_Year,DAY('DLL Schedule'!Loan_Start)),"") | C18: =IF('DLL Schedule'!Values_Entered=1,'DLL Schedule'!Loan_Amount,"") | D18: =IF('DLL Schedule'!Pay_Num<>"",'DLL Schedule'!Scheduled_Monthly_Payment,"") | E18: =IF('DLL Schedule'!Pay_Num<>"",IF('DLL Schedule'!Sched_Pay+'DLL Schedule'!Scheduled_Extra_Payments<'DLL Schedule'!Beg_Bal,'DLL Schedule'!Scheduled_Extra_Payments,IF('DLL Schedule'!Beg_Bal-'DLL Schedule'!Sched_Pay>0,'DLL Schedule'!Beg_Bal-'DLL Schedule'!Sched_Pay,0)),"") | F18: =IF('DLL Schedule'!Pay_Num<>"",IF('DLL Schedule'!Sched_Pay+'DLL Schedule'!Extra_Pay<'DLL Schedule'!Beg_Bal,'DLL Schedule'!Sched_Pay+'DLL Schedule'!Extra_Pay,'DLL Schedule'!Beg_Bal),"") | G18: =IF('DLL Schedule'!Pay_Num<>"",'DLL Schedule'!Total_Pay-'DLL Schedule'!Int,"") | H18: =IF('DLL Schedule'!Pay_Num<>"",'DLL Schedule'!Beg_Bal*('DLL Schedule'!Interest_Rate/'DLL Schedule'!Num_Pmt_Per_Year),"") | I18: =IF('DLL Schedule'!Pay_Num<>"",IF('DLL Schedule'!Sched_Pay+'DLL Schedule'!Extra_Pay<'DLL Schedule'!Beg_Bal,'DLL Schedule'!Beg_Bal-'DLL Schedule'!Princ,0),"") | J18: =SUM($H$18:$H18) -> 0
A19: =IF(AND('DLL Schedule'!Values_Entered=1,A18<>"",I18>0),A18+1,"") | B19: =IF('DLL Schedule'!Pay_Num<>"",DATE(YEAR('DLL Schedule'!Loan_Start),MONTH('DLL Schedule'!Loan_Start)+('DLL Schedule'!Pay_Num)*12/'DLL Schedule'!Num_Pmt_Per_Year,DAY('DLL Schedule'!Loan_Start)),"") | C19: =IF('DLL Schedule'!Pay_Num<>"",I18,"") | D19: =IF('DLL Schedule'!Pay_Num<>"",'DLL Schedule'!Scheduled_Monthly_Payment,"") | E19: =IF('DLL Schedule'!Pay_Num<>"",IF('DLL Schedule'!Sched_Pay+'DLL Schedule'!Scheduled_Extra_Payments<'DLL Schedule'!Beg_Bal,'DLL Schedule'!Scheduled_Extra_Payments,IF('DLL Schedule'!Beg_Bal-'DLL Schedule'!Sched_Pay>0,'DLL Schedule'!Beg_Bal-'DLL Schedule'!Sched_Pay,0)),"") | F19: =IF('DLL Schedule'!Pay_Num<>"",IF('DLL Schedule'!Sched_Pay+'DLL Schedule'!Extra_Pay<'DLL Schedule'!Beg_Bal,'DLL Schedule'!Sched_Pay+'DLL Schedule'!Extra_Pay,'DLL Schedule'!Beg_Bal),"") | G19: =IF('DLL Schedule'!Pay_Num<>"",'DLL Schedule'!Total_Pay-'DLL Schedule'!Int,"") | H19: =IF('DLL Schedule'!Pay_Num<>"",'DLL Schedule'!Beg_Bal*'DLL Schedule'!Interest_Rate/'DLL Schedule'!Num_Pmt_Per_Year,"") | I19: =IF('DLL Schedule'!Pay_Num<>"",IF('DLL Schedule'!Sched_Pay+'DLL Schedule'!Extra_Pay<'DLL Schedule'!Beg_Bal,'DLL Schedule'!Beg_Bal-'DLL Schedule'!Princ,0),"") | J19: =SUM($H$18:$H19) -> 0
A20: =IF(AND('DLL Schedule'!Values_Entered=1,A19<>"",I19>0),A19+1,"") | B20: =IF('DLL Schedule'!Pay_Num<>"",DATE(YEAR('DLL Schedule'!Loan_Start),MONTH('DLL Schedule'!Loan_Start)+('DLL Schedule'!Pay_Num)*12/'DLL Schedule'!Num_Pmt_Per_Year,DAY('DLL Schedule'!Loan_Start)),"") | C20: =IF('DLL Schedule'!Pay_Num<>"",I19,"") | D20: =IF('DLL Schedule'!Pay_Num<>"",'DLL Schedule'!Scheduled_Monthly_Payment,"") | E20: =IF('DLL Schedule'!Pay_Num<>"",IF('DLL Schedule'!Sched_Pay+'DLL Schedule'!Scheduled_Extra_Payments<'DLL Schedule'!Beg_Bal,'DLL Schedule'!Scheduled_Extra_Payments,IF('DLL Schedule'!Beg_Bal-'DLL Schedule'!Sched_Pay>0,'DLL Schedule'!Beg_Bal-'DLL Schedule'!Sched_Pay,0)),"") | F20: =IF('DLL Schedule'!Pay_Num<>"",IF('DLL Schedule'!Sched_Pay+'DLL Schedule'!Extra_Pay<'DLL Schedule'!Beg_Bal,'DLL Schedule'!Sched_Pay+'DLL Schedule'!Extra_Pay,'DLL Schedule'!Beg_Bal),"") | G20: =IF('DLL Schedule'!Pay_Num<>"",'DLL Schedule'!Total_Pay-'DLL Schedule'!Int,"") | H20: =IF('DLL Schedule'!Pay_Num<>"",'DLL Schedule'!Beg_Bal*'DLL Schedule'!Interest_Rate/'DLL Schedule'!Num_Pmt_Per_Year,"") | I20: =IF('DLL Schedule'!Pay_Num<>"",IF('DLL Schedule'!Sched_Pay+'DLL Schedule'!Extra_Pay<'DLL Schedule'!Beg_Bal,'DLL Schedule'!Beg_Bal-'DLL Schedule'!Princ,0),"") | J20: =SUM($H$18:$H20) -> 0
A21: =IF(AND('DLL Schedule'!Values_Entered=1,A20<>"",I20>0),A20+1,"") | B21: =IF('DLL Schedule'!Pay_Num<>"",DATE(YEAR('DLL Schedule'!Loan_Start),MONTH('DLL Schedule'!Loan_Start)+('DLL Schedule'!Pay_Num)*12/'DLL Schedule'!Num_Pmt_Per_Year,DAY('DLL Schedule'!Loan_Start)),"") | C21: =IF('DLL Schedule'!Pay_Num<>"",I20,"") | D21: =IF('DLL Schedule'!Pay_Num<>"",'DLL Schedule'!Scheduled_Monthly_Payment,"") | E21: =IF('DLL Schedule'!Pay_Num<>"",IF('DLL Schedule'!Sched_Pay+'DLL Schedule'!Scheduled_Extra_Payments<'DLL Schedule'!Beg_Bal,'DLL Schedule'!Scheduled_Extra_Payments,IF('DLL Schedule'!Beg_Bal-'DLL Schedule'!Sched_Pay>0,'DLL Schedule'!Beg_Bal-'DLL Schedule'!Sched_Pay,0)),"") | F21: =IF('DLL Schedule'!Pay_Num<>"",IF('DLL Schedule'!Sched_Pay+'DLL Schedule'!Extra_Pay<'DLL Schedule'!Beg_Bal,'DLL Schedule'!Sched_Pay+'DLL Schedule'!Extra_Pay,'DLL Schedule'!Beg_Bal),"") | G21: =IF('DLL Schedule'!Pay_Num<>"",'DLL Schedule'!Total_Pay-'DLL Schedule'!Int,"") | H21: =IF('DLL Schedule'!Pay_Num<>"",'DLL Schedule'!Beg_Bal*'DLL Schedule'!Interest_Rate/'DLL Schedule'!Num_Pmt_Per_Year,"") | I21: =IF('DLL Schedule'!Pay_Num<>"",IF('DLL Schedule'!Sched_Pay+'DLL Schedule'!Extra_Pay<'DLL Schedule'!Beg_Bal,'DLL Schedule'!Beg_Bal-'DLL Schedule'!Princ,0),"") | J21: =SUM($H$18:$H21) -> 0
A22: =IF(AND('DLL Schedule'!Values_Entered=1,A21<>"",I21>0),A21+1,"") | B22: =IF('DLL Schedule'!Pay_Num<>"",DATE(YEAR('DLL Schedule'!Loan_Start),MONTH('DLL Schedule'!Loan_Start)+('DLL Schedule'!Pay_Num)*12/'DLL Schedule'!Num_Pmt_Per_Year,DAY('DLL Schedule'!Loan_Start)),"") | C22: =IF('DLL Schedule'!Pay_Num<>"",I21,"") | D22: =IF('DLL Schedule'!Pay_Num<>"",'DLL Schedule'!Scheduled_Monthly_Payment,"") | E22: =IF('DLL Schedule'!Pay_Num<>"",IF('DLL Schedule'!Sched_Pay+'DLL Schedule'!Scheduled_Extra_Payments<'DLL Schedule'!Beg_Bal,'DLL Schedule'!Scheduled_Extra_Payments,IF('DLL Schedule'!Beg_Bal-'DLL Schedule'!Sched_Pay>0,'DLL Schedule'!Beg_Bal-'DLL Schedule'!Sched_Pay,0)),"") | F22: =IF('DLL Schedule'!Pay_Num<>"",IF('DLL Schedule'!Sched_Pay+'DLL Schedule'!Extra_Pay<'DLL Schedule'!Beg_Bal,'DLL Schedule'!Sched_Pay+'DLL Schedule'!Extra_Pay,'DLL Schedule'!Beg_Bal),"") | G22: =IF('DLL Schedule'!Pay_Num<>"",'DLL Schedule'!Total_Pay-'DLL Schedule'!Int,"") | H22: =IF('DLL Schedule'!Pay_Num<>"",'DLL Schedule'!Beg_Bal*'DLL Schedule'!Interest_Rate/'DLL Schedule'!Num_Pmt_Per_Year,"") | I22: =IF('DLL Schedule'!Pay_Num<>"",IF('DLL Schedule'!Sched_Pay+'DLL Schedule'!Extra_Pay<'DLL Schedule'!Beg_Bal,'DLL Schedule'!Beg_Bal-'DLL Schedule'!Princ,0),"") | J22: =SUM($H$18:$H22) -> 0
A23: =IF(AND('DLL Schedule'!Values_Entered=1,A22<>"",I22>0),A22+1,"") | B23: =IF('DLL Schedule'!Pay_Num<>"",DATE(YEAR('DLL Schedule'!Loan_Start),MONTH('DLL Schedule'!Loan_Start)+('DLL Schedule'!Pay_Num)*12/'DLL Schedule'!Num_Pmt_Per_Year,DAY('DLL Schedule'!Loan_Start)),"") | C23: =IF('DLL Schedule'!Pay_Num<>"",I22,"") | D23: =IF('DLL Schedule'!Pay_Num<>"",'DLL Schedule'!Scheduled_Monthly_Payment,"") | E23: =IF('DLL Schedule'!Pay_Num<>"",IF('DLL Schedule'!Sched_Pay+'DLL Schedule'!Scheduled_Extra_Payments<'DLL Schedule'!Beg_Bal,'DLL Schedule'!Scheduled_Extra_Payments,IF('DLL Schedule'!Beg_Bal-'DLL Schedule'!Sched_Pay>0,'DLL Schedule'!Beg_Bal-'DLL Schedule'!Sched_Pay,0)),"") | F23: =IF('DLL Schedule'!Pay_Num<>"",IF('DLL Schedule'!Sched_Pay+'DLL Schedule'!Extra_Pay<'DLL Schedule'!Beg_Bal,'DLL Schedule'!Sched_Pay+'DLL Schedule'!Extra_Pay,'DLL Schedule'!Beg_Bal),"") | G23: =IF('DLL Schedule'!Pay_Num<>"",'DLL Schedule'!Total_Pay-'DLL Schedule'!Int,"") | H23: =IF('DLL Schedule'!Pay_Num<>"",'DLL Schedule'!Beg_Bal*'DLL Schedule'!Interest_Rate/'DLL Schedule'!Num_Pmt_Per_Year,"") | I23: =IF('DLL Schedule'!Pay_Num<>"",IF('DLL Schedule'!Sched_Pay+'DLL Schedule'!Extra_Pay<'DLL Schedule'!Beg_Bal,'DLL Schedule'!Beg_Bal-'DLL Schedule'!Princ,0),"") | J23: =SUM($H$18:$H23) -> 0
A24: =IF(AND('DLL Schedule'!Values_Entered=1,A23<>"",I23>0),A23+1,"") | B24: =IF('DLL Schedule'!Pay_Num<>"",DATE(YEAR('DLL Schedule'!Loan_Start),MONTH('DLL Schedule'!Loan_Start)+('DLL Schedule'!Pay_Num)*12/'DLL Schedule'!Num_Pmt_Per_Year,DAY('DLL Schedule'!Loan_Start)),"") | C24: =IF('DLL Schedule'!Pay_Num<>"",I23,"") | D24: =IF('DLL Schedule'!Pay_Num<>"",'DLL Schedule'!Scheduled_Monthly_Payment,"") | E24: =IF('DLL Schedule'!Pay_Num<>"",IF('DLL Schedule'!Sched_Pay+'DLL Schedule'!Scheduled_Extra_Payments<'DLL Schedule'!Beg_Bal,'DLL Schedule'!Scheduled_Extra_Payments,IF('DLL Schedule'!Beg_Bal-'DLL Schedule'!Sched_Pay>0,'DLL Schedule'!Beg_Bal-'DLL Schedule'!Sched_Pay,0)),"") | F24: =IF('DLL Schedule'!Pay_Num<>"",IF('DLL Schedule'!Sched_Pay+'DLL Schedule'!Extra_Pay<'DLL Schedule'!Beg_Bal,'DLL Schedule'!Sched_Pay+'DLL Schedule'!Extra_Pay,'DLL Schedule'!Beg_Bal),"") | G24: =IF('DLL Schedule'!Pay_Num<>"",'DLL Schedule'!Total_Pay-'DLL Schedule'!Int,"") | H24: =IF('DLL Schedule'!Pay_Num<>"",'DLL Schedule'!Beg_Bal*'DLL Schedule'!Interest_Rate/'DLL Schedule'!Num_Pmt_Per_Year,"") | I24: =IF('DLL Schedule'!Pay_Num<>"",IF('DLL Schedule'!Sched_Pay+'DLL Schedule'!Extra_Pay<'DLL Schedule'!Beg_Bal,'DLL Schedule'!Beg_Bal-'DLL Schedule'!Princ,0),"") | J24: =SUM($H$18:$H24) -> 0
A25: =IF(AND('DLL Schedule'!Values_Entered=1,A24<>"",I24>0),A24+1,"") | B25: =IF('DLL Schedule'!Pay_Num<>"",DATE(YEAR('DLL Schedule'!Loan_Start),MONTH('DLL Schedule'!Loan_Start)+('DLL Schedule'!Pay_Num)*12/'DLL Schedule'!Num_Pmt_Per_Year,DAY('DLL Schedule'!Loan_Start)),"") | C25: =IF('DLL Schedule'!Pay_Num<>"",I24,"") | D25: =IF('DLL Schedule'!Pay_Num<>"",'DLL Schedule'!Scheduled_Monthly_Payment,"") | E25: =IF('DLL Schedule'!Pay_Num<>"",IF('DLL Schedule'!Sched_Pay+'DLL Schedule'!Scheduled_Extra_Payments<'DLL Schedule'!Beg_Bal,'DLL Schedule'!Scheduled_Extra_Payments,IF('DLL Schedule'!Beg_Bal-'DLL Schedule'!Sched_Pay>0,'DLL Schedule'!Beg_Bal-'DLL Schedule'!Sched_Pay,0)),"") | F25: =IF('DLL Schedule'!Pay_Num<>"",IF('DLL Schedule'!Sched_Pay+'DLL Schedule'!Extra_Pay<'DLL Schedule'!Beg_Bal,'DLL Schedule'!Sched_Pay+'DLL Schedule'!Extra_Pay,'DLL Schedule'!Beg_Bal),"") | G25: =IF('DLL Schedule'!Pay_Num<>"",'DLL Schedule'!Total_Pay-'DLL Schedule'!Int,"") | H25: =IF('DLL Schedule'!Pay_Num<>"",'DLL Schedule'!Beg_Bal*'DLL Schedule'!Interest_Rate/'DLL Schedule'!Num_Pmt_Per_Year,"") | I25: =IF('DLL Schedule'!Pay_Num<>"",IF('DLL Schedule'!Sched_Pay+'DLL Schedule'!Extra_Pay<'DLL Schedule'!Beg_Bal,'DLL Schedule'!Beg_Bal-'DLL Schedule'!Princ,0),"") | J25: =SUM($H$18:$H25) -> 0
A26: =IF(AND('DLL Schedule'!Values_Entered=1,A25<>"",I25>0),A25+1,"") | B26: =IF('DLL Schedule'!Pay_Num<>"",DATE(YEAR('DLL Schedule'!Loan_Start),MONTH('DLL Schedule'!Loan_Start)+('DLL Schedule'!Pay_Num)*12/'DLL Schedule'!Num_Pmt_Per_Year,DAY('DLL Schedule'!Loan_Start)),"") | C26: =IF('DLL Schedule'!Pay_Num<>"",I25,"") | D26: =IF('DLL Schedule'!Pay_Num<>"",'DLL Schedule'!Scheduled_Monthly_Payment,"") | E26: =IF('DLL Schedule'!Pay_Num<>"",IF('DLL Schedule'!Sched_Pay+'DLL Schedule'!Scheduled_Extra_Payments<'DLL Schedule'!Beg_Bal,'DLL Schedule'!Scheduled_Extra_Payments,IF('DLL Schedule'!Beg_Bal-'DLL Schedule'!Sched_Pay>0,'DLL Schedule'!Beg_Bal-'DLL Schedule'!Sched_Pay,0)),"") | F26: =IF('DLL Schedule'!Pay_Num<>"",IF('DLL Schedule'!Sched_Pay+'DLL Schedule'!Extra_Pay<'DLL Schedule'!Beg_Bal,'DLL Schedule'!Sched_Pay+'DLL Schedule'!Extra_Pay,'DLL Schedule'!Beg_Bal),"") | G26: =IF('DLL Schedule'!Pay_Num<>"",'DLL Schedule'!Total_Pay-'DLL Schedule'!Int,"") | H26: =IF('DLL Schedule'!Pay_Num<>"",'DLL Schedule'!Beg_Bal*'DLL Schedule'!Interest_Rate/'DLL Schedule'!Num_Pmt_Per_Year,"") | I26: =IF('DLL Schedule'!Pay_Num<>"",IF('DLL Schedule'!Sched_Pay+'DLL Schedule'!Extra_Pay<'DLL Schedule'!Beg_Bal,'DLL Schedule'!Beg_Bal-'DLL Schedule'!Princ,0),"") | J26: =SUM($H$18:$H26) -> 0
A27: =IF(AND('DLL Schedule'!Values_Entered=1,A26<>"",I26>0),A26+1,"") | B27: =IF('DLL Schedule'!Pay_Num<>"",DATE(YEAR('DLL Schedule'!Loan_Start),MONTH('DLL Schedule'!Loan_Start)+('DLL Schedule'!Pay_Num)*12/'DLL Schedule'!Num_Pmt_Per_Year,DAY('DLL Schedule'!Loan_Start)),"") | C27: =IF('DLL Schedule'!Pay_Num<>"",I26,"") | D27: =IF('DLL Schedule'!Pay_Num<>"",'DLL Schedule'!Scheduled_Monthly_Payment,"") | E27: =IF('DLL Schedule'!Pay_Num<>"",IF('DLL Schedule'!Sched_Pay+'DLL Schedule'!Scheduled_Extra_Payments<'DLL Schedule'!Beg_Bal,'DLL Schedule'!Scheduled_Extra_Payments,IF('DLL Schedule'!Beg_Bal-'DLL Schedule'!Sched_Pay>0,'DLL Schedule'!Beg_Bal-'DLL Schedule'!Sched_Pay,0)),"") | F27: =IF('DLL Schedule'!Pay_Num<>"",IF('DLL Schedule'!Sched_Pay+'DLL Schedule'!Extra_Pay<'DLL Schedule'!Beg_Bal,'DLL Schedule'!Sched_Pay+'DLL Schedule'!Extra_Pay,'DLL Schedule'!Beg_Bal),"") | G27: =IF('DLL Schedule'!Pay_Num<>"",'DLL Schedule'!Total_Pay-'DLL Schedule'!Int,"") | H27: =IF('DLL Schedule'!Pay_Num<>"",'DLL Schedule'!Beg_Bal*'DLL Schedule'!Interest_Rate/'DLL Schedule'!Num_Pmt_Per_Year,"") | I27: =IF('DLL Schedule'!Pay_Num<>"",IF('DLL Schedule'!Sched_Pay+'DLL Schedule'!Extra_Pay<'DLL Schedule'!Beg_Bal,'DLL Schedule'!Beg_Bal-'DLL Schedule'!Princ,0),"") | J27: =SUM($H$18:$H27) -> 0
A28: =IF(AND('DLL Schedule'!Values_Entered=1,A27<>"",I27>0),A27+1,"") | B28: =IF('DLL Schedule'!Pay_Num<>"",DATE(YEAR('DLL Schedule'!Loan_Start),MONTH('DLL Schedule'!Loan_Start)+('DLL Schedule'!Pay_Num)*12/'DLL Schedule'!Num_Pmt_Per_Year,DAY('DLL Schedule'!Loan_Start)),"") | C28: =IF('DLL Schedule'!Pay_Num<>"",I27,"") | D28: =IF('DLL Schedule'!Pay_Num<>"",'DLL Schedule'!Scheduled_Monthly_Payment,"") | E28: =IF('DLL Schedule'!Pay_Num<>"",IF('DLL Schedule'!Sched_Pay+'DLL Schedule'!Scheduled_Extra_Payments<'DLL Schedule'!Beg_Bal,'DLL Schedule'!Scheduled_Extra_Payments,IF('DLL Schedule'!Beg_Bal-'DLL Schedule'!Sched_Pay>0,'DLL Schedule'!Beg_Bal-'DLL Schedule'!Sched_Pay,0)),"") | F28: =IF('DLL Schedule'!Pay_Num<>"",IF('DLL Schedule'!Sched_Pay+'DLL Schedule'!Extra_Pay<'DLL Schedule'!Beg_Bal,'DLL Schedule'!Sched_Pay+'DLL Schedule'!Extra_Pay,'DLL Schedule'!Beg_Bal),"") | G28: =IF('DLL Schedule'!Pay_Num<>"",'DLL Schedule'!Total_Pay-'DLL Schedule'!Int,"") | H28: =IF('DLL Schedule'!Pay_Num<>"",'DLL Schedule'!Beg_Bal*'DLL Schedule'!Interest_Rate/'DLL Schedule'!Num_Pmt_Per_Year,"") | I28: =IF('DLL Schedule'!Pay_Num<>"",IF('DLL Schedule'!Sched_Pay+'DLL Schedule'!Extra_Pay<'DLL Schedule'!Beg_Bal,'DLL Schedule'!Beg_Bal-'DLL Schedule'!Princ,0),"") | J28: =SUM($H$18:$H28) -> 0
A29: =IF(AND('DLL Schedule'!Values_Entered=1,A28<>"",I28>0),A28+1,"") | B29: =IF('DLL Schedule'!Pay_Num<>"",DATE(YEAR('DLL Schedule'!Loan_Start),MONTH('DLL Schedule'!Loan_Start)+('DLL Schedule'!Pay_Num)*12/'DLL Schedule'!Num_Pmt_Per_Year,DAY('DLL Schedule'!Loan_Start)),"") | C29: =IF('DLL Schedule'!Pay_Num<>"",I28,"") | D29: =IF('DLL Schedule'!Pay_Num<>"",'DLL Schedule'!Scheduled_Monthly_Payment,"") | E29: =IF('DLL Schedule'!Pay_Num<>"",IF('DLL Schedule'!Sched_Pay+'DLL Schedule'!Scheduled_Extra_Payments<'DLL Schedule'!Beg_Bal,'DLL Schedule'!Scheduled_Extra_Payments,IF('DLL Schedule'!Beg_Bal-'DLL Schedule'!Sched_Pay>0,'DLL Schedule'!Beg_Bal-'DLL Schedule'!Sched_Pay,0)),"") | F29: =IF('DLL Schedule'!Pay_Num<>"",IF('DLL Schedule'!Sched_Pay+'DLL Schedule'!Extra_Pay<'DLL Schedule'!Beg_Bal,'DLL Schedule'!Sched_Pay+'DLL Schedule'!Extra_Pay,'DLL Schedule'!Beg_Bal),"") | G29: =IF('DLL Schedule'!Pay_Num<>"",'DLL Schedule'!Total_Pay-'DLL Schedule'!Int,"") | H29: =IF('DLL Schedule'!Pay_Num<>"",'DLL Schedule'!Beg_Bal*'DLL Schedule'!Interest_Rate/'DLL Schedule'!Num_Pmt_Per_Year,"") | I29: =IF('DLL Schedule'!Pay_Num<>"",IF('DLL Schedule'!Sched_Pay+'DLL Schedule'!Extra_Pay<'DLL Schedule'!Beg_Bal,'DLL Schedule'!Beg_Bal-'DLL Schedule'!Princ,0),"") | J29: =SUM($H$18:$H29) -> 0
A30: =IF(AND('DLL Schedule'!Values_Entered=1,A29<>"",I29>0),A29+1,"") | B30: =IF('DLL Schedule'!Pay_Num<>"",DATE(YEAR('DLL Schedule'!Loan_Start),MONTH('DLL Schedule'!Loan_Start)+('DLL Schedule'!Pay_Num)*12/'DLL Schedule'!Num_Pmt_Per_Year,DAY('DLL Schedule'!Loan_Start)),"") | C30: =IF('DLL Schedule'!Pay_Num<>"",I29,"") | D30: =IF('DLL Schedule'!Pay_Num<>"",'DLL Schedule'!Scheduled_Monthly_Payment,"") | E30: =IF('DLL Schedule'!Pay_Num<>"",IF('DLL Schedule'!Sched_Pay+'DLL Schedule'!Scheduled_Extra_Payments<'DLL Schedule'!Beg_Bal,'DLL Schedule'!Scheduled_Extra_Payments,IF('DLL Schedule'!Beg_Bal-'DLL Schedule'!Sched_Pay>0,'DLL Schedule'!Beg_Bal-'DLL Schedule'!Sched_Pay,0)),"") | F30: =IF('DLL Schedule'!Pay_Num<>"",IF('DLL Schedule'!Sched_Pay+'DLL Schedule'!Extra_Pay<'DLL Schedule'!Beg_Bal,'DLL Schedule'!Sched_Pay+'DLL Schedule'!Extra_Pay,'DLL Schedule'!Beg_Bal),"") | G30: =IF('DLL Schedule'!Pay_Num<>"",'DLL Schedule'!Total_Pay-'DLL Schedule'!Int,"") | H30: =IF('DLL Schedule'!Pay_Num<>"",'DLL Schedule'!Beg_Bal*'DLL Schedule'!Interest_Rate/'DLL Schedule'!Num_Pmt_Per_Year,"") | I30: =IF('DLL Schedule'!Pay_Num<>"",IF('DLL Schedule'!Sched_Pay+'DLL Schedule'!Extra_Pay<'DLL Schedule'!Beg_Bal,'DLL Schedule'!Beg_Bal-'DLL Schedule'!Princ,0),"") | J30: =SUM($H$18:$H30) -> 0
... A497: =IF(AND('DLL Schedule'!Values_Entered=1,A496<>"",I496>0),A496+1,"") | B497: =IF('DLL Schedule'!Pay_Num<>"",DATE(YEAR('DLL Schedule'!Loan_Start),MONTH('DLL Schedule'!Loan_Start)+('DLL Schedule'!Pay_Num)*12/'DLL Schedule'!Num_Pmt_Per_Year,DAY('DLL Schedule'!Loan_Start)),"") | C497: =IF('DLL Schedule'!Pay_Num<>"",I496,"") | D497: =IF('DLL Schedule'!Pay_Num<>"",'DLL Schedule'!Scheduled_Monthly_Payment,"") | E497: =IF('DLL Schedule'!Pay_Num<>"",IF('DLL Schedule'!Sched_Pay+'DLL Schedule'!Scheduled_Extra_Payments<'DLL Schedule'!Beg_Bal,'DLL Schedule'!Scheduled_Extra_Payments,IF('DLL Schedule'!Beg_Bal-'DLL Schedule'!Sched_Pay>0,'DLL Schedule'!Beg_Bal-'DLL Schedule'!Sched_Pay,0)),"") | F497: =IF('DLL Schedule'!Pay_Num<>"",IF('DLL Schedule'!Sched_Pay+'DLL Schedule'!Extra_Pay<'DLL Schedule'!Beg_Bal,'DLL Schedule'!Sched_Pay+'DLL Schedule'!Extra_Pay,'DLL Schedule'!Beg_Bal),"") | G497: =IF('DLL Schedule'!Pay_Num<>"",'DLL Schedule'!Total_Pay-'DLL Schedule'!Int,"") | H497: =IF('DLL Schedule'!Pay_Num<>"",'DLL Schedule'!Beg_Bal*'DLL Schedule'!Interest_Rate/'DLL Schedule'!Num_Pmt_Per_Year,"") | I497: =IF('DLL Schedule'!Pay_Num<>"",IF('DLL Schedule'!Sched_Pay+'DLL Schedule'!Extra_Pay<'DLL Schedule'!Beg_Bal,'DLL Schedule'!Beg_Bal-'DLL Schedule'!Princ,0),"") | J497: =SUM($H$18:$H497) -> 0

Sheet Cashflow
F1: =SUM(F3:F62) -> 0 | G1: =SUM(G3:G62) -> 0 | H1: =SUM(H3:H62) -> 0
F2: Loan Payment | G2: Carbon Credits | H2: EVSE Profit | I2: Total
E3: 1 | F3: ='DLL Schedule'!J5 | G3: ='Financial Worksheet'!$B$4/('Financial Worksheet'!$B$10*12) -> 0 | H3: =('Updated Chargers Revenue Calcul'!$J$24/12)*1.125^INT((E3-1)/12) -> 0 | I3: =(G3+H3)-F3 -> #VALUE!
E4: 2 | F4: =F3 | G4: ='Financial Worksheet'!$B$4/('Financial Worksheet'!$B$10*12) -> 0 | H4: =('Updated Chargers Revenue Calcul'!$J$24/12)*1.125^INT((E4-1)/12) -> 0 | I4: =(G4+H4)-F4 -> #VALUE!
E5: 3 | F5: =F4 | G5: ='Financial Worksheet'!$B$4/('Financial Worksheet'!$B$10*12) -> 0 | H5: =('Updated Chargers Revenue Calcul'!$J$24/12)*1.125^INT((E5-1)/12) -> 0 | I5: =(G5+H5)-F5 -> #VALUE!
E6: =E5+1 -> 4 | F6: =F5 | G6: ='Financial Worksheet'!$B$4/('Financial Worksheet'!$B$10*12) -> 0 | H6: =('Updated Chargers Revenue Calcul'!$J$24/12)*1.125^INT((E6-1)/12) -> 0 | I6: =(G6+H6)-F6 -> #VALUE!
E7: =E6+1 -> 5 | F7: =F6 | G7: ='Financial Worksheet'!$B$4/('Financial Worksheet'!$B$10*12) -> 0 | H7: =('Updated Chargers Revenue Calcul'!$J$24/12)*1.125^INT((E7-1)/12) -> 0 | I7: =(G7+H7)-F7 -> #VALUE!
E8: =E7+1 -> 6 | F8: =F7 | G8: ='Financial Worksheet'!$B$4/('Financial Worksheet'!$B$10*12) -> 0 | H8: =('Updated Chargers Revenue Calcul'!$J$24/12)*1.125^INT((E8-1)/12) -> 0 | I8: =(G8+H8)-F8 -> #VALUE!
E9: =E8+1 -> 7 | F9: =F8 | G9: ='Financial Worksheet'!$B$4/('Financial Worksheet'!$B$10*12) -> 0 | H9: =('Updated Chargers Revenue Calcul'!$J$24/12)*1.125^INT((E9-1)/12) -> 0 | I9: =(G9+H9)-F9 -> #VALUE!
E10: =E9+1 -> 8 | F10: =F9 | G10: ='Financial Worksheet'!$B$4/('Financial Worksheet'!$B$10*12) -> 0 | H10: =('Updated Chargers Revenue Calcul'!$J$24/12)*1.125^INT((E10-1)/12) -> 0 | I10: =(G10+H10)-F10 -> #VALUE!
E11: =E10+1 -> 9 | F11: =F10 | G11: ='Financial Worksheet'!$B$4/('Financial Worksheet'!$B$10*12) -> 0 | H11: =('Updated Chargers Revenue Calcul'!$J$24/12)*1.125^INT((E11-1)/12) -> 0 | I11: =(G11+H11)-F11 -> #VALUE!
E12: =E11+1 -> 10 | F12: =F11 | G12: ='Financial Worksheet'!$B$4/('Financial Worksheet'!$B$10*12) -> 0 | H12: =('Updated Chargers Revenue Calcul'!$J$24/12)*1.125^INT((E12-1)/12) -> 0 | I12: =(G12+H12)-F12 -> #VALUE!
E13: =E12+1 -> 11 | F13: =F12 | G13: ='Financial Worksheet'!$B$4/('Financial Worksheet'!$B$10*12) -> 0 | H13: =('Updated Chargers Revenue Calcul'!$J$24/12)*1.125^INT((E13-1)/12) -> 0 | I13: =(G13+H13)-F13 -> #VALUE!
E14: =E13+1 -> 12 | F14: =F13 | G14: ='Financial Worksheet'!$B$4/('Financial Worksheet'!$B$10*12) -> 0 | H14: =('Updated Chargers Revenue Calcul'!$J$24/12)*1.125^INT((E14-1)/12) -> 0 | I14: =(G14+H14)-F14 -> #VALUE!
E15: =E14+1 -> 13 | F15: =F14 | G15: ='Financial Worksheet'!$B$4/('Financial Worksheet'!$B$10*12) -> 0 | H15: =('Updated Chargers Revenue Calcul'!$J$24/12)*1.125^INT((E15-1)/12) -> 0 | I15: =(G15+H15)-F15 -> #VALUE!
E16: =E15+1 -> 14 | F16: =F15 | G16: ='Financial Worksheet'!$B$4/('Financial Worksheet'!$B$10*12) -> 0 | H16: =('Updated Chargers Revenue Calcul'!$J$24/12)*1.125^INT((E16-1)/12) -> 0 | I16: =(G16+H16)-F16 -> #VALUE!
E17: =E16+1 -> 15 | F17: =F16 | G17: ='Financial Worksheet'!$B$4/('Financial Worksheet'!$B$10*12) -> 0 | H17: =('Updated Chargers Revenue Calcul'!$J$24/12)*1.125^INT((E17-1)/12) -> 0 | I17: =(G17+H17)-F17 -> #VALUE!
... E62: =E61+1 -> 60 | F62: =F61 | G62: ='Financial Worksheet'!$B$4/('Financial Worksheet'!$B$10*12) -> 0 | H62: =('Updated Chargers Revenue Calcul'!$J$24/12)*1.125^INT((E62-1)/12) -> 0 | I62: =(G62+H62)-F62 -> #VALUE!

Sheet Updated Chargers Revenue Calcul
B1: STANDARD-DAY | X1: FLEET-NIGHT
A3: Revenues | B3: Standard-Low | I3: Standard-Med | P3: Standard-High | X3: Fleet-Low | Y3: Fleet-Med | Z3: Fleet-High
B4: Level 2 | C4: ="L3 ("&'INPUT SHEET'!O10&" kW)" -> L3 (60 kW) | D4: ="L3 ("&'INPUT SHEET'!P10&" kW)" -> L3 (120 kW) | E4: ="L3 ("&'INPUT SHEET'!Q10&" kW)" -> L3 (160 kW) | F4: ="L3 ("&'INPUT SHEET'!R10&" kW)" -> L3 (180 kW) | G4: ="L3 ("&'INPUT SHEET'!S10&" kW)" -> L3 (240 kW) | H4: ="L3 ("&'INPUT SHEET'!T10&" kW)" -> L3 (360 kW) | I4: Level 2 | J4: ="L3 ("&'INPUT SHEET'!O10&" kW)" -> L3 (60 kW) | K4: ="L3 ("&'INPUT SHEET'!P10&" kW)" -> L3 (120 kW) | L4: ="L3 ("&'INPUT SHEET'!Q10&" kW)" -> L3 (160 kW) | M4: ="L3 ("&'INPUT SHEET'!R10&" kW)" -> L3 (180 kW) | N4: ="L3 ("&'INPUT SHEET'!S10&" kW)" -> L3 (240 kW) | O4: ="L3 ("&'INPUT SHEET'!T10&" kW)" -> L3 (360 kW) | P4: Level 2 | Q4: ="L3 ("&'INPUT SHEET'!O10&" kW)" -> L3 (60 kW) | R4: ="L3 ("&'INPUT SHEET'!P10&" kW)" -> L3 (120 kW) | S4: ="L3 ("&'INPUT SHEET'!Q10&" kW)" -> L3 (160 kW) | T4: ="L3 ("&'INPUT SHEET'!R10&" kW)" -> L3 (180 kW) | U4: ="L3 ("&'INPUT SHEET'!S10&" kW)" -> L3 (240 kW) | V4: ="L3 ("&'INPUT SHEET'!T10&" kW)" -> L3 (360 kW) | X4: Level 2 | Y4: Level 2 | Z4: Level 2
A5: Chargers | B5: ='INPUT SHEET'!N8 -> 0 | C5: ='INPUT SHEET'!O8 -> 0 | D5: ='INPUT SHEET'!P8 -> 0 | E5: ='INPUT SHEET'!Q8 -> 0 | F5: ='INPUT SHEET'!R8 -> 0 | G5: ='INPUT SHEET'!S8 -> 0 | H5: ='INPUT SHEET'!T8 -> 0 | I5: =B5 -> 0 | J5: =C5 -> 0 | K5: =D5 -> 0 | L5: =E5 -> 0 | M5: =F5 -> 0 | N5: =G5 -> 0 | O5: =H5 -> 0 | P5: =B5 -> 0 | Q5: =C5 -> 0 | R5: =D5 -> 0 | S5: =E5 -> 0 | T5: =F5 -> 0 | U5: =G5 -> 0 | V5: =H5 -> 0 | X5: =B5 -> 0 | Y5: =B5 -> 0 | Z5: =B5 -> 0
A6: EV Stall Quantity (Based on # of ports) | B6: ='INPUT SHEET'!N9 -> 0 | C6: ='INPUT SHEET'!O9 -> 0 | D6: ='INPUT SHEET'!P9 -> 0 | E6: ='INPUT SHEET'!Q9 -> 0 | F6: ='INPUT SHEET'!R9 -> 0 | G6: ='INPUT SHEET'!S9 -> 0 | H6: ='INPUT SHEET'!T9 -> 0 | I6: =B6 -> 0 | J6: =C6 -> 0 | K6: =D6 -> 0 | L6: =E6 -> 0 | M6: =F6 -> 0 | N6: =G6 -> 0 | O6: =H6 -> 0 | P6: =B6 -> 0 | Q6: =C6 -> 0 | R6: =D6 -> 0 | S6: =E6 -> 0 | T6: =F6 -> 0 | U6: =G6 -> 0 | V6: =H6 -> 0 | X6: =B6 -> 0 | Y6: =B6 -> 0 | Z6: =B6 -> 0
A7: Max hours of operation of parking | B7: 24 | C7: 24 | D7: 24 | E7: 24 | F7: 24 | G7: 24 | H7: 24 | I7: 12 | J7: 12 | K7: 12 | L7: 12 | M7: 12 | N7: 12 | O7: 12 | P7: 12 | Q7: 12 | R7: 12 | S7: 12 | T7: 12 | U7: 12 | V7: 12 | X7: 12 | Y7: 12 | Z7: 12
A8: Assumed Stall Occupancy % | B8: 0.2 | C8: 0.2 | D8: 0.2 | E8: 0.2 | F8: 0.2 | G8: 0.2 | H8: 0.2 | I8: =I20 -> 0.45 | J8: =J20 -> 0.5 | K8: =K20 -> 0.5 | L8: =L20 -> 0.5 | M8: =M20 -> 0.5 | N8: =N20 -> 0.5 | O8: =O20 -> 0.5 | P8: =P20 -> 0.6 | ... Z8: =Z20 -> 0.6
A9: Number of stalls used per day | B9: =B6*B8 -> 0 | C9: =C6*C8 -> 0 | D9: =D6*D8 -> 0 | E9: =E6*E8 -> 0 | F9: =F6*F8 -> 0 | G9: =G6*G8 -> 0 | H9: =H6*H8 -> 0 | I9: =I6*I8 -> 0 | ... V9: =V6*V8 -> 0 | X9: =X6*X8 -> 0 | Y9: =Y6*Y8 -> 0 | Z9: =Z6*Z8 -> 0
A10: Assumed Charging Hourly % per stall per day | B10: =B21 -> 0.5 | C10: =C21 -> 0.5 | D10: =D21 -> 0.5 | E10: =E21 -> 0.5 | F10: =F21 -> 0.5 | G10: =G21 -> 0.5 | H10: =H21 -> 0.5 | I10: =I21 -> 0.75 | ... Z10: =Z21 -> 0.85
A11: Number of hours usage per stall per day | B11: =B10*B7 -> 6 | C11: =C10*C7 -> 6 | D11: =D10*D7 -> 6 | E11: =E10*E7 -> 6 | F11: =F10*F7 -> 6 | G11: =G10*G7 -> 6 | H11: =H10*H7 -> 6 | I11: =I10*I7 -> 9 | ... V11: =V10*V7 -> 10.2 | X11: =X10*X7 -> 6 | Y11: =Y10*Y7 -> 9 | Z11: =Z10*Z7 -> 10.2
A12: Actual Charger Rating | B12: ='INPUT SHEET'!N10*'INPUT SHEET'!$N$11 -> 7.056 | C12: =30*0.98 -> 29.4 | D12: =60*0.98 -> 58.8 | E12: =80*0.98 -> 78.4 | F12: =90*0.98 -> 88.2 | G12: =120*0.98 -> 117.6 | H12: =180*0.98 -> 176.4 | I12: =B12 -> 7.056 | J12: =C12 -> 29.4 | K12: =D12 -> 58.8 | L12: =E12 -> 78.4 | M12: =F12 -> 88.2 | N12: =G12 -> 117.6 | O12: =H12 -> 176.4 | P12: =B12 -> 7.056 | Q12: =C12 -> 29.4 | R12: =D12 -> 58.8 | S12: =E12 -> 78.4 | T12: =F12 -> 88.2 | U12: =G12 -> 117.6 | V12: =H12 -> 176.4 | X12: =B12 -> 7.056 | Y12: =B12 -> 7.056 | Z12: =B12 -> 7.056
A13: Retail Revenue per kWHr | B13: 0.65 | C13: =B13 -> 0.65 | D13: =C13 -> 0.65 | E13: =D13 -> 0.65 | F13: =E13 -> 0.65 | G13: =F13 -> 0.65 | H13: =G13 -> 0.65 | I13: =B13 -> 0.65 | J13: =B13 -> 0.65 | K13: =C13 -> 0.65 | L13: =D13 -> 0.65 | M13: =E13 -> 0.65 | N13: =F13 -> 0.65 | O13: =G13 -> 0.65 | P13: =B13 -> 0.65 | Q13: =B13 -> 0.65 | R13: =C13 -> 0.65 | S13: =D13 -> 0.65 | T13: =E13 -> 0.65 | U13: =F13 -> 0.65 | V13: =G13 -> 0.65 | X13: 0.65 | Y13: =X13 -> 0.65 | Z13: =X13 -> 0.65
A14: Total Revenue per day | B14: =B13*B16 -> 0 | C14: =C13*C16 -> 0 | D14: =D13*D16 -> 0 | E14: =E13*E16 -> 0 | F14: =F13*F16 -> 0 | G14: =G13*G16 -> 0 | H14: =H13*H16 -> 0 | I14: =I13*I16 -> 0 | ... V14: =V13*V16 -> 0 | X14: =X13*X16 -> 0 | Y14: =Y13*Y16 -> 0 | Z14: =Z13*Z16 -> 0
A15: Per month (days per year ÷ 12) | B15: =B14*B36/12 -> 0 | C15: =C14*C36/12 -> 0 | D15: =D14*D36/12 -> 0 | E15: =E14*E36/12 -> 0 | F15: =F14*F36/12 -> 0 | G15: =G14*G36/12 -> 0 | H15: =H14*H36/12 -> 0 | I15: =I14*I36/12 -> 0 | ... V15: =V14*V36/12 -> 0 | X15: =X14*X36/12 -> 0 | Y15: =Y14*Y36/12 -> 0 | Z15: =Z14*Z36/12 -> 0
A16: Total kWhr dispensed per day | B16: =B9*B11*B35 -> 0 | C16: =C9*C11*C35 -> 0 | D16: =D9*D11*D35 -> 0 | E16: =E9*E11*E35 -> 0 | F16: =F9*F11*F35 -> 0 | G16: =G9*G11*G35 -> 0 | H16: =H9*H11*H35 -> 0 | I16: =I9*I11*I35 -> 0 | ... V16: =V9*V11*V35 -> 0 | X16: =X9*X11*X35 -> 0 | Y16: =Y9*Y11*Y35 -> 0 | Z16: =Z9*Z11*Z35 -> 0
A17: EV Utility Rate average per kWHr | B17: =B46 -> 0 | C17: =C46 -> 0 | D17: =D46 -> 0 | E17: =E46 -> 0 | F17: =F46 -> 0 | G17: =G46 -> 0 | H17: =H46 -> 0 | I17: =I46 -> 0 | ... V17: =V46 -> 0 | X17: =X46 -> 0.25 | Y17: =Y46 -> 0.25 | Z17: =Z46 -> 0.25
A18: Net Profit per Month | B18: =B15-(B16*B17*B36/12) -> 0 | C18: =C15-(C16*C17*C36/12) -> 0 | D18: =D15-(D16*D17*D36/12) -> 0 | E18: =E15-(E16*E17*E36/12) -> 0 | F18: =F15-(F16*F17*F36/12) -> 0 | G18: =G15-(G16*G17*G36/12) -> 0 | H18: =H15-(H16*H17*H36/12) -> 0 | I18: =I15-(I16*I17*I36/12) -> 0 | ... V18: =V15-(V16*V17*V36/12) -> 0 | X18: =X15-(X16*X17*X36/12) -> 0 | Y18: =Y15-(Y16*Y17*Y36/12) -> 0 | Z18: =Z15-(Z16*Z17*Z36/12) -> 0
A19: Total Profit per Year | B19: =B18*12 -> 0 | C19: =C18*12 -> 0 | D19: =D18*12 -> 0 | E19: =E18*12 -> 0 | F19: =F18*12 -> 0 | G19: =G18*12 -> 0 | H19: =H18*12 -> 0 | I19: =I18*12 -> 0 | ... V19: =V18*12 -> 0 | X19: =X18*12 -> 0 | Y19: =Y18*12 -> 0 | Z19: =Z18*12 -> 0
A20: Modify Stall Occupancy % here | B20: 0.2 | C20: 0.2 | D20: 0.2 | E20: 0.2 | F20: 0.2 | G20: 0.2 | H20: 0.2 | I20: 0.45 | J20: 0.5 | K20: 0.5 | L20: 0.5 | M20: 0.5 | N20: 0.5 | O20: 0.5 | P20: 0.6 | Q20: 0.7 | R20: 0.7 | S20: 0.7 | T20: 0.7 | U20: 0.7 | V20: 0.7 | X20: 0.2 | Y20: 0.45 | Z20: 0.6
A21: Modify Charging Hourly percentage per stall per day | B21: 0.25 | C21: 0.25 | D21: 0.25 | E21: 0.25 | F21: 0.25 | G21: 0.25 | H21: 0.25 | I21: 0.75 | J21: 0.75 | K21: 0.75 | L21: 0.75 | M21: 0.75 | N21: 0.75 | O21: 0.75 | P21: 0.85 | Q21: 0.85 | R21: 0.85 | S21: 0.85 | T21: 0.85 | U21: 0.85 | V21: 0.85 | X21: 0.5 | Y21: 0.75 | Z21: 0.85
