Workbook

Sheet Version
A1: DOCUMENT CONTROL
A2: Hardcoded. These values identify which generation of the template a returned file came from — never make them formulas.
A4: Template version | B4: 2.9.0
A5: Released | B5: 2026-08-29
A6: Template name | B6: EVSE Project Intake
A7: Issued by | B7: Zero Impact Energy
A8: Template content hash | B8: 4aecae7d4b5f25a9 | C8: The hash of the BLANK template this file was built from, frozen at its release. It does not change when you fill the sheet in.
A9: Completed by — fill these in
A10: This file version | B10: Rev A | C10: e.g. Rev A, Rev B — increment each time you send it back
A11: Date completed | B11: 46267
A12: Completed by | B12: Test CPM
A13: Project reference | B13: BW-TEST-001
A14: Notes on this revision | B14: Fixture for the importer test | C14: What changed since the last version you sent
A15: File content hash | B15: 4aecae7d4b5f25a9 | C15: A hash of THIS workbook. It changes every time someone edits it, and it is what a model records so you can tell whether the model was built from the file in front of you.
A16: Changelog
A17: Version | B17: Released | C17: What changed
A18: 1.0.0 | B18: 2026-08-26 | C18: Initial release — project, equipment, electrical, construction, commercial, revenue and carbon intake with live consistency checks.
A19: 1.1.0 | B19: 2026-08-26 | C19: Deal structure knobs and the override register. Base case unchanged at zero.
A20: 1.2.0 | B20: 2026-08-26 | C20: PG&E Rule 29 interconnection capture. Electrical materials costed independently of the EVSE price book.
A21: 1.3.0 | B21: 2026-08-26 | C21: Utility rate engine across PG&E, SCE and SDG&E. Market benchmarks. Demand subscription ramps with concurrency.
A22: 1.4.0 | B22: 2026-08-26 | C22: Scope of supply controls — each service line can be provided by us, by others, or not required. Document control added.
A23: 1.5.0 | B23: 2026-08-26 | C23: Mixed-fleet fix — accessories no longer counted as charging units, and the placement check compares against DC cabinets only.
A24: 1.6.0 | B24: 2026-08-26 | C24: Description was not recorded at the time. The change sits between the mixed-fleet fix (1.5.0) and the rip-and-replace capability (1.7.0).
A25: 1.7.0 | B25: 2026-08-26 | C25: Rip-and-replace project type. A new Existing tab captures the existing installation, the retained-versus-replaced register, thirty-six months of usage and billing history, port and connector expansion, and the removal scope. Tabs 3, 4 and 6 respond to what is retained and can now be driven from historical actuals.
A26: 1.8.0 | B26: 2026-08-26 | C26: Utility selection became a dropdown of every California delivery utility — 56 investor-owned, publicly owned, tribal and cooperative entities that set their own retail tariff. New Utilities tab carries the roster and the community choice aggregators separately, because a CCA sets generation only and cannot set an EV tariff. New RateLibrary tab carries 32 researched commercial EV and fallback rates with a STATUS column, plus the utility rebate programmes and their open/closed state.
A27: 1.9.0 | B27: 2026-08-27 | C27: Price book states the included manufacturer warranty per charger class — two years on DC fast charging, one year on Level 2, parts only — and the out-of-warranty service column now reads NOT OFFERED rather than sitting blank, because a blank reads as zero to anything consuming the table. Service is sold only against a warranty in force, included or extended.
A28: 1.10.0 | B28: 2026-08-27 | C28: Capacity-first equipment picker on 2_Equipment. Pick a capacity — 60 kW, 120 kW, 360 kW, Level 2 and so on — and the SKU dropdown narrows to that capacity, five to fourteen SKUs instead of ninety-two. The capacity also supplies the rating kW where the price book records none, which it does for every Level 2, Buy America and V2G row; a Buy America 60 kW cabinet previously counted as zero kW and zero cabinets. A DC-only capacity line is added and the carbon credit repointed at it, because the LCFS credit is paid on DC capacity alone.
... A46: 2.9.0 | B46: 2026-08-29 | C46: The demand subscription is computed. This template declared a subscription policy, supplied every input a ramp needs and left both outputs blank, so on a schedule that sells capacity in blocks the largest operating cost on a high-capacity site was not in the workbook at all. Expected peak concurrency and Subscribed kW are now derived from the day's energy, the peak-to-average factor and the safety margin; the block size and price are read from the rate library; and the annual cost joins the fixed-and-demand line the project model reads. Where the library carries no block for a schedule the cost is zero and the check says UNPRICED with the subscribed capacity in it, because a zero that nobody has priced is an absence and not a saving.

Sheet README
A1: EVSE PROJECT INTAKE
A2: Zero Impact Energy — one form, one project. Fill the blue cells; everything else is derived.
A4: How to use this workbook
A5: • | B5: Fill in every BLUE cell you can. Leave a cell blank rather than guessing — a blank is a question we will ask; a guess becomes a number in a proposal.
A6: • | B6: YELLOW cells are key commercial assumptions. They have sensible defaults, but they drive the return — change them deliberately, not by habit.
A7: • | B7: GREEN cells are live checks. They recalculate as you type. If a green cell turns into a warning, the sheet is telling you two of your inputs disagree.
A8: • | B8: GREY tabs (Lists, PriceBook, RefData) are reference data. Do not edit them unless prices have actually changed.
A9: • | B9: When the form is complete, send the file back. Everything downstream — electrical sizing, materials, labour, revenue, carbon, financing, the proposal — is computed from these inputs alone.
A11: Cell legend
A12: Appearance | B12: Meaning | C12: What to do
A13: Blue fill, blue text | B13: Human input | C13: Fill it in
A14: Yellow fill, blue bold | B14: Key commercial assumption | C14: Review the default, change deliberately
A15: Green fill, green text | B15: Live check / derived | C15: Read it — never type over it
A16: Grey | B16: Reference data | C16: Leave alone
A18: Tabs, in the order you should fill them
A19: 1_Project | B19: Who, where, which utility, and how the site is accessed
A20: 2_Equipment | B20: What is being sold — pick SKUs from the price book
A21: 3_Electrical | B21: Distances, wire, existing service. Drives every electrical cost.
A22: 4_Construction | B22: Site works, labour days, ADA, permits, rentals
A23: 5_Commercial | B23: Discounts, financing terms, service and network term
A24: 6_Revenue | B24: Pricing, utilisation, ramp and growth
A25: 7_Carbon | B25: FCI credit rate, aggregator, eligibility, grants
A27: 8_Deal_Structure | B27: Optional. Knobs for trading price against a share of credits or revenue.
A28: 9_Overrides | B28: Optional. Force any derived value when you have a quote or a measurement.
A30: Version | B30: Template 1.4.0, released 2026-08-26 — see the Version tab
A32: Replacement projects
A33: • | B33: The Existing tab is the difference between a greenfield project and a charger swap. Complete it whenever the site already has charging equipment.
A34: • | B34: Set the project type on the Existing tab section A first — every other check on that tab keys off it.
A35: • | B35: Section B is the register that decides the cost. Marking the service, feeder, switchgear and conduit as RETAIN removes most of the electrical and civil scope; the Electrical and Construction tabs then tell you exactly which lines to zero.
A36: • | B36: Section E is the most valuable page in the whole intake. Twelve months of metered history beats every market assumption on the Revenue tab, and twenty-four months beats twelve. Enter outage months as they happened — do not smooth them.
A37: • | B37: Sections F and G turn the old installation into a projection: availability recovered, ports added, connector coverage widened and power increased, each with its own capture factor you can argue with.
A38: • | B38: Section H is the removal scope. It is zero on a greenfield project and real money on a replacement.
A39: • | B39: Set the revenue basis at the foot of the Revenue tab to "Historical actuals" on any replacement site with twelve or more months of data.
A41: Choosing the utility
A42: • | B42: Pick the DELIVERY utility on the Project tab — the one that owns the wires and sets the tariff. If the site buys generation from a community choice aggregator, still pick the delivery utility; the CCA is a separate field below it.
A43: • | B43: A CCA changes only the generation cents per kWh. Eligibility, time-of-use periods, the demand subscription and every delivery charge stay with the utility. Build the bill from the delivery tariff and substitute one line.
A44: • | B44: Rule 29 exists only at investor-owned utilities. A municipal utility, irrigation district or cooperative has its own line-extension policy and the cost split can be completely different — do not carry a Rule 29 allowance on a POU site.
A45: • | B45: Read the STATUS column on RateLibrary before using any rate. VERIFIED means it was read in the utility's own tariff. NOT PUBLISHED means the utility does not publish it — SCE is the significant case — and those rows are left at zero deliberately rather than filled with a guess.
A46: • | B46: Whether a utility has an EV tariff at all is often worth more than the cents per kWh. A site on a utility with no EV rate pays full demand charges on a general commercial schedule, which at low utilisation dominates the bill.
A48: Returning this workbook
...

Sheet Project
A1: 1 · PROJECT AND SITE
A2: Identity, location, utility and access policy.
A4: Client
A5: Client legal name | B5: Best Western Hawthorne | C5: As it will appear on the proposal
A6: Client contact name | B6: Mohammad Noorali
A7: Contact title | B7: General Manager
A8: Contact email | B8: gm@example.com
A9: Contact phone | B9: 310-555-0100
A11: Site
A12: Site name | B12: Best Western Hawthorne
A13: Street address | B13: 15000 Hawthorn Blvd
A14: City / State / ZIP | B14: Hawthorne, CA 90260
A15: County | B15: Los Angeles
A16: Property type | B16: Hotel | C16: Retail, dealership, fleet depot, hotel, grocery…
A17: Project type | B17: =Existing!B5 | C17: Set this on the Existing tab. A replacement site must complete the Existing tab in full; a greenfield site leaves it blank.
A18: Existing chargers on site? | B18: =IF(Existing!B43=0,"None",TEXT(Existing!B43,"0")&" ports across "&TEXT(Existing!B42,"0")&" units — see the Existing tab") | C18: Derived from the equipment schedule on the Existing tab.
A20: Access and operating policy
A21: Public access | B21: Public 24/7 | C21: Public 24/7 / Public during business hours / Restricted
A22: Hours open per day | B22: 24 | C22: CRITICAL: 24 unless access is genuinely gated
A23: Days open per year | B23: 365 | C23: Use 365 unless the site closes seasonally
A25: Utility
A26: Electric utility (delivery) | B26: SCE — Southern California Edison | C26: Pick from the list. This is the utility that DELIVERS power and therefore sets the EV tariff — see the Utilities tab. If the site is served by a community choice aggregator, still pick the delivery utility here.
A27: Current rate schedule | B27: TOU-GS-2 | C27: From a recent bill
A28: Existing service size (A) | B28: 800 | C28: Main service amperage today
A29: Service voltage | B29: 480 | C29: Usually 480V 3-phase for DC fast charging
A30: 12 months of bills obtained? | B30: Yes | C30: Yes / No — needed to validate the energy cost
A32: Commercial
A33: Proposal date | B33: 46266
A34: Proposal validity (days) | B34: 30
A35: Prepared by | B35: Vatsal Patel
A36: RSM / account owner | B36: Account Owner
A39: Utility context — derived from the selection above
A40: These read the Utilities and RateLibrary tabs. They tell you what tariff regime the site sits in before anyone opens a tariff book.
A41: Utility type | B41: =IFERROR(INDEX(Utilities!$K$5:$K$78,MATCH($B$26,Utilities!$J$5:$J$78,0)),"") | C41: IOU utilities are CPUC-regulated and follow Rule 29. POUs and co-ops set their own rules — no Rule 29, no PCIA, their own interconnection process.
A42: Service territory | B42: =IFERROR(INDEX(Utilities!$L$5:$L$78,MATCH($B$26,Utilities!$J$5:$J$78,0)),"")
A43: EV rate status | B43: =IFERROR(INDEX(Utilities!$M$5:$M$78,MATCH($B$26,Utilities!$J$5:$J$78,0)),"") | C43: Whether this utility publishes a commercial EV tariff at all. Where it does not, the site pays full demand charges on a general commercial schedule — usually the single largest difference between two otherwise identical sites.
A44: Rate rows in the library | B44: =COUNTIF(RATE_UTIL,$B$26) | C44: How many schedules the library carries for this utility. Zero means it has not been researched — obtain the tariff.
A45: Best status in the library | B45: =IF(COUNTIF(RATE_UTIL,$B$26)=0,"NOT RESEARCHED — obtain the tariff at site selection",IF(COUNTIFS(RATE_UTIL,$B$26,RATE_STATUS,"VERIFIED")>0,"VERIFIED rates available",IF(COUNTIFS(RATE_UTIL,$B$26,RATE_STATUS,"PARTIAL")>0,"PARTIAL — some fields missing, read the row before pricing","UNVERIFIED — the library carries a rate but nobody has checked it against the filed tariff"))) | C45: Never price a project from a NOT PUBLISHED row. Get the tariff sheet or a written rate quotation.
A46: Community choice aggregator, if any | B46: Clean Power Alliance | C46: A CCA changes ONLY the generation $/kWh. Eligibility, time-of-use periods, the demand subscription and every delivery charge stay with the utility above.
A47: CCA delivery utility check | B47: =IF(OR($B$46="",$B$46="None — bundled utility service"),"n/a — no aggregator",IF(IFERROR(INDEX(Utilities!$N$5:$N$78,MATCH($B$26,Utilities!$J$5:$J$78,0)),"")<>"California","n/a — community choice aggregation is a California mechanism",IFERROR(IF(ISNUMBER(SEARCH(LEFT($B$26,4),INDEX(Utilities!$C$67:$C$93,MATCH($B$46,Utilities!$A$67:$A$93,0)))),"OK — this CCA operates in the selected utility territory","CHECK — this CCA normally rides "&INDEX(Utilities!$C$67:$C$93,MATCH($B$46,Utilities!$A$67:$A$93,0))&" delivery"),"CHECK the pairing"))) | C47: Catches an aggregator paired with the wrong delivery utility. Central Coast Community Energy genuinely spans both PG&E and SCE, so it will flag — settle the host utility by address. Silent where no aggregator is named and outside California, where the mechanism does not exist.
...

Sheet Existing
A1: 1B · EXISTING INSTALLATION — RIP AND REPLACE
A2: Complete this tab only when the site already has charging equipment. On a greenfield site leave it blank and the model ignores it entirely. On a replacement site this tab is the most valuable page in the intake, because it replaces market assumptions with the site's own operating history.
A4: A · Project type
A5: Project type | B5: Rip and replace — reuse infrastructure | C5: Greenfield builds everything. Rip and replace swaps the chargers and reuses the electrical infrastructure. Replace and expand does both — new chargers plus added capacity.
A6: Age of the existing installation (years) | B6: 7 | C6: Drives whether the existing conductors and gear are worth reusing.
A7: Reason for replacement | B7: End of life and unreliable | C7: End of life, unreliability, obsolete connectors, insufficient power, or a commercial decision.
A8: Who owns the existing equipment? | B8: Client | C8: If a third party owns it, removal and disposal need their agreement.
A10: B · What is retained and what is replaced
A11: This register is the whole commercial difference between a greenfield project and a replacement. Every line marked RETAIN removes cost from the electrical and construction scope. Every line marked REPLACE puts it back. Answer honestly — a conductor that is retained on paper and re-pulled in the field is a change order.
A12: Element | B12: Decision | C12: Basis for the decision
A13: Utility service and meter | B13: RETAIN | C13: Existing service stays. No Rule 29 application, no new meter.
A14: Service feeder to switchgear | B14: RETAIN | C14: Conductor from the point of delivery to the switchboard.
A15: Main distribution switchgear | B15: REPLACE | C15: Switchboard, main breaker and metering section.
A16: Branch conductors to each charger | B16: RETAIN | C16: The feeders from switchgear to cabinet. The single largest reuse saving.
A17: Conduit and trench | B17: RETAIN | C17: Existing conduit reused; no re-trenching if the new cabinets land on the same pads.
A18: Branch breakers | B18: REPLACE | C18: Sized to the new cabinet, not the old one. Usually cheap and always worth replacing.
A19: Concrete pads | B19: REPLACE | C19: New cabinets rarely match the old footprint or anchor pattern.
A20: Bollards and equipment protection | B20: REPLACE | C20: Usually disturbed by pad removal.
A21: Paving and striping | B21: PARTIAL | C21: Reinstatement around the new pads only.
A22: ADA stalls and route | B22: RETAIN | C22: Reused if the layout is unchanged and still compliant.
A23: Signage | B23: REPLACE | C23: Network branding, pricing and connector types all change.
A24: Network and payment hardware | B24: REPLACE | C24: Integrated in the new cabinets.
A26: Elements retained | B26: =COUNTIF($B$13:$B$24,"RETAIN") | C26: Of 12 in the register.
A27: Elements replaced | B27: =COUNTIF($B$13:$B$24,"REPLACE")+COUNTIF($B$13:$B$24,"PARTIAL")
A28: Scope profile | B28: =IF($B$13="RETAIN",IF($B$14="RETAIN","Infrastructure reuse — no new service, no new feeder","Service retained, feeder replaced"),"New or upgraded service — price this as greenfield electrical") | D28: What the retained register implies for the electrical scope on the Electrical tab.
A30: C · Existing equipment being removed
A31: One row per existing cabinet or unit. This drives the demolition, disconnection and disposal scope on the Construction tab, and the port comparison in section F.
A32: Make and model | B32: Rating kW | C32: Ports | D32: Connectors | E32: Qty | F32: Year installed | G32: Working?
A33: ABB Terra 54 | B33: 50 | C33: 2 | D33: CCS1 / CHAdeMO | E33: 2 | F33: 2018 | G33: Working
A34: ChargePoint Express 250 | B34: 62.5 | C34: 1 | D34: CCS1 | E34: 2 | F34: 2019 | G34: Failed
A42: Existing units on site | B42: =SUM($E$33:$E$40) | C42: Cabinets or standalone units to be removed.
A43: Existing ports on site | B43: =SUMPRODUCT($C$33:$C$40,$E$33:$E$40) | C43: Ports the site presents today.
A44: Existing connected load (kW) | B44: =SUMPRODUCT($B$33:$B$40,$E$33:$E$40) | C44: The load the existing service was sized for. Compare against the new load on the Electrical tab.
A45: Units fully working | B45: =SUMIF($G$33:$G$40,"Working",$E$33:$E$40) | C45: Quantity, not row count. The gap against units on site is the availability the new equipment recovers.
A46: Units failed or intermittent | B46: =SUMIF($G$33:$G$40,"Failed",$E$33:$E$40)+SUMIF($G$33:$G$40,"Intermittent",$E$33:$E$40) | C46: What the replacement is actually fixing.
A47: Units of unknown condition | B47: =SUMIF($G$33:$G$40,"Unknown",$E$33:$E$40) | C47: The availability uplift on the revenue projection is built from what was working and what was not. Anything in this row is a projection input nobody has established yet.
A48: D · Existing electrical infrastructure
A49: What is already in the ground. Where a line is being retained, this is what the new design has to work with; where it is being replaced, this is what has to come out.
A50: Existing service size (A) | B50: 800 | C50: From the meter panel or the utility bill.
A51: Existing service voltage | B51: 480 | C51: 480V three-phase for most DC sites.
...

Sheet Equipment
A1: 2 · EQUIPMENT SCHEDULE
A2: Pick the CAPACITY first, then the SKU. A distributed system is TWO kinds of line: the power cabinet, and each dispenser it feeds.
A4: Enter one row per SKU. Qty is the number of CABINETS, not ports.
A6: Line | B6: Capacity | C6: SKU | D6: Description (auto) | E6: Role (auto) | F6: DC output kW (auto) | G6: AC input kW (auto) | H6: Connectors (auto) | I6: Qty (units) | J6: Discount — set on the Commercial tab | K6: MSRP each (auto) | L6: Dispenser SKU (distributed only) | M6: Max dispensers (auto) | N6: Dispensers per cabinet | O6: Connectors per dispenser (1 or 2) | P6: Dispenser MSRP each (auto)
A7: 1 | B7: 360 kW DC | C7: TP5-360-480-2-300 | D7: =IFERROR(INDEX(PriceBook!$C$2:$C$203,MATCH($C7,PriceBook!$B$2:$B$203,0)),"") | E7: =IF($C7="","",IFERROR(INDEX(ROLE_VAL,MATCH($C7,ROLE_SKU,0)),"all_in_one")) | F7: =IF($C7="",0,IFERROR(INDEX(SPEC_DCKW,MATCH($C7,SPEC_SKU,0)),IF($E7="dispenser",0,IF($E7="accessory",0,IFERROR(IF(N(INDEX(PriceBook!$E$2:$E$203,MATCH($C7,PriceBook!$B$2:$B$203,0)))>0,INDEX(PriceBook!$E$2:$E$203,MATCH($C7,PriceBook!$B$2:$B$203,0)),INDEX(RATED_KW,MATCH($B7,CAPACITY_LIST,0))*IF(INDEX(PER_PORT,MATCH($B7,CAPACITY_LIST,0))=1,MAX(1,N($H7)),1)),0))))) | G7: =IF($C7="",0,IFERROR(INDEX(SPEC_ACKW,MATCH($C7,SPEC_SKU,0)),$F7)) | H7: =IF($C7="",0,IF($E7="power_cabinet",N($N7)*N($O7),IFERROR(INDEX(SPEC_OUTS,MATCH($C7,SPEC_SKU,0)),IFERROR(INDEX(SKU_CONN,MATCH($C7,SKU_ALL,0)),0)))) | I7: 4 | K7: =IFERROR(INDEX(PriceBook!$D$2:$D$203,MATCH($C7,PriceBook!$B$2:$B$203,0)),0) | M7: =IF($E7<>"power_cabinet",0,IFERROR(INDEX(SPEC_MAXDISP,MATCH($C7,SPEC_SKU,0)),0)) | P7: =IF($L7="",0,IFERROR(INDEX(PriceBook!$D$2:$D$203,MATCH($L7,PriceBook!$B$2:$B$203,0)),0))
A8: 2 | B8: Level 2 AC | C8: CTX-C40-240-2 | D8: =IFERROR(INDEX(PriceBook!$C$2:$C$203,MATCH($C8,PriceBook!$B$2:$B$203,0)),"") | E8: =IF($C8="","",IFERROR(INDEX(ROLE_VAL,MATCH($C8,ROLE_SKU,0)),"all_in_one")) | F8: =IF($C8="",0,IFERROR(INDEX(SPEC_DCKW,MATCH($C8,SPEC_SKU,0)),IF($E8="dispenser",0,IF($E8="accessory",0,IFERROR(IF(N(INDEX(PriceBook!$E$2:$E$203,MATCH($C8,PriceBook!$B$2:$B$203,0)))>0,INDEX(PriceBook!$E$2:$E$203,MATCH($C8,PriceBook!$B$2:$B$203,0)),INDEX(RATED_KW,MATCH($B8,CAPACITY_LIST,0))*IF(INDEX(PER_PORT,MATCH($B8,CAPACITY_LIST,0))=1,MAX(1,N($H8)),1)),0))))) | G8: =IF($C8="",0,IFERROR(INDEX(SPEC_ACKW,MATCH($C8,SPEC_SKU,0)),$F8)) | H8: =IF($C8="",0,IF($E8="power_cabinet",N($N8)*N($O8),IFERROR(INDEX(SPEC_OUTS,MATCH($C8,SPEC_SKU,0)),IFERROR(INDEX(SKU_CONN,MATCH($C8,SKU_ALL,0)),0)))) | I8: 2 | K8: =IFERROR(INDEX(PriceBook!$D$2:$D$203,MATCH($C8,PriceBook!$B$2:$B$203,0)),0) | M8: =IF($E8<>"power_cabinet",0,IFERROR(INDEX(SPEC_MAXDISP,MATCH($C8,SPEC_SKU,0)),0)) | P8: =IF($L8="",0,IFERROR(INDEX(PriceBook!$D$2:$D$203,MATCH($L8,PriceBook!$B$2:$B$203,0)),0))
A9: 3 | D9: =IFERROR(INDEX(PriceBook!$C$2:$C$203,MATCH($C9,PriceBook!$B$2:$B$203,0)),"") | E9: =IF($C9="","",IFERROR(INDEX(ROLE_VAL,MATCH($C9,ROLE_SKU,0)),"all_in_one")) | F9: =IF($C9="",0,IFERROR(INDEX(SPEC_DCKW,MATCH($C9,SPEC_SKU,0)),IF($E9="dispenser",0,IF($E9="accessory",0,IFERROR(IF(N(INDEX(PriceBook!$E$2:$E$203,MATCH($C9,PriceBook!$B$2:$B$203,0)))>0,INDEX(PriceBook!$E$2:$E$203,MATCH($C9,PriceBook!$B$2:$B$203,0)),INDEX(RATED_KW,MATCH($B9,CAPACITY_LIST,0))*IF(INDEX(PER_PORT,MATCH($B9,CAPACITY_LIST,0))=1,MAX(1,N($H9)),1)),0))))) | G9: =IF($C9="",0,IFERROR(INDEX(SPEC_ACKW,MATCH($C9,SPEC_SKU,0)),$F9)) | H9: =IF($C9="",0,IF($E9="power_cabinet",N($N9)*N($O9),IFERROR(INDEX(SPEC_OUTS,MATCH($C9,SPEC_SKU,0)),IFERROR(INDEX(SKU_CONN,MATCH($C9,SKU_ALL,0)),0)))) | K9: =IFERROR(INDEX(PriceBook!$D$2:$D$203,MATCH($C9,PriceBook!$B$2:$B$203,0)),0) | M9: =IF($E9<>"power_cabinet",0,IFERROR(INDEX(SPEC_MAXDISP,MATCH($C9,SPEC_SKU,0)),0)) | P9: =IF($L9="",0,IFERROR(INDEX(PriceBook!$D$2:$D$203,MATCH($L9,PriceBook!$B$2:$B$203,0)),0))
A10: 4 | D10: =IFERROR(INDEX(PriceBook!$C$2:$C$203,MATCH($C10,PriceBook!$B$2:$B$203,0)),"") | E10: =IF($C10="","",IFERROR(INDEX(ROLE_VAL,MATCH($C10,ROLE_SKU,0)),"all_in_one")) | F10: =IF($C10="",0,IFERROR(INDEX(SPEC_DCKW,MATCH($C10,SPEC_SKU,0)),IF($E10="dispenser",0,IF($E10="accessory",0,IFERROR(IF(N(INDEX(PriceBook!$E$2:$E$203,MATCH($C10,PriceBook!$B$2:$B$203,0)))>0,INDEX(PriceBook!$E$2:$E$203,MATCH($C10,PriceBook!$B$2:$B$203,0)),INDEX(RATED_KW,MATCH($B10,CAPACITY_LIST,0))*IF(INDEX(PER_PORT,MATCH($B10,CAPACITY_LIST,0))=1,MAX(1,N($H10)),1)),0))))) | G10: =IF($C10="",0,IFERROR(INDEX(SPEC_ACKW,MATCH($C10,SPEC_SKU,0)),$F10)) | H10: =IF($C10="",0,IF($E10="power_cabinet",N($N10)*N($O10),IFERROR(INDEX(SPEC_OUTS,MATCH($C10,SPEC_SKU,0)),IFERROR(INDEX(SKU_CONN,MATCH($C10,SKU_ALL,0)),0)))) | K10: =IFERROR(INDEX(PriceBook!$D$2:$D$203,MATCH($C10,PriceBook!$B$2:$B$203,0)),0) | M10: =IF($E10<>"power_cabinet",0,IFERROR(INDEX(SPEC_MAXDISP,MATCH($C10,SPEC_SKU,0)),0)) | P10: =IF($L10="",0,IFERROR(INDEX(PriceBook!$D$2:$D$203,MATCH($L10,PriceBook!$B$2:$B$203,0)),0))
A11: 5 | D11: =IFERROR(INDEX(PriceBook!$C$2:$C$203,MATCH($C11,PriceBook!$B$2:$B$203,0)),"") | E11: =IF($C11="","",IFERROR(INDEX(ROLE_VAL,MATCH($C11,ROLE_SKU,0)),"all_in_one")) | F11: =IF($C11="",0,IFERROR(INDEX(SPEC_DCKW,MATCH($C11,SPEC_SKU,0)),IF($E11="dispenser",0,IF($E11="accessory",0,IFERROR(IF(N(INDEX(PriceBook!$E$2:$E$203,MATCH($C11,PriceBook!$B$2:$B$203,0)))>0,INDEX(PriceBook!$E$2:$E$203,MATCH($C11,PriceBook!$B$2:$B$203,0)),INDEX(RATED_KW,MATCH($B11,CAPACITY_LIST,0))*IF(INDEX(PER_PORT,MATCH($B11,CAPACITY_LIST,0))=1,MAX(1,N($H11)),1)),0))))) | G11: =IF($C11="",0,IFERROR(INDEX(SPEC_ACKW,MATCH($C11,SPEC_SKU,0)),$F11)) | H11: =IF($C11="",0,IF($E11="power_cabinet",N($N11)*N($O11),IFERROR(INDEX(SPEC_OUTS,MATCH($C11,SPEC_SKU,0)),IFERROR(INDEX(SKU_CONN,MATCH($C11,SKU_ALL,0)),0)))) | K11: =IFERROR(INDEX(PriceBook!$D$2:$D$203,MATCH($C11,PriceBook!$B$2:$B$203,0)),0) | M11: =IF($E11<>"power_cabinet",0,IFERROR(INDEX(SPEC_MAXDISP,MATCH($C11,SPEC_SKU,0)),0)) | P11: =IF($L11="",0,IFERROR(INDEX(PriceBook!$D$2:$D$203,MATCH($L11,PriceBook!$B$2:$B$203,0)),0))
A12: 6 | D12: =IFERROR(INDEX(PriceBook!$C$2:$C$203,MATCH($C12,PriceBook!$B$2:$B$203,0)),"") | E12: =IF($C12="","",IFERROR(INDEX(ROLE_VAL,MATCH($C12,ROLE_SKU,0)),"all_in_one")) | F12: =IF($C12="",0,IFERROR(INDEX(SPEC_DCKW,MATCH($C12,SPEC_SKU,0)),IF($E12="dispenser",0,IF($E12="accessory",0,IFERROR(IF(N(INDEX(PriceBook!$E$2:$E$203,MATCH($C12,PriceBook!$B$2:$B$203,0)))>0,INDEX(PriceBook!$E$2:$E$203,MATCH($C12,PriceBook!$B$2:$B$203,0)),INDEX(RATED_KW,MATCH($B12,CAPACITY_LIST,0))*IF(INDEX(PER_PORT,MATCH($B12,CAPACITY_LIST,0))=1,MAX(1,N($H12)),1)),0))))) | G12: =IF($C12="",0,IFERROR(INDEX(SPEC_ACKW,MATCH($C12,SPEC_SKU,0)),$F12)) | H12: =IF($C12="",0,IF($E12="power_cabinet",N($N12)*N($O12),IFERROR(INDEX(SPEC_OUTS,MATCH($C12,SPEC_SKU,0)),IFERROR(INDEX(SKU_CONN,MATCH($C12,SKU_ALL,0)),0)))) | K12: =IFERROR(INDEX(PriceBook!$D$2:$D$203,MATCH($C12,PriceBook!$B$2:$B$203,0)),0) | M12: =IF($E12<>"power_cabinet",0,IFERROR(INDEX(SPEC_MAXDISP,MATCH($C12,SPEC_SKU,0)),0)) | P12: =IF($L12="",0,IFERROR(INDEX(PriceBook!$D$2:$D$203,MATCH($L12,PriceBook!$B$2:$B$203,0)),0))
A13: 7 | D13: =IFERROR(INDEX(PriceBook!$C$2:$C$203,MATCH($C13,PriceBook!$B$2:$B$203,0)),"") | E13: =IF($C13="","",IFERROR(INDEX(ROLE_VAL,MATCH($C13,ROLE_SKU,0)),"all_in_one")) | F13: =IF($C13="",0,IFERROR(INDEX(SPEC_DCKW,MATCH($C13,SPEC_SKU,0)),IF($E13="dispenser",0,IF($E13="accessory",0,IFERROR(IF(N(INDEX(PriceBook!$E$2:$E$203,MATCH($C13,PriceBook!$B$2:$B$203,0)))>0,INDEX(PriceBook!$E$2:$E$203,MATCH($C13,PriceBook!$B$2:$B$203,0)),INDEX(RATED_KW,MATCH($B13,CAPACITY_LIST,0))*IF(INDEX(PER_PORT,MATCH($B13,CAPACITY_LIST,0))=1,MAX(1,N($H13)),1)),0))))) | G13: =IF($C13="",0,IFERROR(INDEX(SPEC_ACKW,MATCH($C13,SPEC_SKU,0)),$F13)) | H13: =IF($C13="",0,IF($E13="power_cabinet",N($N13)*N($O13),IFERROR(INDEX(SPEC_OUTS,MATCH($C13,SPEC_SKU,0)),IFERROR(INDEX(SKU_CONN,MATCH($C13,SKU_ALL,0)),0)))) | K13: =IFERROR(INDEX(PriceBook!$D$2:$D$203,MATCH($C13,PriceBook!$B$2:$B$203,0)),0) | M13: =IF($E13<>"power_cabinet",0,IFERROR(INDEX(SPEC_MAXDISP,MATCH($C13,SPEC_SKU,0)),0)) | P13: =IF($L13="",0,IFERROR(INDEX(PriceBook!$D$2:$D$203,MATCH($L13,PriceBook!$B$2:$B$203,0)),0))
A14: 8 | D14: =IFERROR(INDEX(PriceBook!$C$2:$C$203,MATCH($C14,PriceBook!$B$2:$B$203,0)),"") | E14: =IF($C14="","",IFERROR(INDEX(ROLE_VAL,MATCH($C14,ROLE_SKU,0)),"all_in_one")) | F14: =IF($C14="",0,IFERROR(INDEX(SPEC_DCKW,MATCH($C14,SPEC_SKU,0)),IF($E14="dispenser",0,IF($E14="accessory",0,IFERROR(IF(N(INDEX(PriceBook!$E$2:$E$203,MATCH($C14,PriceBook!$B$2:$B$203,0)))>0,INDEX(PriceBook!$E$2:$E$203,MATCH($C14,PriceBook!$B$2:$B$203,0)),INDEX(RATED_KW,MATCH($B14,CAPACITY_LIST,0))*IF(INDEX(PER_PORT,MATCH($B14,CAPACITY_LIST,0))=1,MAX(1,N($H14)),1)),0))))) | G14: =IF($C14="",0,IFERROR(INDEX(SPEC_ACKW,MATCH($C14,SPEC_SKU,0)),$F14)) | H14: =IF($C14="",0,IF($E14="power_cabinet",N($N14)*N($O14),IFERROR(INDEX(SPEC_OUTS,MATCH($C14,SPEC_SKU,0)),IFERROR(INDEX(SKU_CONN,MATCH($C14,SKU_ALL,0)),0)))) | K14: =IFERROR(INDEX(PriceBook!$D$2:$D$203,MATCH($C14,PriceBook!$B$2:$B$203,0)),0) | M14: =IF($E14<>"power_cabinet",0,IFERROR(INDEX(SPEC_MAXDISP,MATCH($C14,SPEC_SKU,0)),0)) | P14: =IF($L14="",0,IFERROR(INDEX(PriceBook!$D$2:$D$203,MATCH($L14,PriceBook!$B$2:$B$203,0)),0))
A15: 9 | D15: =IFERROR(INDEX(PriceBook!$C$2:$C$203,MATCH($C15,PriceBook!$B$2:$B$203,0)),"") | E15: =IF($C15="","",IFERROR(INDEX(ROLE_VAL,MATCH($C15,ROLE_SKU,0)),"all_in_one")) | F15: =IF($C15="",0,IFERROR(INDEX(SPEC_DCKW,MATCH($C15,SPEC_SKU,0)),IF($E15="dispenser",0,IF($E15="accessory",0,IFERROR(IF(N(INDEX(PriceBook!$E$2:$E$203,MATCH($C15,PriceBook!$B$2:$B$203,0)))>0,INDEX(PriceBook!$E$2:$E$203,MATCH($C15,PriceBook!$B$2:$B$203,0)),INDEX(RATED_KW,MATCH($B15,CAPACITY_LIST,0))*IF(INDEX(PER_PORT,MATCH($B15,CAPACITY_LIST,0))=1,MAX(1,N($H15)),1)),0))))) | G15: =IF($C15="",0,IFERROR(INDEX(SPEC_ACKW,MATCH($C15,SPEC_SKU,0)),$F15)) | H15: =IF($C15="",0,IF($E15="power_cabinet",N($N15)*N($O15),IFERROR(INDEX(SPEC_OUTS,MATCH($C15,SPEC_SKU,0)),IFERROR(INDEX(SKU_CONN,MATCH($C15,SKU_ALL,0)),0)))) | K15: =IFERROR(INDEX(PriceBook!$D$2:$D$203,MATCH($C15,PriceBook!$B$2:$B$203,0)),0) | M15: =IF($E15<>"power_cabinet",0,IFERROR(INDEX(SPEC_MAXDISP,MATCH($C15,SPEC_SKU,0)),0)) | P15: =IF($L15="",0,IFERROR(INDEX(PriceBook!$D$2:$D$203,MATCH($L15,PriceBook!$B$2:$B$203,0)),0))
A16: 10 | D16: =IFERROR(INDEX(PriceBook!$C$2:$C$203,MATCH($C16,PriceBook!$B$2:$B$203,0)),"") | E16: =IF($C16="","",IFERROR(INDEX(ROLE_VAL,MATCH($C16,ROLE_SKU,0)),"all_in_one")) | F16: =IF($C16="",0,IFERROR(INDEX(SPEC_DCKW,MATCH($C16,SPEC_SKU,0)),IF($E16="dispenser",0,IF($E16="accessory",0,IFERROR(IF(N(INDEX(PriceBook!$E$2:$E$203,MATCH($C16,PriceBook!$B$2:$B$203,0)))>0,INDEX(PriceBook!$E$2:$E$203,MATCH($C16,PriceBook!$B$2:$B$203,0)),INDEX(RATED_KW,MATCH($B16,CAPACITY_LIST,0))*IF(INDEX(PER_PORT,MATCH($B16,CAPACITY_LIST,0))=1,MAX(1,N($H16)),1)),0))))) | G16: =IF($C16="",0,IFERROR(INDEX(SPEC_ACKW,MATCH($C16,SPEC_SKU,0)),$F16)) | H16: =IF($C16="",0,IF($E16="power_cabinet",N($N16)*N($O16),IFERROR(INDEX(SPEC_OUTS,MATCH($C16,SPEC_SKU,0)),IFERROR(INDEX(SKU_CONN,MATCH($C16,SKU_ALL,0)),0)))) | K16: =IFERROR(INDEX(PriceBook!$D$2:$D$203,MATCH($C16,PriceBook!$B$2:$B$203,0)),0) | M16: =IF($E16<>"power_cabinet",0,IFERROR(INDEX(SPEC_MAXDISP,MATCH($C16,SPEC_SKU,0)),0)) | P16: =IF($L16="",0,IFERROR(INDEX(PriceBook!$D$2:$D$203,MATCH($L16,PriceBook!$B$2:$B$203,0)),0))
A17: 11 | D17: =IFERROR(INDEX(PriceBook!$C$2:$C$203,MATCH($C17,PriceBook!$B$2:$B$203,0)),"") | E17: =IF($C17="","",IFERROR(INDEX(ROLE_VAL,MATCH($C17,ROLE_SKU,0)),"all_in_one")) | F17: =IF($C17="",0,IFERROR(INDEX(SPEC_DCKW,MATCH($C17,SPEC_SKU,0)),IF($E17="dispenser",0,IF($E17="accessory",0,IFERROR(IF(N(INDEX(PriceBook!$E$2:$E$203,MATCH($C17,PriceBook!$B$2:$B$203,0)))>0,INDEX(PriceBook!$E$2:$E$203,MATCH($C17,PriceBook!$B$2:$B$203,0)),INDEX(RATED_KW,MATCH($B17,CAPACITY_LIST,0))*IF(INDEX(PER_PORT,MATCH($B17,CAPACITY_LIST,0))=1,MAX(1,N($H17)),1)),0))))) | G17: =IF($C17="",0,IFERROR(INDEX(SPEC_ACKW,MATCH($C17,SPEC_SKU,0)),$F17)) | H17: =IF($C17="",0,IF($E17="power_cabinet",N($N17)*N($O17),IFERROR(INDEX(SPEC_OUTS,MATCH($C17,SPEC_SKU,0)),IFERROR(INDEX(SKU_CONN,MATCH($C17,SKU_ALL,0)),0)))) | K17: =IFERROR(INDEX(PriceBook!$D$2:$D$203,MATCH($C17,PriceBook!$B$2:$B$203,0)),0) | M17: =IF($E17<>"power_cabinet",0,IFERROR(INDEX(SPEC_MAXDISP,MATCH($C17,SPEC_SKU,0)),0)) | P17: =IF($L17="",0,IFERROR(INDEX(PriceBook!$D$2:$D$203,MATCH($L17,PriceBook!$B$2:$B$203,0)),0))
A18: 12 | D18: =IFERROR(INDEX(PriceBook!$C$2:$C$203,MATCH($C18,PriceBook!$B$2:$B$203,0)),"") | E18: =IF($C18="","",IFERROR(INDEX(ROLE_VAL,MATCH($C18,ROLE_SKU,0)),"all_in_one")) | F18: =IF($C18="",0,IFERROR(INDEX(SPEC_DCKW,MATCH($C18,SPEC_SKU,0)),IF($E18="dispenser",0,IF($E18="accessory",0,IFERROR(IF(N(INDEX(PriceBook!$E$2:$E$203,MATCH($C18,PriceBook!$B$2:$B$203,0)))>0,INDEX(PriceBook!$E$2:$E$203,MATCH($C18,PriceBook!$B$2:$B$203,0)),INDEX(RATED_KW,MATCH($B18,CAPACITY_LIST,0))*IF(INDEX(PER_PORT,MATCH($B18,CAPACITY_LIST,0))=1,MAX(1,N($H18)),1)),0))))) | G18: =IF($C18="",0,IFERROR(INDEX(SPEC_ACKW,MATCH($C18,SPEC_SKU,0)),$F18)) | H18: =IF($C18="",0,IF($E18="power_cabinet",N($N18)*N($O18),IFERROR(INDEX(SPEC_OUTS,MATCH($C18,SPEC_SKU,0)),IFERROR(INDEX(SKU_CONN,MATCH($C18,SKU_ALL,0)),0)))) | K18: =IFERROR(INDEX(PriceBook!$D$2:$D$203,MATCH($C18,PriceBook!$B$2:$B$203,0)),0) | M18: =IF($E18<>"power_cabinet",0,IFERROR(INDEX(SPEC_MAXDISP,MATCH($C18,SPEC_SKU,0)),0)) | P18: =IF($L18="",0,IFERROR(INDEX(PriceBook!$D$2:$D$203,MATCH($L18,PriceBook!$B$2:$B$203,0)),0))
A20: Charging units (excludes accessories) | B20: =SUMPRODUCT(--($H$7:$H$18>0),$I$7:$I$18) | C20: Units a driver plugs into — dispensers, all-in-one chargers and Level 2. A power cabinet has no connectors and is not one.
A21: AC-connected units — cabinets and all-in-ones | B21: =SUMPRODUCT(($E$7:$E$18="power_cabinet")+($E$7:$E$18="all_in_one"),$I$7:$I$18) | C21: Each of these needs its own AC run from the switchgear, and a placement distance on the Electrical tab.
A22: Total ports | B22: =SUMPRODUCT($H$7:$H$18,$I$7:$I$18) | C22: Connectors x units. The EVOLV billing basis. Dispensers carry the ports on a distributed system; the cabinet carries none.
A23: Total connected load (kW) | B23: =SUMPRODUCT(($E$7:$E$18="power_cabinet")+($E$7:$E$18="all_in_one")+($E$7:$E$18="level_2"),$G$7:$G$18,$I$7:$I$18) | C23: AC input, which is what the switchgear sees — a 480 kW cabinet draws 524 kW. Dispensers add nothing: their power comes from the cabinet, not the switchgear.
A24: Equipment MSRP total | B24: =SUMPRODUCT($I$7:$I$18,$K$7:$K$18)+SUMPRODUCT($I$7:$I$18,$N$7:$N$18,$P$7:$P$18) | C24: Catalogue SKUs at their price-book price, plus any dispensers priced by hand on the cabinet row.
A25: Equipment after discount | B25: =$B$24*(1-Commercial!$B$5) | C25: Sales tax is computed on THIS, not on MSRP. The discount is the one on the Commercial tab — there is no per-line discount any more.
A26: of which DC fast-charging capacity (kW) | B26: =SUMPRODUCT(($E$7:$E$18="power_cabinet")+($E$7:$E$18="all_in_one"),$F$7:$F$18,$I$7:$I$18) | C26: DC output. The LCFS credit basis. Counted once, at the cabinet — never again at the dispenser.
A27: Scope of work sentence (one line, must match the rows above) | B27: Installation of (4) 360 kW dual-port DC fast chargers and (2) dual Level 2 units — 12 charging positions
B29: Write it from the table, e.g. "Installation of (4) 360 kW dual-port DC fast chargers — 8 charging positions".
A32: Distributed system — do the dispensers fit the cabinets?
A33: Only relevant when a power cabinet is on the schedule. A cabinet feeds a limited number of DC outputs; each dual dispenser consumes two of them. Every dispenser also needs a DC run back to its cabinet — schedule those on the Electrical tab.
A34: Power cabinets on site | B34: =SUMPRODUCT(--($E$7:$E$18="power_cabinet"),$I$7:$I$18)
A35: Dispensers those cabinets can take | B35: =SUMPRODUCT($M$7:$M$18,$I$7:$I$18) | C35: From the architecture table: a 480 kW cabinet takes up to 3 dual dispensers, a 1.28 MW up to 8.
A36: Dispensers on the cabinet rows | B36: =SUMPRODUCT(--($E$7:$E$18="power_cabinet"),$N$7:$N$18,$I$7:$I$18) | C36: Dispensers per cabinet x the number of cabinets. This is now the only way a dispenser is entered.
A37: Dispensers entered on a line of their own | B37: =SUMPRODUCT(--($E$7:$E$18="dispenser"),$I$7:$I$18) | C37: Should always be zero. A dispenser belongs on its cabinet row, not on a line of its own.
A38: Dispensers in total | B38: =$B$36+$B$37
A39: Connectors those dispensers carry | B39: =SUMPRODUCT(--($E$7:$E$18="power_cabinet"),$H$7:$H$18,$I$7:$I$18)
A40: DISTRIBUTED SYSTEM CHECK | B40: =IF(AND($B$34=0,$B$38=0),"n/a — no distributed system on this schedule",IF($B$34=0,"ERROR — DISPENSERS WITHOUT A POWER CABINET. A dispenser has no power of its own.",IF($B$38=0,"ERROR — POWER CABINET WITHOUT DISPENSERS. A cabinet has no connectors and cannot charge a vehicle on its own. Enter the dispensers in the last column of the table.",IF($B$38>$B$35,"ERROR — TOO MANY DISPENSERS. "&TEXT($B$38,"0")&" entered against a limit of "&TEXT($B$35,"0")&" for the cabinets on this schedule.","OK — "&TEXT($B$38,"0")&" dispenser(s) on "&TEXT($B$34,"0")&" cabinet(s), "&TEXT($B$35-$B$38,"0")&" more allowed, "&TEXT($B$39,"0")&" connectors"))))
A41: Dispenser value at list | B41: =SUMPRODUCT($I$7:$I$18,$N$7:$N$18,$P$7:$P$18) | C41: Dispensers x their price-book price. Included in the two equipment totals above.
A42: Is a dispenser SKU picked where dispensers are scheduled? | B42: {=IF(SUMPRODUCT(($E$7:$E$18="power_cabinet")*N($N$7:$N$18))=0,"n/a — no dispensers scheduled",IF(SUMPRODUCT((N($N$7:$N$18)>0)*($L$7:$L$18=""))>0,"ERROR — dispensers are scheduled on a cabinet row with no dispenser SKU picked, so they are costing this project nothing. Pick one from the dropdown.",IF(SUMPRODUCT((N($N$7:$N$18)>0)*(N($O$7:$O$18)=0))>0,"ERROR — dispensers are scheduled with no connectors-per-dispenser picked, so the site shows no charging positions. Pick 1 or 2.","OK — "&TEXT(SUMPRODUCT(N($I$7:$I$18),N($N$7:$N$18)),"0")&" dispenser(s) at their price-book price")))}
A43: Any dispenser on a line of its own? | B43: =IF(AND(SUMPRODUCT(--($E$7:$E$18="dispenser"),$I$7:$I$18)>0,$B$36>0),"ERROR — dispensers are entered BOTH on their own line and as a count on a cabinet row. Pick one route: the totals add them together and double-count ports and price.",IF(SUMPRODUCT(--($E$7:$E$18="dispenser"),$I$7:$I$18)>0,"OK — dispensers are on their own lines, priced from the price book","OK — no dispenser is on a line of its own")) | C43: It used to fire whenever a dispenser was on its own line at all, which is a legitimate entry now the dispenser SKU is in the price book. The thing that is actually wrong is using both routes, because the totals sum them.
A46: ENTRY CHECKS — what a wrong entry looks like
A47: Each of these is a real way to get a wrong answer out of this tab. None of them used to say anything.
A48: Any discount typed on an equipment line? | B48: =IF(COUNTA($J$7:$J$18)>0,"ERROR — A DISCOUNT HAS BEEN TYPED ON A LINE. Discounts are set once, on the Commercial tab. A figure in this column is not applied to anything and will mislead whoever reads the schedule next — clear it, and change the rate on the Commercial tab instead.","OK — the discount is set once, on the Commercial tab: "&TEXT(Commercial!$B$5,"0%"))
...

Sheet Electrical
A1: 3 · SITE AND ELECTRICAL
A2: Distances and materials. This tab drives the largest single cost in the project.
A4: Materials | E4: Conductor sizing basis
A5: Feeder conductor material | B5: Cu | C5: Cu or Al | E5: Design ambient (C) | F5: 40 | G5: Design ambient for the branch runs, in Celsius. THIS IS SITE DATA — there is no house default and none is offered. Use the ASHRAE 2% design dry-bulb for the location, or the duct-bank design temperature if the run is buried. NEC Table 310.15(B)(1)(1) corrects the ampacity from it, so an ambient carried over from another project silently resizes every conductor on this one.
A6: Conduit type | B6: PVC | C6: PVC or EMT | E6: Conductor insulation rating (C) | F6: 90 | G6: What the wire is rated for. THHN/XHHW-2 is 90 C. Ambient correction is applied to THIS column.
A7: Trench surface | B7: Asphalt | C7: Asphalt / concrete / landscape / mixed | E7: Termination rating (C) | F7: 75 | G7: NEC 110.14(C). The corrected ampacity is capped here. Confirm against the switchgear and the cabinet terminals — 60 C lugs change every size on this tab.
A8: Trench depth (in) | B8: 24 | E8: Allowable voltage drop (%) | F8: 0.03 | G8: NEC treats voltage drop as an informational note, not a requirement. On a 300 ft feeder it is usually what decides the size.
A10: AC runs — switchgear to each charger: all-in-one units and power cabinets alike | C10: One feeder per AC-connected unit. An all-in-one charger and a power cabinet both take a feeder and both belong here; a DISPENSER does not — it takes DC from its cabinet and is scheduled in the DC runs block further down. The "What this run feeds" column below says which is which for every line.
A11: Unit | B11: Equip. line | C11: AC input kW (auto) | D11: Distance from switchgear (ft) | E11: Design current A (auto) | F11: Continuous 125% A (auto) | G11: OCPD A (auto) | H11: Ampacity floor A (auto) | I11: Conductor size | J11: Sets in parallel | K11: Ampacity per set, corrected (auto) | L11: Provided A (auto) | M11: Voltage drop % (auto) | N11: Verdict (auto) | O11: Conduit size | P11: What this run feeds (auto) | Q11: Phase conductor (ft) (auto) | R11: Ground size (auto, 250.122) | S11: Ground (ft) (auto) | T11: Conduit (ft) (auto) | U11: Comms (ft) (auto) | V11: Material cost (auto)
A12: Charger 1 | B12: 1 | C12: =IF(N($B12)=0,"",IFERROR(INDEX(Equipment!$G$7:$G$18,MATCH($B12,Equipment!$A$7:$A$18,0)),"")) | D12: 80 | E12: =IF(N($C12)=0,"",N($C12)*1000/(Project!$B$29*SQRT(3))) | F12: =IF(N($E12)=0,"",N($E12)*1.25) | G12: =IF(N($F12)=0,"",IF(ISNUMBER(MATCH($F12,OCPD_LIST,0)),$F12,IF($F12>MAX(OCPD_LIST),"ABOVE THE LARGEST STANDARD DEVICE",INDEX(OCPD_LIST,MATCH($F12,OCPD_LIST,1)+1)))) | H12: =IF(N($G12)=0,"",IF(N($G12)>800,N($G12),N($F12))) | I12: 300 kcmil | J12: 2 | K12: =IF($I12="","",IFERROR(MIN(N(INDEX(AMP_TBL,MATCH($I12,AMP_SIZE,0),MATCH($B$5&"-"&TEXT($F$6,"0"),AMP_HDR,0)))*N(INDEX(AMB_TBL,IF(ISNUMBER(MATCH($F$5,AMB_MAX,0)),MATCH($F$5,AMB_MAX,0),MATCH($F$5,AMB_MAX,1)+1),MATCH(TEXT($F$6,"0"),AMB_HDR,0))),N(INDEX(AMP_TBL,MATCH($I12,AMP_SIZE,0),MATCH($B$5&"-"&TEXT($F$7,"0"),AMP_HDR,0)))),"")) | L12: =IF(N($K12)=0,"",N($K12)*MAX(1,N($J12))) | M12: =IF(OR($I12="",N($D12)=0,N($E12)=0),"",IFERROR(SQRT(3)*N($E12)/MAX(1,N($J12))*N($D12)*N(INDEX(Z_TBL,MATCH($I12,Z_SIZE,0),IF($B$5="Cu",1,2)))/1000/Project!$B$29,"")) | N12: =IF(N($C12)=0,"",IF($I12="","pick a conductor size",IF($F$5="","SET THE DESIGN AMBIENT for this run — ampacity cannot be corrected without it, and this verdict cannot be trusted until it is set",IF(N($K12)=0,"no ampacity on file for that size — NEC Table 310.16 does not list it",IF(N($J12)=0,"enter the number of parallel sets",IF(N($L12)<N($H12),"UNDERSIZED — "&TEXT(N($L12),"#,##0")&" A provided against a floor of "&TEXT(N($H12),"#,##0")&" A. NEC 240.4(C) applies above 800 A: the conductor carries the device, not the load.",IF(N($M12)>N($F$8),"ampacity OK, but voltage drop "&TEXT(N($M12),"0.00%")&" exceeds the "&TEXT($F$8,"0.0%")&" allowance — ADVISORY, the impedance table is unverified","OK — "&TEXT(N($L12),"#,##0")&" A against a "&TEXT(N($H12),"#,##0")&" A floor; voltage drop "&TEXT(N($M12),"0.00%")&" (ADVISORY)"))))))) | O12: 3" | P12: =IF($B12="","",IFERROR(IF(INDEX(Equipment!$E$7:$E$18,MATCH($B12,Equipment!$A$7:$A$18,0))="power_cabinet","power cabinet — dispensers run on from it",IF(INDEX(Equipment!$E$7:$E$18,MATCH($B12,Equipment!$A$7:$A$18,0))="dispenser","DISPENSER — this belongs in the DC runs block, not here",IF(INDEX(Equipment!$B$7:$B$18,MATCH($B12,Equipment!$A$7:$A$18,0))="Level 2 AC","Level 2 — use the Level 2 branch circuits block","all-in-one charger"))),"equipment line not found")) | Q12: =IF(N($D12)=0,0,N($D12)*MAX(1,N($J12))*3) | R12: =IF(N($G12)=0,"",IFERROR(INDEX(IF($B$5="Cu",EGC_CU,EGC_AL),MATCH($G12,EGC_OCPD,1)+IF(ISNUMBER(MATCH($G12,EGC_OCPD,0)),0,1)),"")) | S12: =IF(N($D12)=0,0,N($D12)*MAX(1,N($J12))) | T12: =IF(N($D12)=0,0,N($D12)*MAX(1,N($J12))) | U12: =IF(N($D12)=0,0,N($D12)) | V12: =IFERROR(N($Q12)*INDEX(IF($B$5="Cu",WIRE_CU,WIRE_AL),MATCH($I12,WIRE_SIZE,0)),0)+IFERROR(N($S12)*INDEX(IF($B$5="Cu",WIRE_CU,WIRE_AL),MATCH($R12,WIRE_SIZE,0)),0)+IFERROR(N($T12)*INDEX(PVC_RATE,MATCH($O12,PVC_SIZE,0)),0)+IFERROR(N($U12)*INDEX(PVC_RATE,MATCH("(3/4"")",PVC_SIZE,0)),0)
A13: Charger 2 | B13: 1 | C13: =IF(N($B13)=0,"",IFERROR(INDEX(Equipment!$G$7:$G$18,MATCH($B13,Equipment!$A$7:$A$18,0)),"")) | D13: 95 | E13: =IF(N($C13)=0,"",N($C13)*1000/(Project!$B$29*SQRT(3))) | F13: =IF(N($E13)=0,"",N($E13)*1.25) | G13: =IF(N($F13)=0,"",IF(ISNUMBER(MATCH($F13,OCPD_LIST,0)),$F13,IF($F13>MAX(OCPD_LIST),"ABOVE THE LARGEST STANDARD DEVICE",INDEX(OCPD_LIST,MATCH($F13,OCPD_LIST,1)+1)))) | H13: =IF(N($G13)=0,"",IF(N($G13)>800,N($G13),N($F13))) | I13: 300 kcmil | J13: 2 | K13: =IF($I13="","",IFERROR(MIN(N(INDEX(AMP_TBL,MATCH($I13,AMP_SIZE,0),MATCH($B$5&"-"&TEXT($F$6,"0"),AMP_HDR,0)))*N(INDEX(AMB_TBL,IF(ISNUMBER(MATCH($F$5,AMB_MAX,0)),MATCH($F$5,AMB_MAX,0),MATCH($F$5,AMB_MAX,1)+1),MATCH(TEXT($F$6,"0"),AMB_HDR,0))),N(INDEX(AMP_TBL,MATCH($I13,AMP_SIZE,0),MATCH($B$5&"-"&TEXT($F$7,"0"),AMP_HDR,0)))),"")) | L13: =IF(N($K13)=0,"",N($K13)*MAX(1,N($J13))) | M13: =IF(OR($I13="",N($D13)=0,N($E13)=0),"",IFERROR(SQRT(3)*N($E13)/MAX(1,N($J13))*N($D13)*N(INDEX(Z_TBL,MATCH($I13,Z_SIZE,0),IF($B$5="Cu",1,2)))/1000/Project!$B$29,"")) | N13: =IF(N($C13)=0,"",IF($I13="","pick a conductor size",IF($F$5="","SET THE DESIGN AMBIENT for this run — ampacity cannot be corrected without it, and this verdict cannot be trusted until it is set",IF(N($K13)=0,"no ampacity on file for that size — NEC Table 310.16 does not list it",IF(N($J13)=0,"enter the number of parallel sets",IF(N($L13)<N($H13),"UNDERSIZED — "&TEXT(N($L13),"#,##0")&" A provided against a floor of "&TEXT(N($H13),"#,##0")&" A. NEC 240.4(C) applies above 800 A: the conductor carries the device, not the load.",IF(N($M13)>N($F$8),"ampacity OK, but voltage drop "&TEXT(N($M13),"0.00%")&" exceeds the "&TEXT($F$8,"0.0%")&" allowance — ADVISORY, the impedance table is unverified","OK — "&TEXT(N($L13),"#,##0")&" A against a "&TEXT(N($H13),"#,##0")&" A floor; voltage drop "&TEXT(N($M13),"0.00%")&" (ADVISORY)"))))))) | O13: 3" | P13: =IF($B13="","",IFERROR(IF(INDEX(Equipment!$E$7:$E$18,MATCH($B13,Equipment!$A$7:$A$18,0))="power_cabinet","power cabinet — dispensers run on from it",IF(INDEX(Equipment!$E$7:$E$18,MATCH($B13,Equipment!$A$7:$A$18,0))="dispenser","DISPENSER — this belongs in the DC runs block, not here",IF(INDEX(Equipment!$B$7:$B$18,MATCH($B13,Equipment!$A$7:$A$18,0))="Level 2 AC","Level 2 — use the Level 2 branch circuits block","all-in-one charger"))),"equipment line not found")) | Q13: =IF(N($D13)=0,0,N($D13)*MAX(1,N($J13))*3) | R13: =IF(N($G13)=0,"",IFERROR(INDEX(IF($B$5="Cu",EGC_CU,EGC_AL),MATCH($G13,EGC_OCPD,1)+IF(ISNUMBER(MATCH($G13,EGC_OCPD,0)),0,1)),"")) | S13: =IF(N($D13)=0,0,N($D13)*MAX(1,N($J13))) | T13: =IF(N($D13)=0,0,N($D13)*MAX(1,N($J13))) | U13: =IF(N($D13)=0,0,N($D13)) | V13: =IFERROR(N($Q13)*INDEX(IF($B$5="Cu",WIRE_CU,WIRE_AL),MATCH($I13,WIRE_SIZE,0)),0)+IFERROR(N($S13)*INDEX(IF($B$5="Cu",WIRE_CU,WIRE_AL),MATCH($R13,WIRE_SIZE,0)),0)+IFERROR(N($T13)*INDEX(PVC_RATE,MATCH($O13,PVC_SIZE,0)),0)+IFERROR(N($U13)*INDEX(PVC_RATE,MATCH("(3/4"")",PVC_SIZE,0)),0)
A14: Charger 3 | B14: 1 | C14: =IF(N($B14)=0,"",IFERROR(INDEX(Equipment!$G$7:$G$18,MATCH($B14,Equipment!$A$7:$A$18,0)),"")) | D14: 110 | E14: =IF(N($C14)=0,"",N($C14)*1000/(Project!$B$29*SQRT(3))) | F14: =IF(N($E14)=0,"",N($E14)*1.25) | G14: =IF(N($F14)=0,"",IF(ISNUMBER(MATCH($F14,OCPD_LIST,0)),$F14,IF($F14>MAX(OCPD_LIST),"ABOVE THE LARGEST STANDARD DEVICE",INDEX(OCPD_LIST,MATCH($F14,OCPD_LIST,1)+1)))) | H14: =IF(N($G14)=0,"",IF(N($G14)>800,N($G14),N($F14))) | I14: 300 kcmil | J14: 2 | K14: =IF($I14="","",IFERROR(MIN(N(INDEX(AMP_TBL,MATCH($I14,AMP_SIZE,0),MATCH($B$5&"-"&TEXT($F$6,"0"),AMP_HDR,0)))*N(INDEX(AMB_TBL,IF(ISNUMBER(MATCH($F$5,AMB_MAX,0)),MATCH($F$5,AMB_MAX,0),MATCH($F$5,AMB_MAX,1)+1),MATCH(TEXT($F$6,"0"),AMB_HDR,0))),N(INDEX(AMP_TBL,MATCH($I14,AMP_SIZE,0),MATCH($B$5&"-"&TEXT($F$7,"0"),AMP_HDR,0)))),"")) | L14: =IF(N($K14)=0,"",N($K14)*MAX(1,N($J14))) | M14: =IF(OR($I14="",N($D14)=0,N($E14)=0),"",IFERROR(SQRT(3)*N($E14)/MAX(1,N($J14))*N($D14)*N(INDEX(Z_TBL,MATCH($I14,Z_SIZE,0),IF($B$5="Cu",1,2)))/1000/Project!$B$29,"")) | N14: =IF(N($C14)=0,"",IF($I14="","pick a conductor size",IF($F$5="","SET THE DESIGN AMBIENT for this run — ampacity cannot be corrected without it, and this verdict cannot be trusted until it is set",IF(N($K14)=0,"no ampacity on file for that size — NEC Table 310.16 does not list it",IF(N($J14)=0,"enter the number of parallel sets",IF(N($L14)<N($H14),"UNDERSIZED — "&TEXT(N($L14),"#,##0")&" A provided against a floor of "&TEXT(N($H14),"#,##0")&" A. NEC 240.4(C) applies above 800 A: the conductor carries the device, not the load.",IF(N($M14)>N($F$8),"ampacity OK, but voltage drop "&TEXT(N($M14),"0.00%")&" exceeds the "&TEXT($F$8,"0.0%")&" allowance — ADVISORY, the impedance table is unverified","OK — "&TEXT(N($L14),"#,##0")&" A against a "&TEXT(N($H14),"#,##0")&" A floor; voltage drop "&TEXT(N($M14),"0.00%")&" (ADVISORY)"))))))) | O14: 3" | P14: =IF($B14="","",IFERROR(IF(INDEX(Equipment!$E$7:$E$18,MATCH($B14,Equipment!$A$7:$A$18,0))="power_cabinet","power cabinet — dispensers run on from it",IF(INDEX(Equipment!$E$7:$E$18,MATCH($B14,Equipment!$A$7:$A$18,0))="dispenser","DISPENSER — this belongs in the DC runs block, not here",IF(INDEX(Equipment!$B$7:$B$18,MATCH($B14,Equipment!$A$7:$A$18,0))="Level 2 AC","Level 2 — use the Level 2 branch circuits block","all-in-one charger"))),"equipment line not found")) | Q14: =IF(N($D14)=0,0,N($D14)*MAX(1,N($J14))*3) | R14: =IF(N($G14)=0,"",IFERROR(INDEX(IF($B$5="Cu",EGC_CU,EGC_AL),MATCH($G14,EGC_OCPD,1)+IF(ISNUMBER(MATCH($G14,EGC_OCPD,0)),0,1)),"")) | S14: =IF(N($D14)=0,0,N($D14)*MAX(1,N($J14))) | T14: =IF(N($D14)=0,0,N($D14)*MAX(1,N($J14))) | U14: =IF(N($D14)=0,0,N($D14)) | V14: =IFERROR(N($Q14)*INDEX(IF($B$5="Cu",WIRE_CU,WIRE_AL),MATCH($I14,WIRE_SIZE,0)),0)+IFERROR(N($S14)*INDEX(IF($B$5="Cu",WIRE_CU,WIRE_AL),MATCH($R14,WIRE_SIZE,0)),0)+IFERROR(N($T14)*INDEX(PVC_RATE,MATCH($O14,PVC_SIZE,0)),0)+IFERROR(N($U14)*INDEX(PVC_RATE,MATCH("(3/4"")",PVC_SIZE,0)),0)
A15: Charger 4 | B15: 1 | C15: =IF(N($B15)=0,"",IFERROR(INDEX(Equipment!$G$7:$G$18,MATCH($B15,Equipment!$A$7:$A$18,0)),"")) | D15: 125 | E15: =IF(N($C15)=0,"",N($C15)*1000/(Project!$B$29*SQRT(3))) | F15: =IF(N($E15)=0,"",N($E15)*1.25) | G15: =IF(N($F15)=0,"",IF(ISNUMBER(MATCH($F15,OCPD_LIST,0)),$F15,IF($F15>MAX(OCPD_LIST),"ABOVE THE LARGEST STANDARD DEVICE",INDEX(OCPD_LIST,MATCH($F15,OCPD_LIST,1)+1)))) | H15: =IF(N($G15)=0,"",IF(N($G15)>800,N($G15),N($F15))) | I15: 300 kcmil | J15: 2 | K15: =IF($I15="","",IFERROR(MIN(N(INDEX(AMP_TBL,MATCH($I15,AMP_SIZE,0),MATCH($B$5&"-"&TEXT($F$6,"0"),AMP_HDR,0)))*N(INDEX(AMB_TBL,IF(ISNUMBER(MATCH($F$5,AMB_MAX,0)),MATCH($F$5,AMB_MAX,0),MATCH($F$5,AMB_MAX,1)+1),MATCH(TEXT($F$6,"0"),AMB_HDR,0))),N(INDEX(AMP_TBL,MATCH($I15,AMP_SIZE,0),MATCH($B$5&"-"&TEXT($F$7,"0"),AMP_HDR,0)))),"")) | L15: =IF(N($K15)=0,"",N($K15)*MAX(1,N($J15))) | M15: =IF(OR($I15="",N($D15)=0,N($E15)=0),"",IFERROR(SQRT(3)*N($E15)/MAX(1,N($J15))*N($D15)*N(INDEX(Z_TBL,MATCH($I15,Z_SIZE,0),IF($B$5="Cu",1,2)))/1000/Project!$B$29,"")) | N15: =IF(N($C15)=0,"",IF($I15="","pick a conductor size",IF($F$5="","SET THE DESIGN AMBIENT for this run — ampacity cannot be corrected without it, and this verdict cannot be trusted until it is set",IF(N($K15)=0,"no ampacity on file for that size — NEC Table 310.16 does not list it",IF(N($J15)=0,"enter the number of parallel sets",IF(N($L15)<N($H15),"UNDERSIZED — "&TEXT(N($L15),"#,##0")&" A provided against a floor of "&TEXT(N($H15),"#,##0")&" A. NEC 240.4(C) applies above 800 A: the conductor carries the device, not the load.",IF(N($M15)>N($F$8),"ampacity OK, but voltage drop "&TEXT(N($M15),"0.00%")&" exceeds the "&TEXT($F$8,"0.0%")&" allowance — ADVISORY, the impedance table is unverified","OK — "&TEXT(N($L15),"#,##0")&" A against a "&TEXT(N($H15),"#,##0")&" A floor; voltage drop "&TEXT(N($M15),"0.00%")&" (ADVISORY)"))))))) | O15: 3" | P15: =IF($B15="","",IFERROR(IF(INDEX(Equipment!$E$7:$E$18,MATCH($B15,Equipment!$A$7:$A$18,0))="power_cabinet","power cabinet — dispensers run on from it",IF(INDEX(Equipment!$E$7:$E$18,MATCH($B15,Equipment!$A$7:$A$18,0))="dispenser","DISPENSER — this belongs in the DC runs block, not here",IF(INDEX(Equipment!$B$7:$B$18,MATCH($B15,Equipment!$A$7:$A$18,0))="Level 2 AC","Level 2 — use the Level 2 branch circuits block","all-in-one charger"))),"equipment line not found")) | Q15: =IF(N($D15)=0,0,N($D15)*MAX(1,N($J15))*3) | R15: =IF(N($G15)=0,"",IFERROR(INDEX(IF($B$5="Cu",EGC_CU,EGC_AL),MATCH($G15,EGC_OCPD,1)+IF(ISNUMBER(MATCH($G15,EGC_OCPD,0)),0,1)),"")) | S15: =IF(N($D15)=0,0,N($D15)*MAX(1,N($J15))) | T15: =IF(N($D15)=0,0,N($D15)*MAX(1,N($J15))) | U15: =IF(N($D15)=0,0,N($D15)) | V15: =IFERROR(N($Q15)*INDEX(IF($B$5="Cu",WIRE_CU,WIRE_AL),MATCH($I15,WIRE_SIZE,0)),0)+IFERROR(N($S15)*INDEX(IF($B$5="Cu",WIRE_CU,WIRE_AL),MATCH($R15,WIRE_SIZE,0)),0)+IFERROR(N($T15)*INDEX(PVC_RATE,MATCH($O15,PVC_SIZE,0)),0)+IFERROR(N($U15)*INDEX(PVC_RATE,MATCH("(3/4"")",PVC_SIZE,0)),0)
A16: Charger 5 | C16: =IF(N($B16)=0,"",IFERROR(INDEX(Equipment!$G$7:$G$18,MATCH($B16,Equipment!$A$7:$A$18,0)),"")) | E16: =IF(N($C16)=0,"",N($C16)*1000/(Project!$B$29*SQRT(3))) | F16: =IF(N($E16)=0,"",N($E16)*1.25) | G16: =IF(N($F16)=0,"",IF(ISNUMBER(MATCH($F16,OCPD_LIST,0)),$F16,IF($F16>MAX(OCPD_LIST),"ABOVE THE LARGEST STANDARD DEVICE",INDEX(OCPD_LIST,MATCH($F16,OCPD_LIST,1)+1)))) | H16: =IF(N($G16)=0,"",IF(N($G16)>800,N($G16),N($F16))) | K16: =IF($I16="","",IFERROR(MIN(N(INDEX(AMP_TBL,MATCH($I16,AMP_SIZE,0),MATCH($B$5&"-"&TEXT($F$6,"0"),AMP_HDR,0)))*N(INDEX(AMB_TBL,IF(ISNUMBER(MATCH($F$5,AMB_MAX,0)),MATCH($F$5,AMB_MAX,0),MATCH($F$5,AMB_MAX,1)+1),MATCH(TEXT($F$6,"0"),AMB_HDR,0))),N(INDEX(AMP_TBL,MATCH($I16,AMP_SIZE,0),MATCH($B$5&"-"&TEXT($F$7,"0"),AMP_HDR,0)))),"")) | L16: =IF(N($K16)=0,"",N($K16)*MAX(1,N($J16))) | M16: =IF(OR($I16="",N($D16)=0,N($E16)=0),"",IFERROR(SQRT(3)*N($E16)/MAX(1,N($J16))*N($D16)*N(INDEX(Z_TBL,MATCH($I16,Z_SIZE,0),IF($B$5="Cu",1,2)))/1000/Project!$B$29,"")) | N16: =IF(N($C16)=0,"",IF($I16="","pick a conductor size",IF($F$5="","SET THE DESIGN AMBIENT for this run — ampacity cannot be corrected without it, and this verdict cannot be trusted until it is set",IF(N($K16)=0,"no ampacity on file for that size — NEC Table 310.16 does not list it",IF(N($J16)=0,"enter the number of parallel sets",IF(N($L16)<N($H16),"UNDERSIZED — "&TEXT(N($L16),"#,##0")&" A provided against a floor of "&TEXT(N($H16),"#,##0")&" A. NEC 240.4(C) applies above 800 A: the conductor carries the device, not the load.",IF(N($M16)>N($F$8),"ampacity OK, but voltage drop "&TEXT(N($M16),"0.00%")&" exceeds the "&TEXT($F$8,"0.0%")&" allowance — ADVISORY, the impedance table is unverified","OK — "&TEXT(N($L16),"#,##0")&" A against a "&TEXT(N($H16),"#,##0")&" A floor; voltage drop "&TEXT(N($M16),"0.00%")&" (ADVISORY)"))))))) | P16: =IF($B16="","",IFERROR(IF(INDEX(Equipment!$E$7:$E$18,MATCH($B16,Equipment!$A$7:$A$18,0))="power_cabinet","power cabinet — dispensers run on from it",IF(INDEX(Equipment!$E$7:$E$18,MATCH($B16,Equipment!$A$7:$A$18,0))="dispenser","DISPENSER — this belongs in the DC runs block, not here",IF(INDEX(Equipment!$B$7:$B$18,MATCH($B16,Equipment!$A$7:$A$18,0))="Level 2 AC","Level 2 — use the Level 2 branch circuits block","all-in-one charger"))),"equipment line not found")) | Q16: =IF(N($D16)=0,0,N($D16)*MAX(1,N($J16))*3) | R16: =IF(N($G16)=0,"",IFERROR(INDEX(IF($B$5="Cu",EGC_CU,EGC_AL),MATCH($G16,EGC_OCPD,1)+IF(ISNUMBER(MATCH($G16,EGC_OCPD,0)),0,1)),"")) | S16: =IF(N($D16)=0,0,N($D16)*MAX(1,N($J16))) | T16: =IF(N($D16)=0,0,N($D16)*MAX(1,N($J16))) | U16: =IF(N($D16)=0,0,N($D16)) | V16: =IFERROR(N($Q16)*INDEX(IF($B$5="Cu",WIRE_CU,WIRE_AL),MATCH($I16,WIRE_SIZE,0)),0)+IFERROR(N($S16)*INDEX(IF($B$5="Cu",WIRE_CU,WIRE_AL),MATCH($R16,WIRE_SIZE,0)),0)+IFERROR(N($T16)*INDEX(PVC_RATE,MATCH($O16,PVC_SIZE,0)),0)+IFERROR(N($U16)*INDEX(PVC_RATE,MATCH("(3/4"")",PVC_SIZE,0)),0)
A17: Charger 6 | C17: =IF(N($B17)=0,"",IFERROR(INDEX(Equipment!$G$7:$G$18,MATCH($B17,Equipment!$A$7:$A$18,0)),"")) | E17: =IF(N($C17)=0,"",N($C17)*1000/(Project!$B$29*SQRT(3))) | F17: =IF(N($E17)=0,"",N($E17)*1.25) | G17: =IF(N($F17)=0,"",IF(ISNUMBER(MATCH($F17,OCPD_LIST,0)),$F17,IF($F17>MAX(OCPD_LIST),"ABOVE THE LARGEST STANDARD DEVICE",INDEX(OCPD_LIST,MATCH($F17,OCPD_LIST,1)+1)))) | H17: =IF(N($G17)=0,"",IF(N($G17)>800,N($G17),N($F17))) | K17: =IF($I17="","",IFERROR(MIN(N(INDEX(AMP_TBL,MATCH($I17,AMP_SIZE,0),MATCH($B$5&"-"&TEXT($F$6,"0"),AMP_HDR,0)))*N(INDEX(AMB_TBL,IF(ISNUMBER(MATCH($F$5,AMB_MAX,0)),MATCH($F$5,AMB_MAX,0),MATCH($F$5,AMB_MAX,1)+1),MATCH(TEXT($F$6,"0"),AMB_HDR,0))),N(INDEX(AMP_TBL,MATCH($I17,AMP_SIZE,0),MATCH($B$5&"-"&TEXT($F$7,"0"),AMP_HDR,0)))),"")) | L17: =IF(N($K17)=0,"",N($K17)*MAX(1,N($J17))) | M17: =IF(OR($I17="",N($D17)=0,N($E17)=0),"",IFERROR(SQRT(3)*N($E17)/MAX(1,N($J17))*N($D17)*N(INDEX(Z_TBL,MATCH($I17,Z_SIZE,0),IF($B$5="Cu",1,2)))/1000/Project!$B$29,"")) | N17: =IF(N($C17)=0,"",IF($I17="","pick a conductor size",IF($F$5="","SET THE DESIGN AMBIENT for this run — ampacity cannot be corrected without it, and this verdict cannot be trusted until it is set",IF(N($K17)=0,"no ampacity on file for that size — NEC Table 310.16 does not list it",IF(N($J17)=0,"enter the number of parallel sets",IF(N($L17)<N($H17),"UNDERSIZED — "&TEXT(N($L17),"#,##0")&" A provided against a floor of "&TEXT(N($H17),"#,##0")&" A. NEC 240.4(C) applies above 800 A: the conductor carries the device, not the load.",IF(N($M17)>N($F$8),"ampacity OK, but voltage drop "&TEXT(N($M17),"0.00%")&" exceeds the "&TEXT($F$8,"0.0%")&" allowance — ADVISORY, the impedance table is unverified","OK — "&TEXT(N($L17),"#,##0")&" A against a "&TEXT(N($H17),"#,##0")&" A floor; voltage drop "&TEXT(N($M17),"0.00%")&" (ADVISORY)"))))))) | P17: =IF($B17="","",IFERROR(IF(INDEX(Equipment!$E$7:$E$18,MATCH($B17,Equipment!$A$7:$A$18,0))="power_cabinet","power cabinet — dispensers run on from it",IF(INDEX(Equipment!$E$7:$E$18,MATCH($B17,Equipment!$A$7:$A$18,0))="dispenser","DISPENSER — this belongs in the DC runs block, not here",IF(INDEX(Equipment!$B$7:$B$18,MATCH($B17,Equipment!$A$7:$A$18,0))="Level 2 AC","Level 2 — use the Level 2 branch circuits block","all-in-one charger"))),"equipment line not found")) | Q17: =IF(N($D17)=0,0,N($D17)*MAX(1,N($J17))*3) | R17: =IF(N($G17)=0,"",IFERROR(INDEX(IF($B$5="Cu",EGC_CU,EGC_AL),MATCH($G17,EGC_OCPD,1)+IF(ISNUMBER(MATCH($G17,EGC_OCPD,0)),0,1)),"")) | S17: =IF(N($D17)=0,0,N($D17)*MAX(1,N($J17))) | T17: =IF(N($D17)=0,0,N($D17)*MAX(1,N($J17))) | U17: =IF(N($D17)=0,0,N($D17)) | V17: =IFERROR(N($Q17)*INDEX(IF($B$5="Cu",WIRE_CU,WIRE_AL),MATCH($I17,WIRE_SIZE,0)),0)+IFERROR(N($S17)*INDEX(IF($B$5="Cu",WIRE_CU,WIRE_AL),MATCH($R17,WIRE_SIZE,0)),0)+IFERROR(N($T17)*INDEX(PVC_RATE,MATCH($O17,PVC_SIZE,0)),0)+IFERROR(N($U17)*INDEX(PVC_RATE,MATCH("(3/4"")",PVC_SIZE,0)),0)
