Workbook
Name BM_L2_STATE: RefData!$A$205:$A$206
Name BM_L2_KWH: RefData!$B$205:$B$206
Name BM_L2_PRICE: RefData!$C$205:$C$206
Name CND_SIZE: RefData!$A$211:$A$228
Name CND_3G: RefData!$B$211:$B$228
Name CND_2G: RefData!$C$211:$C$228
Name SZ_SIZE: Electrical!$A$220:$A$237
Name SZ_AMP: Electrical!$D$220:$D$237
Name SZ_Z: Electrical!$E$220:$E$237

Sheet START HERE
B1: START HERE — how to fill this intake
B2: Two minutes to read. The tabs run left to right in the order you should fill them.
A4: 1 | B4: Fill the tabs in order: Project → Equipment → Electrical → Construction → Commercial → Revenue → Carbon. Existing is for sites that already have chargers OR an existing service the new chargers will connect to; Deal_Structure and Overrides only if they apply; Pricing computes itself.
A5: 2 | B5: Blue cells are yours. Type only in blue cells. Everything else is locked and works itself out.
A6: 3 | B6: Pick from the dropdown where one is offered. The price book, the rate library and the utility list sit behind the dropdowns on hidden tabs — right-click any tab and choose Unhide if you need to see them.
A7: 4 | B7: A [+] in the left margin means a block is folded away because most sites do not need it — entry checks, replacement-site sections, power-cabinet runs, derived working. The heading stays visible; click [+] to open it.
A8: 5 | B8: Leave a blue cell blank if you do not know the answer. Never type N/A, ?, TBC or a note into a number cell — a blank is read correctly, a word breaks the calculation.
A9: 6 | B9: Before you send it back, look at the verdict lines: ENTRY CHECKS ALL PASS at the foot of Equipment, the verdict column on the Electrical charger runs, and any line reading FIX or MISMATCH.
A10: 7 | B10: Do not add rows, columns or tabs, and do not move anything. The model reads this file by its labels. Save it with the revision letter in the file name and record what you changed on the Revisions tab.
B12: What the colours mean
B13: Blue — yours to fill. Unlocked. A dropdown may be attached.
B14: Grey — computed. Locked. Reads your blue cells and the reference tabs.
B15: Green — a check that passes, or a total.
B16: Amber — a caution note worth reading before you fill the block above it.
B17: Teal band — a table header. The table's rows are below it.
B19: Questions go to the Zero Impact Energy EV Charging Infrastructure Team.

Sheet Version
A1: DOCUMENT CONTROL
A2: Hardcoded. These values identify which generation of the template a returned file came from — never make them formulas.
A4: Template version | B4: 3.7.2
A5: Released | B5: 2026-09-18
A6: Template name | B6: EVSE Project Intake
A7: Issued by | B7: Zero Impact Energy
A8: Template content hash | B8: b83387921f8472c2 | C8: The hash of the BLANK template this file was built from, frozen at its release. It does not change when you fill the sheet in.
A9: Completed by — fill these in
A10: This file version | C10: e.g. Rev A, Rev B — increment each time you send it back
A11: Date completed
A12: Completed by
A13: Project reference
A14: Notes on this revision | C14: What changed since the last version you sent
A15: File content hash | B15: b83387921f8472c2 | C15: A hash of THIS workbook. It changes every time someone edits it, and it is what a model records so you can tell whether the model was built from the file in front of you.
A16: Changelog
A17: Version | B17: Released | C17: What changed
A18: 1.0.0 | B18: 2026-08-26 | C18: Initial release — project, equipment, electrical, construction, commercial, revenue and carbon intake with live consistency checks.
A19: 1.1.0 | B19: 2026-08-26 | C19: Deal structure knobs and the override register. Base case unchanged at zero.
A20: 1.2.0 | B20: 2026-08-26 | C20: PG&E Rule 29 interconnection capture. Electrical materials costed independently of the EVSE price book.
A21: 1.3.0 | B21: 2026-08-26 | C21: Utility rate engine across PG&E, SCE and SDG&E. Market benchmarks. Demand subscription ramps with concurrency.
A22: 1.4.0 | B22: 2026-08-26 | C22: Scope of supply controls — each service line can be provided by us, by others, or not required. Document control added.
A23: 1.5.0 | B23: 2026-08-26 | C23: Mixed-fleet fix — accessories no longer counted as charging units, and the placement check compares against DC cabinets only.
A24: 1.6.0 | B24: 2026-08-26 | C24: Description was not recorded at the time. The change sits between the mixed-fleet fix (1.5.0) and the rip-and-replace capability (1.7.0).
A25: 1.7.0 | B25: 2026-08-26 | C25: Rip-and-replace project type. A new Existing tab captures the existing installation, the retained-versus-replaced register, thirty-six months of usage and billing history, port and connector expansion, and the removal scope. Tabs 3, 4 and 6 respond to what is retained and can now be driven from historical actuals.
A26: 1.8.0 | B26: 2026-08-26 | C26: Utility selection became a dropdown of every California delivery utility — 56 investor-owned, publicly owned, tribal and cooperative entities that set their own retail tariff. New Utilities tab carries the roster and the community choice aggregators separately, because a CCA sets generation only and cannot set an EV tariff. New RateLibrary tab carries 32 researched commercial EV and fallback rates with a STATUS column, plus the utility rebate programmes and their open/closed state.
A27: 1.9.0 | B27: 2026-08-27 | C27: Price book states the included manufacturer warranty per charger class — two years on DC fast charging, one year on Level 2, parts only — and the out-of-warranty service column now reads NOT OFFERED rather than sitting blank, because a blank reads as zero to anything consuming the table. Service is sold only against a warranty in force, included or extended.
A28: 1.10.0 | B28: 2026-08-27 | C28: Capacity-first equipment picker on 2_Equipment. Pick a capacity — 60 kW, 120 kW, 360 kW, Level 2 and so on — and the SKU dropdown narrows to that capacity, five to fourteen SKUs instead of ninety-two. The capacity also supplies the rating kW where the price book records none, which it does for every Level 2, Buy America and V2G row; a Buy America 60 kW cabinet previously counted as zero kW and zero cabinets. A DC-only capacity line is added and the carbon credit repointed at it, because the LCFS credit is paid on DC capacity alone.
... A56: 3.7.2 | B56: 2026-09-18 | C56: 3.7.0 — Distribution feeders priced. New Electrical block I: one row per feeder between the items on the distribution schedule (existing board to EV panel, breaker to transformer, transformer to Level 2 panel, panel to panel), auto-sized from the site conductor table at the floor set by the item fed, with ground, conduit, parallel sets, voltage drop, material at RefData rates and a verdict per row. "Distribution feeder material ($)" joins the wire line on the Pricing tab and in engine 3.4.7. Until now nothing in the workbook priced the wire between the boxes. No rows inserted. 3.7.1 — Excel repair fix: the From/To dropdowns in block I were stored with a leading "=" in the validation formula, which Excel reports as corrupt content and strips on open. Stored form corrected; excel_limits.py now checks every delivered workbook for it. Rate-schedule picker: the SDG&E EV-HP entries now carry the rate library's exact names (the lookup is by text) and EV-HP Primary joins the list. Every row address as 3.7.0. 3.7.2 — Nine formulas (Electrical N160, B211:C213, B214; Construction B66) had been one closing bracket short since 3.6.0. LibreOffice closes an unbalanced formula silently, so every filled revision was whole; Excel deletes it, so every blank template since 3.6.0 opened through the repair prompt. Brackets restored at the source; every delivered workbook is now checked for bracket and quote balance.

Sheet Revisions
A1: PROJECT REVISION HISTORY
A2: This filled file's own history, one row per revision sent or received — Rev A is the first issue, Rev B the first return with corrections, and so on. The template's own changelog is on the Version tab. The engine copies this table onto the model's Version tab, so the model says which revision it was built from and what changed on the way there.
A4: Rev | B4: Date | C4: By | D4: What changed — the facts that moved, the decisions taken, what is still open
A18: Revisions recorded | B18: =COUNTA($A$5:$A$16)
A19: Latest revision on this table | B19: =IF(COUNTA($A$5:$A$16)=0,"none yet",INDEX($A$5:$A$16,COUNTA($A$5:$A$16)))
A20: Matches "This file version" on the Version tab? | B20: =IF(COUNTA($A$5:$A$16)=0,"nothing recorded — add a row for this revision",IF(TRIM($B$19)=TRIM(Version!$B$10),"OK — the Version tab and this table agree","MISMATCH — the Version tab says "&Version!$B$10&" and the latest row here is "&$B$19))

Sheet README
A1: EVSE PROJECT INTAKE
A2: Zero Impact Energy — one form, one project. Fill the blue cells; everything else is derived.
A4: How to use this workbook
A5: • | B5: Fill in every BLUE cell you can. Leave a cell blank rather than guessing — a blank is a question we will ask; a guess becomes a number in a proposal.
A6: • | B6: YELLOW cells are key commercial assumptions. They have sensible defaults, but they drive the return — change them deliberately, not by habit.
A7: • | B7: GREEN cells are live checks. They recalculate as you type. If a green cell turns into a warning, the sheet is telling you two of your inputs disagree.
A8: • | B8: GREY tabs (Lists, PriceBook, RefData) are reference data. Do not edit them unless prices have actually changed.
A9: • | B9: When the form is complete, send the file back. Everything downstream — electrical sizing, materials, labour, revenue, carbon, financing, the proposal — is computed from these inputs alone.
A11: Cell legend
A12: Appearance | B12: Meaning | C12: What to do
A13: Blue fill, blue text | B13: Human input | C13: Fill it in
A14: Yellow fill, blue bold | B14: Key commercial assumption | C14: Review the default, change deliberately
A15: Green fill, green text | B15: Live check / derived | C15: Read it — never type over it
A16: Grey | B16: Reference data | C16: Leave alone
A18: Tabs, in the order you should fill them
A19: 1_Project | B19: Who, where, which utility, and how the site is accessed
A20: 2_Equipment | B20: What is being sold — pick SKUs from the price book
A21: 3_Electrical | B21: Distances, wire, existing service. Drives every electrical cost.
A22: 4_Construction | B22: Site works, labour days, ADA, permits, rentals
A23: 5_Commercial | B23: Discounts, financing terms, service and network term
A24: 6_Revenue | B24: Pricing, utilisation, ramp and growth
A25: 7_Carbon | B25: FCI credit rate, aggregator, eligibility, grants
A27: 8_Deal_Structure | B27: Optional. Knobs for trading price against a share of credits or revenue.
A28: 9_Overrides | B28: Optional. Force any derived value when you have a quote or a measurement.
A30: Version | B30: Template 1.4.0, released 2026-08-26 — see the Version tab
A32: Replacement projects
A33: • | B33: The Existing tab covers three situations: a site that adds EV load to a service and switchboard it already has, a charger swap, and a replace-and-expand. Complete it whenever the site already has a service you intend to use or charging equipment you intend to replace.
A34: • | B34: Set the project type on the Existing tab section A first — every section header on that tab then says whether it applies, and every check keys off it.
A35: • | B35: Section B is the register that decides the cost. Marking the service, feeder, switchgear and conduit as RETAIN removes most of the electrical and civil scope; the Electrical and Construction tabs then tell you exactly which lines to zero.
A36: • | B36: Section E is the most valuable page in the whole intake. Twelve months of metered history beats every market assumption on the Revenue tab, and twenty-four months beats twelve. Enter outage months as they happened — do not smooth them.
A37: • | B37: Sections F and G turn the old installation into a projection: availability recovered, ports added, connector coverage widened and power increased, each with its own capture factor you can argue with.
A38: • | B38: Section H is the removal scope. It is zero on a greenfield or add-load project and real money on a replacement. Section I is the capacity test for any site that keeps its service.
A39: • | B39: Set the revenue basis at the foot of the Revenue tab to "Historical actuals" on any replacement site with twelve or more months of data.
A41: Choosing the utility
A42: • | B42: Pick the DELIVERY utility on the Project tab — the one that owns the wires and sets the tariff. If the site buys generation from a community choice aggregator, still pick the delivery utility; the CCA is a separate field below it.
A43: • | B43: A CCA changes only the generation cents per kWh. Eligibility, time-of-use periods, the demand subscription and every delivery charge stay with the utility. Build the bill from the delivery tariff and substitute one line.
A44: • | B44: Rule 29 exists only at investor-owned utilities. A municipal utility, irrigation district or cooperative has its own line-extension policy and the cost split can be completely different — do not carry a Rule 29 allowance on a POU site.
A45: • | B45: Read the STATUS column on RateLibrary before using any rate. VERIFIED means it was read in the utility's own tariff. NOT PUBLISHED means the utility does not publish it — SCE is the significant case — and those rows are left at zero deliberately rather than filled with a guess.
A46: • | B46: Whether a utility has an EV tariff at all is often worth more than the cents per kWh. A site on a utility with no EV rate pays full demand charges on a general commercial schedule, which at low utilisation dominates the bill.
A48: Returning this workbook
...

Sheet Project
A1: 1 · PROJECT AND SITE
A2: Identity, location, utility and access policy.
A4: Client
A5: Client legal name | C5: As it will appear on the proposal
A6: Client contact name
A7: Contact title
A8: Contact email
A9: Contact phone
A11: Site
A12: Site name
A13: Street address
A14: City / State / ZIP
A15: County
A16: Property type | C16: Retail, dealership, fleet depot, hotel, grocery…
A17: Project type | B17: =Existing!B5 | C17: Set this on the Existing tab. An add-load site completes the Existing tab sections B, D and I; a replacement site completes it in full; a greenfield site with a new service leaves it alone.
A18: Existing chargers on site? | B18: =IF(Existing!B43=0,"None",TEXT(Existing!B43,"0")&" ports across "&TEXT(Existing!B42,"0")&" units — see the Existing tab") | C18: Derived from the equipment schedule on the Existing tab.
A20: Access and operating policy
A21: Public access | C21: Public 24/7 / Public during business hours / Restricted
A22: Hours open per day | B22: 24 | C22: CRITICAL: 24 unless access is genuinely gated
A23: Days open per year | B23: 365 | C23: Use 365 unless the site closes seasonally
A25: Utility
A26: Electric utility (delivery) | C26: Pick from the list. This is the utility that DELIVERS power and therefore sets the EV tariff — see the Utilities tab. If the site is served by a community choice aggregator, still pick the delivery utility here.
A27: Current rate schedule | C27: From a recent bill
A28: Existing service size (A) | C28: Main service amperage today
A29: Service voltage | B29: 480 | C29: Usually 480V 3-phase for DC fast charging
A30: 12 months of bills obtained? | C30: Yes / No — needed to validate the energy cost
A32: Commercial
A33: Proposal date
A34: Proposal validity (days) | B34: 30
A35: Prepared by
A36: RSM / account owner
A39: Utility context — derived from the selection above
A40: These read the Utilities and RateLibrary tabs. They tell you what tariff regime the site sits in before anyone opens a tariff book.
A41: Utility type | B41: =IFERROR(INDEX(Utilities!$K$5:$K$78,MATCH($B$26,Utilities!$J$5:$J$78,0)),"") | C41: IOU utilities are CPUC-regulated and follow Rule 29. POUs and co-ops set their own rules — no Rule 29, no PCIA, their own interconnection process.
A42: Service territory | B42: =IFERROR(INDEX(Utilities!$L$5:$L$78,MATCH($B$26,Utilities!$J$5:$J$78,0)),"")
A43: EV rate status | B43: =IFERROR(INDEX(Utilities!$M$5:$M$78,MATCH($B$26,Utilities!$J$5:$J$78,0)),"") | C43: Whether this utility publishes a commercial EV tariff at all. Where it does not, the site pays full demand charges on a general commercial schedule — usually the single largest difference between two otherwise identical sites.
A44: Rate rows in the library | B44: =COUNTIF(RATE_UTIL,$B$26) | C44: How many schedules the library carries for this utility. Zero means it has not been researched — obtain the tariff.
A45: Best status in the library | B45: =IF(COUNTIF(RATE_UTIL,$B$26)=0,"NOT RESEARCHED — obtain the tariff at site selection",IF(COUNTIFS(RATE_UTIL,$B$26,RATE_STATUS,"VERIFIED")>0,"VERIFIED rates available",IF(COUNTIFS(RATE_UTIL,$B$26,RATE_STATUS,"PARTIAL")>0,"PARTIAL — some fields missing, read the row before pricing","UNVERIFIED — the library carries a rate but nobody has checked it against the filed tariff"))) | C45: Never price a project from a NOT PUBLISHED row. Get the tariff sheet or a written rate quotation.
A46: Community choice aggregator, if any | C46: A CCA changes ONLY the generation $/kWh. Eligibility, time-of-use periods, the demand subscription and every delivery charge stay with the utility above.
A47: CCA delivery utility check | B47: =IF(OR($B$46="",$B$46="None — bundled utility service"),"n/a — no aggregator",IF(IFERROR(INDEX(Utilities!$N$5:$N$78,MATCH($B$26,Utilities!$J$5:$J$78,0)),"")<>"California","n/a — community choice aggregation is a California mechanism",IFERROR(IF(ISNUMBER(SEARCH(LEFT($B$26,4),INDEX(Utilities!$C$67:$C$93,MATCH($B$46,Utilities!$A$67:$A$93,0)))),"OK — this CCA operates in the selected utility territory","CHECK — this CCA normally rides "&INDEX(Utilities!$C$67:$C$93,MATCH($B$46,Utilities!$A$67:$A$93,0))&" delivery"),"CHECK the pairing"))) | C47: Catches an aggregator paired with the wrong delivery utility. Central Coast Community Energy genuinely spans both PG&E and SCE, so it will flag — settle the host utility by address. Silent where no aggregator is named and outside California, where the mechanism does not exist.
...

Sheet Existing
A1: 1B · EXISTING SITE — existing service, rip and replace, or replace and expand
A2: Complete this tab when the site already has an electrical service you intend to use, or charging equipment you intend to replace. Set the project type first: it decides which sections below apply, and every check on this tab and on the Electrical and Construction tabs keys off it.
A4: A · Project type
A5: Project type | B5: Greenfield — new service | C5: Four types. GREENFIELD — NEW SERVICE builds everything, including a new utility service; only section A applies here. GREENFIELD — ADD LOAD TO EXISTING SERVICE: no chargers today, but a service and switchboard that can take the new load — complete sections B (service, feeder and switchgear rows), D and I; the others stand down. RIP AND REPLACE and REPLACE AND EXPAND: chargers exist today — complete every section.
A6: Age of the existing installation (years) | C6: Drives whether the existing conductors and gear are worth reusing.
A7: Reason for replacement | C7: End of life, unreliability, obsolete connectors, insufficient power, or a commercial decision.
A8: Who owns the existing equipment? | C8: If a third party owns it, removal and disposal need their agreement.
A10: B · What is retained and what is replaced
A11: This register is the whole commercial difference between a greenfield build, an added load on an existing service and a charger swap. On an add-load site the first three rows are RETAIN and the rest are NOT PRESENT — there are no chargers to keep or replace.
A12: Element | B12: Decision | C12: Basis for the decision
A13: Utility service and meter | C13: Existing service stays. No Rule 29 application, no new meter.
A14: Service feeder to switchgear | C14: Conductor from the point of delivery to the switchboard.
A15: Main distribution switchgear | C15: Switchboard, main breaker and metering section.
A16: Branch conductors to each charger | C16: The feeders from switchgear to cabinet. The single largest reuse saving.
A17: Conduit and trench | C17: Existing conduit reused; no re-trenching if the new cabinets land on the same pads.
A18: Branch breakers | C18: Sized to the new cabinet, not the old one. Usually cheap and always worth replacing.
A19: Concrete pads | C19: New cabinets rarely match the old footprint or anchor pattern.
A20: Bollards and equipment protection | C20: Usually disturbed by pad removal.
A21: Paving and striping | C21: Reinstatement around the new pads only.
A22: ADA stalls and route | C22: Reused if the layout is unchanged and still compliant.
A23: Signage | C23: Network branding, pricing and connector types all change.
A24: Network and payment hardware | C24: Integrated in the new cabinets.
A26: Elements retained | B26: =COUNTIF($B$13:$B$24,"RETAIN") | C26: Of 12 in the register.
A27: Elements replaced | B27: =COUNTIF($B$13:$B$24,"REPLACE")+COUNTIF($B$13:$B$24,"PARTIAL")
A28: Scope profile | B28: =IF($B$5="Greenfield — add load to existing service","Add load to existing service — no new service, no new feeder; connect at the existing switchgear and price the distribution from there inward",IF($B$13="RETAIN",IF($B$14="RETAIN","Infrastructure reuse — no new service, no new feeder","Service retained, feeder replaced"),"New or upgraded service — price this as greenfield electrical")) | D28: What the retained register implies for the electrical scope on the Electrical tab.
A30: C · Existing equipment being removed | B30: =IF(OR($B$5="Greenfield — new service",$B$5="Greenfield — add load to existing service"),"— skip: no existing chargers","— complete this section")
A31: One row per existing cabinet or unit. This drives the demolition, disconnection and disposal scope on the Construction tab, and the port comparison in section F.
A32: Make and model | B32: Rating kW | C32: Ports | D32: Connectors | E32: Qty | F32: Year installed | G32: Working?
A42: Existing units on site | B42: =SUM($E$33:$E$40) | C42: Cabinets or standalone units to be removed.
A43: Existing ports on site | B43: =SUMPRODUCT($C$33:$C$40,$E$33:$E$40) | C43: Ports the site presents today.
A44: Existing connected load (kW) | B44: =SUMPRODUCT($B$33:$B$40,$E$33:$E$40) | C44: The load the existing service was sized for. Compare against the new load on the Electrical tab.
A45: Units fully working | B45: =SUMIF($G$33:$G$40,"Working",$E$33:$E$40) | C45: Quantity, not row count. The gap against units on site is the availability the new equipment recovers.
A46: Units failed or intermittent | B46: =SUMIF($G$33:$G$40,"Failed",$E$33:$E$40)+SUMIF($G$33:$G$40,"Intermittent",$E$33:$E$40) | C46: What the replacement is actually fixing.
A47: Units of unknown condition | B47: =SUMIF($G$33:$G$40,"Unknown",$E$33:$E$40) | C47: The availability uplift on the revenue projection is built from what was working and what was not. Anything in this row is a projection input nobody has established yet.
A48: D · Existing electrical infrastructure | B48: =IF($B$5<>"Greenfield — new service","— complete this section","— skip: new service")
A49: What is already in the ground. Where a line is being retained — including on an add-load site — this is what the new design has to work with; where it is being replaced, this is what has to come out. The capacity verdicts on rows 60 and 61 are computed in section I at the foot of this tab.
A50: Existing service size (A) | C50: From the meter panel or the utility bill.
A51: Existing service voltage | B51: =IF($B$5="Greenfield — new service","n/a",IF($B$13="RETAIN",Project!$B$29,"replaced — the new service voltage is on the Project tab")) | C51: Derived. When the service is retained this IS the service voltage on the Project tab, and the electrical checks read that cell — it was a second home for one fact, and on a Level 2 replacement the two disagreed by 272 V. Set the voltage on the Project tab.
A52: Spare capacity in the existing gear (A) | C52: What is available for the new equipment without an upgrade.
A53: Existing switchgear frame (A) | C53: The main breaker frame size.
...

Sheet Equipment
A1: 2 · EQUIPMENT SCHEDULE
A2: Pick the CAPACITY first, then the SKU. A distributed system is TWO kinds of line: the power cabinet, and each dispenser it feeds.
A4: Enter one row per SKU. Qty is the number of CABINETS, not ports. Columns Q-V are auto: they number the units and dispensers so the Electrical tab can list every run for you.
A6: Line | B6: Capacity | C6: SKU | D6: Description (auto) | E6: Role (auto) | F6: DC output kW (auto) | G6: AC input kW (auto, at the Level 2 supply voltage) | H6: Connectors (auto) | I6: Qty (units) | J6: Discount — set on the Commercial tab | K6: MSRP each (auto) | L6: Dispenser SKU (distributed only) | M6: Max dispensers (auto) | N6: Dispensers per cabinet | O6: Connectors per dispenser (1 or 2) | P6: Dispenser MSRP each (auto) | Q6: Feeder or branch units (auto) | R6: First unit # (auto) | S6: Units through this line (auto) | T6: Dispensers on this line (auto) | U6: First dispenser # (auto) | V6: Dispensers through this line (auto)
A7: 1 | D7: =IFERROR(INDEX(PriceBook!$C$2:$C$203,MATCH($C7,PriceBook!$B$2:$B$203,0)),"") | E7: =IF($C7="","",IFERROR(INDEX(ROLE_VAL,MATCH($C7,ROLE_SKU,0)),"all_in_one")) | F7: =IF($C7="",0,IFERROR(INDEX(SPEC_DCKW,MATCH($C7,SPEC_SKU,0)),IF($E7="dispenser",0,IF($E7="accessory",0,IFERROR(IF(N(INDEX(PriceBook!$E$2:$E$203,MATCH($C7,PriceBook!$B$2:$B$203,0)))>0,INDEX(PriceBook!$E$2:$E$203,MATCH($C7,PriceBook!$B$2:$B$203,0)),INDEX(RATED_KW,MATCH($B7,CAPACITY_LIST,0))*IF(INDEX(PER_PORT,MATCH($B7,CAPACITY_LIST,0))=1,MAX(1,N($H7)),1)),0))))) | G7: =IF($C7="",0,IFERROR(INDEX(SPEC_ACKW,MATCH($C7,SPEC_SKU,0)),$F7)*IF(AND($E7="level_2",N($B$30)>0,$B$30<240),$B$30/240,1)) | H7: =IF($C7="",0,IF($E7="power_cabinet",N($N7)*N($O7),IFERROR(INDEX(SPEC_OUTS,MATCH($C7,SPEC_SKU,0)),IFERROR(INDEX(SKU_CONN,MATCH($C7,SKU_ALL,0)),0)))) | K7: =IFERROR(INDEX(PriceBook!$D$2:$D$203,MATCH($C7,PriceBook!$B$2:$B$203,0)),0) | M7: =IF($E7<>"power_cabinet",0,IFERROR(INDEX(SPEC_MAXDISP,MATCH($C7,SPEC_SKU,0)),0)) | P7: =IF($L7="",0,IFERROR(INDEX(PriceBook!$D$2:$D$203,MATCH($L7,PriceBook!$B$2:$B$203,0)),0)) | Q7: =IF(OR($E7="all_in_one",$E7="power_cabinet",$E7="level_2"),N($I7),0) | R7: =IF(N($Q7)=0,"",SUM($Q$7:$Q7)-N($Q7)+1) | S7: =SUM($Q$7:$Q7) | T7: =IF($E7="power_cabinet",N($I7)*N($N7),0) | U7: =IF(N($T7)=0,"",SUM($T$7:$T7)-N($T7)+1) | V7: =SUM($T$7:$T7)
A8: 2 | D8: =IFERROR(INDEX(PriceBook!$C$2:$C$203,MATCH($C8,PriceBook!$B$2:$B$203,0)),"") | E8: =IF($C8="","",IFERROR(INDEX(ROLE_VAL,MATCH($C8,ROLE_SKU,0)),"all_in_one")) | F8: =IF($C8="",0,IFERROR(INDEX(SPEC_DCKW,MATCH($C8,SPEC_SKU,0)),IF($E8="dispenser",0,IF($E8="accessory",0,IFERROR(IF(N(INDEX(PriceBook!$E$2:$E$203,MATCH($C8,PriceBook!$B$2:$B$203,0)))>0,INDEX(PriceBook!$E$2:$E$203,MATCH($C8,PriceBook!$B$2:$B$203,0)),INDEX(RATED_KW,MATCH($B8,CAPACITY_LIST,0))*IF(INDEX(PER_PORT,MATCH($B8,CAPACITY_LIST,0))=1,MAX(1,N($H8)),1)),0))))) | G8: =IF($C8="",0,IFERROR(INDEX(SPEC_ACKW,MATCH($C8,SPEC_SKU,0)),$F8)*IF(AND($E8="level_2",N($B$30)>0,$B$30<240),$B$30/240,1)) | H8: =IF($C8="",0,IF($E8="power_cabinet",N($N8)*N($O8),IFERROR(INDEX(SPEC_OUTS,MATCH($C8,SPEC_SKU,0)),IFERROR(INDEX(SKU_CONN,MATCH($C8,SKU_ALL,0)),0)))) | K8: =IFERROR(INDEX(PriceBook!$D$2:$D$203,MATCH($C8,PriceBook!$B$2:$B$203,0)),0) | M8: =IF($E8<>"power_cabinet",0,IFERROR(INDEX(SPEC_MAXDISP,MATCH($C8,SPEC_SKU,0)),0)) | P8: =IF($L8="",0,IFERROR(INDEX(PriceBook!$D$2:$D$203,MATCH($L8,PriceBook!$B$2:$B$203,0)),0)) | Q8: =IF(OR($E8="all_in_one",$E8="power_cabinet",$E8="level_2"),N($I8),0) | R8: =IF(N($Q8)=0,"",SUM($Q$7:$Q8)-N($Q8)+1) | S8: =SUM($Q$7:$Q8) | T8: =IF($E8="power_cabinet",N($I8)*N($N8),0) | U8: =IF(N($T8)=0,"",SUM($T$7:$T8)-N($T8)+1) | V8: =SUM($T$7:$T8)
A9: 3 | D9: =IFERROR(INDEX(PriceBook!$C$2:$C$203,MATCH($C9,PriceBook!$B$2:$B$203,0)),"") | E9: =IF($C9="","",IFERROR(INDEX(ROLE_VAL,MATCH($C9,ROLE_SKU,0)),"all_in_one")) | F9: =IF($C9="",0,IFERROR(INDEX(SPEC_DCKW,MATCH($C9,SPEC_SKU,0)),IF($E9="dispenser",0,IF($E9="accessory",0,IFERROR(IF(N(INDEX(PriceBook!$E$2:$E$203,MATCH($C9,PriceBook!$B$2:$B$203,0)))>0,INDEX(PriceBook!$E$2:$E$203,MATCH($C9,PriceBook!$B$2:$B$203,0)),INDEX(RATED_KW,MATCH($B9,CAPACITY_LIST,0))*IF(INDEX(PER_PORT,MATCH($B9,CAPACITY_LIST,0))=1,MAX(1,N($H9)),1)),0))))) | G9: =IF($C9="",0,IFERROR(INDEX(SPEC_ACKW,MATCH($C9,SPEC_SKU,0)),$F9)*IF(AND($E9="level_2",N($B$30)>0,$B$30<240),$B$30/240,1)) | H9: =IF($C9="",0,IF($E9="power_cabinet",N($N9)*N($O9),IFERROR(INDEX(SPEC_OUTS,MATCH($C9,SPEC_SKU,0)),IFERROR(INDEX(SKU_CONN,MATCH($C9,SKU_ALL,0)),0)))) | K9: =IFERROR(INDEX(PriceBook!$D$2:$D$203,MATCH($C9,PriceBook!$B$2:$B$203,0)),0) | M9: =IF($E9<>"power_cabinet",0,IFERROR(INDEX(SPEC_MAXDISP,MATCH($C9,SPEC_SKU,0)),0)) | P9: =IF($L9="",0,IFERROR(INDEX(PriceBook!$D$2:$D$203,MATCH($L9,PriceBook!$B$2:$B$203,0)),0)) | Q9: =IF(OR($E9="all_in_one",$E9="power_cabinet",$E9="level_2"),N($I9),0) | R9: =IF(N($Q9)=0,"",SUM($Q$7:$Q9)-N($Q9)+1) | S9: =SUM($Q$7:$Q9) | T9: =IF($E9="power_cabinet",N($I9)*N($N9),0) | U9: =IF(N($T9)=0,"",SUM($T$7:$T9)-N($T9)+1) | V9: =SUM($T$7:$T9)
A10: 4 | D10: =IFERROR(INDEX(PriceBook!$C$2:$C$203,MATCH($C10,PriceBook!$B$2:$B$203,0)),"") | E10: =IF($C10="","",IFERROR(INDEX(ROLE_VAL,MATCH($C10,ROLE_SKU,0)),"all_in_one")) | F10: =IF($C10="",0,IFERROR(INDEX(SPEC_DCKW,MATCH($C10,SPEC_SKU,0)),IF($E10="dispenser",0,IF($E10="accessory",0,IFERROR(IF(N(INDEX(PriceBook!$E$2:$E$203,MATCH($C10,PriceBook!$B$2:$B$203,0)))>0,INDEX(PriceBook!$E$2:$E$203,MATCH($C10,PriceBook!$B$2:$B$203,0)),INDEX(RATED_KW,MATCH($B10,CAPACITY_LIST,0))*IF(INDEX(PER_PORT,MATCH($B10,CAPACITY_LIST,0))=1,MAX(1,N($H10)),1)),0))))) | G10: =IF($C10="",0,IFERROR(INDEX(SPEC_ACKW,MATCH($C10,SPEC_SKU,0)),$F10)*IF(AND($E10="level_2",N($B$30)>0,$B$30<240),$B$30/240,1)) | H10: =IF($C10="",0,IF($E10="power_cabinet",N($N10)*N($O10),IFERROR(INDEX(SPEC_OUTS,MATCH($C10,SPEC_SKU,0)),IFERROR(INDEX(SKU_CONN,MATCH($C10,SKU_ALL,0)),0)))) | K10: =IFERROR(INDEX(PriceBook!$D$2:$D$203,MATCH($C10,PriceBook!$B$2:$B$203,0)),0) | M10: =IF($E10<>"power_cabinet",0,IFERROR(INDEX(SPEC_MAXDISP,MATCH($C10,SPEC_SKU,0)),0)) | P10: =IF($L10="",0,IFERROR(INDEX(PriceBook!$D$2:$D$203,MATCH($L10,PriceBook!$B$2:$B$203,0)),0)) | Q10: =IF(OR($E10="all_in_one",$E10="power_cabinet",$E10="level_2"),N($I10),0) | R10: =IF(N($Q10)=0,"",SUM($Q$7:$Q10)-N($Q10)+1) | S10: =SUM($Q$7:$Q10) | T10: =IF($E10="power_cabinet",N($I10)*N($N10),0) | U10: =IF(N($T10)=0,"",SUM($T$7:$T10)-N($T10)+1) | V10: =SUM($T$7:$T10)
A11: 5 | D11: =IFERROR(INDEX(PriceBook!$C$2:$C$203,MATCH($C11,PriceBook!$B$2:$B$203,0)),"") | E11: =IF($C11="","",IFERROR(INDEX(ROLE_VAL,MATCH($C11,ROLE_SKU,0)),"all_in_one")) | F11: =IF($C11="",0,IFERROR(INDEX(SPEC_DCKW,MATCH($C11,SPEC_SKU,0)),IF($E11="dispenser",0,IF($E11="accessory",0,IFERROR(IF(N(INDEX(PriceBook!$E$2:$E$203,MATCH($C11,PriceBook!$B$2:$B$203,0)))>0,INDEX(PriceBook!$E$2:$E$203,MATCH($C11,PriceBook!$B$2:$B$203,0)),INDEX(RATED_KW,MATCH($B11,CAPACITY_LIST,0))*IF(INDEX(PER_PORT,MATCH($B11,CAPACITY_LIST,0))=1,MAX(1,N($H11)),1)),0))))) | G11: =IF($C11="",0,IFERROR(INDEX(SPEC_ACKW,MATCH($C11,SPEC_SKU,0)),$F11)*IF(AND($E11="level_2",N($B$30)>0,$B$30<240),$B$30/240,1)) | H11: =IF($C11="",0,IF($E11="power_cabinet",N($N11)*N($O11),IFERROR(INDEX(SPEC_OUTS,MATCH($C11,SPEC_SKU,0)),IFERROR(INDEX(SKU_CONN,MATCH($C11,SKU_ALL,0)),0)))) | K11: =IFERROR(INDEX(PriceBook!$D$2:$D$203,MATCH($C11,PriceBook!$B$2:$B$203,0)),0) | M11: =IF($E11<>"power_cabinet",0,IFERROR(INDEX(SPEC_MAXDISP,MATCH($C11,SPEC_SKU,0)),0)) | P11: =IF($L11="",0,IFERROR(INDEX(PriceBook!$D$2:$D$203,MATCH($L11,PriceBook!$B$2:$B$203,0)),0)) | Q11: =IF(OR($E11="all_in_one",$E11="power_cabinet",$E11="level_2"),N($I11),0) | R11: =IF(N($Q11)=0,"",SUM($Q$7:$Q11)-N($Q11)+1) | S11: =SUM($Q$7:$Q11) | T11: =IF($E11="power_cabinet",N($I11)*N($N11),0) | U11: =IF(N($T11)=0,"",SUM($T$7:$T11)-N($T11)+1) | V11: =SUM($T$7:$T11)
A12: 6 | D12: =IFERROR(INDEX(PriceBook!$C$2:$C$203,MATCH($C12,PriceBook!$B$2:$B$203,0)),"") | E12: =IF($C12="","",IFERROR(INDEX(ROLE_VAL,MATCH($C12,ROLE_SKU,0)),"all_in_one")) | F12: =IF($C12="",0,IFERROR(INDEX(SPEC_DCKW,MATCH($C12,SPEC_SKU,0)),IF($E12="dispenser",0,IF($E12="accessory",0,IFERROR(IF(N(INDEX(PriceBook!$E$2:$E$203,MATCH($C12,PriceBook!$B$2:$B$203,0)))>0,INDEX(PriceBook!$E$2:$E$203,MATCH($C12,PriceBook!$B$2:$B$203,0)),INDEX(RATED_KW,MATCH($B12,CAPACITY_LIST,0))*IF(INDEX(PER_PORT,MATCH($B12,CAPACITY_LIST,0))=1,MAX(1,N($H12)),1)),0))))) | G12: =IF($C12="",0,IFERROR(INDEX(SPEC_ACKW,MATCH($C12,SPEC_SKU,0)),$F12)*IF(AND($E12="level_2",N($B$30)>0,$B$30<240),$B$30/240,1)) | H12: =IF($C12="",0,IF($E12="power_cabinet",N($N12)*N($O12),IFERROR(INDEX(SPEC_OUTS,MATCH($C12,SPEC_SKU,0)),IFERROR(INDEX(SKU_CONN,MATCH($C12,SKU_ALL,0)),0)))) | K12: =IFERROR(INDEX(PriceBook!$D$2:$D$203,MATCH($C12,PriceBook!$B$2:$B$203,0)),0) | M12: =IF($E12<>"power_cabinet",0,IFERROR(INDEX(SPEC_MAXDISP,MATCH($C12,SPEC_SKU,0)),0)) | P12: =IF($L12="",0,IFERROR(INDEX(PriceBook!$D$2:$D$203,MATCH($L12,PriceBook!$B$2:$B$203,0)),0)) | Q12: =IF(OR($E12="all_in_one",$E12="power_cabinet",$E12="level_2"),N($I12),0) | R12: =IF(N($Q12)=0,"",SUM($Q$7:$Q12)-N($Q12)+1) | S12: =SUM($Q$7:$Q12) | T12: =IF($E12="power_cabinet",N($I12)*N($N12),0) | U12: =IF(N($T12)=0,"",SUM($T$7:$T12)-N($T12)+1) | V12: =SUM($T$7:$T12)
A13: 7 | D13: =IFERROR(INDEX(PriceBook!$C$2:$C$203,MATCH($C13,PriceBook!$B$2:$B$203,0)),"") | E13: =IF($C13="","",IFERROR(INDEX(ROLE_VAL,MATCH($C13,ROLE_SKU,0)),"all_in_one")) | F13: =IF($C13="",0,IFERROR(INDEX(SPEC_DCKW,MATCH($C13,SPEC_SKU,0)),IF($E13="dispenser",0,IF($E13="accessory",0,IFERROR(IF(N(INDEX(PriceBook!$E$2:$E$203,MATCH($C13,PriceBook!$B$2:$B$203,0)))>0,INDEX(PriceBook!$E$2:$E$203,MATCH($C13,PriceBook!$B$2:$B$203,0)),INDEX(RATED_KW,MATCH($B13,CAPACITY_LIST,0))*IF(INDEX(PER_PORT,MATCH($B13,CAPACITY_LIST,0))=1,MAX(1,N($H13)),1)),0))))) | G13: =IF($C13="",0,IFERROR(INDEX(SPEC_ACKW,MATCH($C13,SPEC_SKU,0)),$F13)*IF(AND($E13="level_2",N($B$30)>0,$B$30<240),$B$30/240,1)) | H13: =IF($C13="",0,IF($E13="power_cabinet",N($N13)*N($O13),IFERROR(INDEX(SPEC_OUTS,MATCH($C13,SPEC_SKU,0)),IFERROR(INDEX(SKU_CONN,MATCH($C13,SKU_ALL,0)),0)))) | K13: =IFERROR(INDEX(PriceBook!$D$2:$D$203,MATCH($C13,PriceBook!$B$2:$B$203,0)),0) | M13: =IF($E13<>"power_cabinet",0,IFERROR(INDEX(SPEC_MAXDISP,MATCH($C13,SPEC_SKU,0)),0)) | P13: =IF($L13="",0,IFERROR(INDEX(PriceBook!$D$2:$D$203,MATCH($L13,PriceBook!$B$2:$B$203,0)),0)) | Q13: =IF(OR($E13="all_in_one",$E13="power_cabinet",$E13="level_2"),N($I13),0) | R13: =IF(N($Q13)=0,"",SUM($Q$7:$Q13)-N($Q13)+1) | S13: =SUM($Q$7:$Q13) | T13: =IF($E13="power_cabinet",N($I13)*N($N13),0) | U13: =IF(N($T13)=0,"",SUM($T$7:$T13)-N($T13)+1) | V13: =SUM($T$7:$T13)
A14: 8 | D14: =IFERROR(INDEX(PriceBook!$C$2:$C$203,MATCH($C14,PriceBook!$B$2:$B$203,0)),"") | E14: =IF($C14="","",IFERROR(INDEX(ROLE_VAL,MATCH($C14,ROLE_SKU,0)),"all_in_one")) | F14: =IF($C14="",0,IFERROR(INDEX(SPEC_DCKW,MATCH($C14,SPEC_SKU,0)),IF($E14="dispenser",0,IF($E14="accessory",0,IFERROR(IF(N(INDEX(PriceBook!$E$2:$E$203,MATCH($C14,PriceBook!$B$2:$B$203,0)))>0,INDEX(PriceBook!$E$2:$E$203,MATCH($C14,PriceBook!$B$2:$B$203,0)),INDEX(RATED_KW,MATCH($B14,CAPACITY_LIST,0))*IF(INDEX(PER_PORT,MATCH($B14,CAPACITY_LIST,0))=1,MAX(1,N($H14)),1)),0))))) | G14: =IF($C14="",0,IFERROR(INDEX(SPEC_ACKW,MATCH($C14,SPEC_SKU,0)),$F14)*IF(AND($E14="level_2",N($B$30)>0,$B$30<240),$B$30/240,1)) | H14: =IF($C14="",0,IF($E14="power_cabinet",N($N14)*N($O14),IFERROR(INDEX(SPEC_OUTS,MATCH($C14,SPEC_SKU,0)),IFERROR(INDEX(SKU_CONN,MATCH($C14,SKU_ALL,0)),0)))) | K14: =IFERROR(INDEX(PriceBook!$D$2:$D$203,MATCH($C14,PriceBook!$B$2:$B$203,0)),0) | M14: =IF($E14<>"power_cabinet",0,IFERROR(INDEX(SPEC_MAXDISP,MATCH($C14,SPEC_SKU,0)),0)) | P14: =IF($L14="",0,IFERROR(INDEX(PriceBook!$D$2:$D$203,MATCH($L14,PriceBook!$B$2:$B$203,0)),0)) | Q14: =IF(OR($E14="all_in_one",$E14="power_cabinet",$E14="level_2"),N($I14),0) | R14: =IF(N($Q14)=0,"",SUM($Q$7:$Q14)-N($Q14)+1) | S14: =SUM($Q$7:$Q14) | T14: =IF($E14="power_cabinet",N($I14)*N($N14),0) | U14: =IF(N($T14)=0,"",SUM($T$7:$T14)-N($T14)+1) | V14: =SUM($T$7:$T14)
A15: 9 | D15: =IFERROR(INDEX(PriceBook!$C$2:$C$203,MATCH($C15,PriceBook!$B$2:$B$203,0)),"") | E15: =IF($C15="","",IFERROR(INDEX(ROLE_VAL,MATCH($C15,ROLE_SKU,0)),"all_in_one")) | F15: =IF($C15="",0,IFERROR(INDEX(SPEC_DCKW,MATCH($C15,SPEC_SKU,0)),IF($E15="dispenser",0,IF($E15="accessory",0,IFERROR(IF(N(INDEX(PriceBook!$E$2:$E$203,MATCH($C15,PriceBook!$B$2:$B$203,0)))>0,INDEX(PriceBook!$E$2:$E$203,MATCH($C15,PriceBook!$B$2:$B$203,0)),INDEX(RATED_KW,MATCH($B15,CAPACITY_LIST,0))*IF(INDEX(PER_PORT,MATCH($B15,CAPACITY_LIST,0))=1,MAX(1,N($H15)),1)),0))))) | G15: =IF($C15="",0,IFERROR(INDEX(SPEC_ACKW,MATCH($C15,SPEC_SKU,0)),$F15)*IF(AND($E15="level_2",N($B$30)>0,$B$30<240),$B$30/240,1)) | H15: =IF($C15="",0,IF($E15="power_cabinet",N($N15)*N($O15),IFERROR(INDEX(SPEC_OUTS,MATCH($C15,SPEC_SKU,0)),IFERROR(INDEX(SKU_CONN,MATCH($C15,SKU_ALL,0)),0)))) | K15: =IFERROR(INDEX(PriceBook!$D$2:$D$203,MATCH($C15,PriceBook!$B$2:$B$203,0)),0) | M15: =IF($E15<>"power_cabinet",0,IFERROR(INDEX(SPEC_MAXDISP,MATCH($C15,SPEC_SKU,0)),0)) | P15: =IF($L15="",0,IFERROR(INDEX(PriceBook!$D$2:$D$203,MATCH($L15,PriceBook!$B$2:$B$203,0)),0)) | Q15: =IF(OR($E15="all_in_one",$E15="power_cabinet",$E15="level_2"),N($I15),0) | R15: =IF(N($Q15)=0,"",SUM($Q$7:$Q15)-N($Q15)+1) | S15: =SUM($Q$7:$Q15) | T15: =IF($E15="power_cabinet",N($I15)*N($N15),0) | U15: =IF(N($T15)=0,"",SUM($T$7:$T15)-N($T15)+1) | V15: =SUM($T$7:$T15)
A16: 10 | D16: =IFERROR(INDEX(PriceBook!$C$2:$C$203,MATCH($C16,PriceBook!$B$2:$B$203,0)),"") | E16: =IF($C16="","",IFERROR(INDEX(ROLE_VAL,MATCH($C16,ROLE_SKU,0)),"all_in_one")) | F16: =IF($C16="",0,IFERROR(INDEX(SPEC_DCKW,MATCH($C16,SPEC_SKU,0)),IF($E16="dispenser",0,IF($E16="accessory",0,IFERROR(IF(N(INDEX(PriceBook!$E$2:$E$203,MATCH($C16,PriceBook!$B$2:$B$203,0)))>0,INDEX(PriceBook!$E$2:$E$203,MATCH($C16,PriceBook!$B$2:$B$203,0)),INDEX(RATED_KW,MATCH($B16,CAPACITY_LIST,0))*IF(INDEX(PER_PORT,MATCH($B16,CAPACITY_LIST,0))=1,MAX(1,N($H16)),1)),0))))) | G16: =IF($C16="",0,IFERROR(INDEX(SPEC_ACKW,MATCH($C16,SPEC_SKU,0)),$F16)*IF(AND($E16="level_2",N($B$30)>0,$B$30<240),$B$30/240,1)) | H16: =IF($C16="",0,IF($E16="power_cabinet",N($N16)*N($O16),IFERROR(INDEX(SPEC_OUTS,MATCH($C16,SPEC_SKU,0)),IFERROR(INDEX(SKU_CONN,MATCH($C16,SKU_ALL,0)),0)))) | K16: =IFERROR(INDEX(PriceBook!$D$2:$D$203,MATCH($C16,PriceBook!$B$2:$B$203,0)),0) | M16: =IF($E16<>"power_cabinet",0,IFERROR(INDEX(SPEC_MAXDISP,MATCH($C16,SPEC_SKU,0)),0)) | P16: =IF($L16="",0,IFERROR(INDEX(PriceBook!$D$2:$D$203,MATCH($L16,PriceBook!$B$2:$B$203,0)),0)) | Q16: =IF(OR($E16="all_in_one",$E16="power_cabinet",$E16="level_2"),N($I16),0) | R16: =IF(N($Q16)=0,"",SUM($Q$7:$Q16)-N($Q16)+1) | S16: =SUM($Q$7:$Q16) | T16: =IF($E16="power_cabinet",N($I16)*N($N16),0) | U16: =IF(N($T16)=0,"",SUM($T$7:$T16)-N($T16)+1) | V16: =SUM($T$7:$T16)
A17: 11 | D17: =IFERROR(INDEX(PriceBook!$C$2:$C$203,MATCH($C17,PriceBook!$B$2:$B$203,0)),"") | E17: =IF($C17="","",IFERROR(INDEX(ROLE_VAL,MATCH($C17,ROLE_SKU,0)),"all_in_one")) | F17: =IF($C17="",0,IFERROR(INDEX(SPEC_DCKW,MATCH($C17,SPEC_SKU,0)),IF($E17="dispenser",0,IF($E17="accessory",0,IFERROR(IF(N(INDEX(PriceBook!$E$2:$E$203,MATCH($C17,PriceBook!$B$2:$B$203,0)))>0,INDEX(PriceBook!$E$2:$E$203,MATCH($C17,PriceBook!$B$2:$B$203,0)),INDEX(RATED_KW,MATCH($B17,CAPACITY_LIST,0))*IF(INDEX(PER_PORT,MATCH($B17,CAPACITY_LIST,0))=1,MAX(1,N($H17)),1)),0))))) | G17: =IF($C17="",0,IFERROR(INDEX(SPEC_ACKW,MATCH($C17,SPEC_SKU,0)),$F17)*IF(AND($E17="level_2",N($B$30)>0,$B$30<240),$B$30/240,1)) | H17: =IF($C17="",0,IF($E17="power_cabinet",N($N17)*N($O17),IFERROR(INDEX(SPEC_OUTS,MATCH($C17,SPEC_SKU,0)),IFERROR(INDEX(SKU_CONN,MATCH($C17,SKU_ALL,0)),0)))) | K17: =IFERROR(INDEX(PriceBook!$D$2:$D$203,MATCH($C17,PriceBook!$B$2:$B$203,0)),0) | M17: =IF($E17<>"power_cabinet",0,IFERROR(INDEX(SPEC_MAXDISP,MATCH($C17,SPEC_SKU,0)),0)) | P17: =IF($L17="",0,IFERROR(INDEX(PriceBook!$D$2:$D$203,MATCH($L17,PriceBook!$B$2:$B$203,0)),0)) | Q17: =IF(OR($E17="all_in_one",$E17="power_cabinet",$E17="level_2"),N($I17),0) | R17: =IF(N($Q17)=0,"",SUM($Q$7:$Q17)-N($Q17)+1) | S17: =SUM($Q$7:$Q17) | T17: =IF($E17="power_cabinet",N($I17)*N($N17),0) | U17: =IF(N($T17)=0,"",SUM($T$7:$T17)-N($T17)+1) | V17: =SUM($T$7:$T17)
A18: 12 | D18: =IFERROR(INDEX(PriceBook!$C$2:$C$203,MATCH($C18,PriceBook!$B$2:$B$203,0)),"") | E18: =IF($C18="","",IFERROR(INDEX(ROLE_VAL,MATCH($C18,ROLE_SKU,0)),"all_in_one")) | F18: =IF($C18="",0,IFERROR(INDEX(SPEC_DCKW,MATCH($C18,SPEC_SKU,0)),IF($E18="dispenser",0,IF($E18="accessory",0,IFERROR(IF(N(INDEX(PriceBook!$E$2:$E$203,MATCH($C18,PriceBook!$B$2:$B$203,0)))>0,INDEX(PriceBook!$E$2:$E$203,MATCH($C18,PriceBook!$B$2:$B$203,0)),INDEX(RATED_KW,MATCH($B18,CAPACITY_LIST,0))*IF(INDEX(PER_PORT,MATCH($B18,CAPACITY_LIST,0))=1,MAX(1,N($H18)),1)),0))))) | G18: =IF($C18="",0,IFERROR(INDEX(SPEC_ACKW,MATCH($C18,SPEC_SKU,0)),$F18)*IF(AND($E18="level_2",N($B$30)>0,$B$30<240),$B$30/240,1)) | H18: =IF($C18="",0,IF($E18="power_cabinet",N($N18)*N($O18),IFERROR(INDEX(SPEC_OUTS,MATCH($C18,SPEC_SKU,0)),IFERROR(INDEX(SKU_CONN,MATCH($C18,SKU_ALL,0)),0)))) | K18: =IFERROR(INDEX(PriceBook!$D$2:$D$203,MATCH($C18,PriceBook!$B$2:$B$203,0)),0) | M18: =IF($E18<>"power_cabinet",0,IFERROR(INDEX(SPEC_MAXDISP,MATCH($C18,SPEC_SKU,0)),0)) | P18: =IF($L18="",0,IFERROR(INDEX(PriceBook!$D$2:$D$203,MATCH($L18,PriceBook!$B$2:$B$203,0)),0)) | Q18: =IF(OR($E18="all_in_one",$E18="power_cabinet",$E18="level_2"),N($I18),0) | R18: =IF(N($Q18)=0,"",SUM($Q$7:$Q18)-N($Q18)+1) | S18: =SUM($Q$7:$Q18) | T18: =IF($E18="power_cabinet",N($I18)*N($N18),0) | U18: =IF(N($T18)=0,"",SUM($T$7:$T18)-N($T18)+1) | V18: =SUM($T$7:$T18)
A20: Charging units (excludes accessories) | B20: =SUMPRODUCT(--($H$7:$H$18>0),$I$7:$I$18) | C20: Units a driver plugs into — dispensers, all-in-one chargers and Level 2. A power cabinet has no connectors and is not one.
A21: AC-connected units — cabinets and all-in-ones | B21: =SUMPRODUCT(($E$7:$E$18="power_cabinet")+($E$7:$E$18="all_in_one"),$I$7:$I$18) | C21: Each of these needs its own AC run from the switchgear, and a placement distance on the Electrical tab.
A22: Total ports | B22: =SUMPRODUCT($H$7:$H$18,$I$7:$I$18) | C22: Connectors x units. The EVOLV billing basis. Dispensers carry the ports on a distributed system; the cabinet carries none.
A23: Total connected load (kW) | B23: =SUMPRODUCT(($E$7:$E$18="power_cabinet")+($E$7:$E$18="all_in_one")+($E$7:$E$18="level_2"),$G$7:$G$18,$I$7:$I$18) | C23: AC input, which is what the switchgear sees — a 480 kW cabinet draws 524 kW. Dispensers add nothing: their power comes from the cabinet, not the switchgear.
A24: Equipment MSRP total | B24: =SUMPRODUCT($I$7:$I$18,$K$7:$K$18)+SUMPRODUCT($I$7:$I$18,$N$7:$N$18,$P$7:$P$18) | C24: Catalogue SKUs at their price-book price, plus any dispensers priced by hand on the cabinet row.
A25: Equipment after discount | B25: =$B$24*(1-Commercial!$B$5) | C25: Sales tax is computed on THIS, not on MSRP. The discount is the one on the Commercial tab — there is no per-line discount any more.
A26: of which DC fast-charging capacity (kW) | B26: =SUMPRODUCT(($E$7:$E$18="power_cabinet")+($E$7:$E$18="all_in_one"),$F$7:$F$18,$I$7:$I$18) | C26: DC output. The LCFS credit basis. Counted once, at the cabinet — never again at the dispenser.
A27: Scope of work sentence (one line, must match the rows above)
B29: Write it from the table, e.g. "Installation of (4) 360 kW dual-port DC fast chargers — 8 charging positions".
A30: Level 2 supply voltage (V) | C30: The voltage the Level 2 units are actually fed at — 208 on a 208Y/120 service, 240 on a split-phase or 240 V panel, and usually 208 from a step-down panel on a 480 V site. A 32 A unit rated 7.2 kW at 240 V delivers 6.66 kW at 208 V, and the AC input column above derates to this figure. Leave blank and the schedule shows nameplate; the check below says so when that is not safe.
A32: Distributed system — do the dispensers fit the cabinets?
A33: Only relevant when a power cabinet is on the schedule. A cabinet feeds a limited number of DC outputs; each dual dispenser consumes two of them. Every dispenser also needs a DC run back to its cabinet — schedule those on the Electrical tab.
A34: Power cabinets on site | B34: =SUMPRODUCT(--($E$7:$E$18="power_cabinet"),$I$7:$I$18)
A35: Dispensers those cabinets can take | B35: =SUMPRODUCT($M$7:$M$18,$I$7:$I$18) | C35: From the architecture table: a 480 kW cabinet takes up to 3 dual dispensers, a 1.28 MW up to 8.
A36: Dispensers on the cabinet rows | B36: =SUMPRODUCT(--($E$7:$E$18="power_cabinet"),$N$7:$N$18,$I$7:$I$18) | C36: Dispensers per cabinet x the number of cabinets. This is now the only way a dispenser is entered.
A37: Dispensers entered on a line of their own | B37: =SUMPRODUCT(--($E$7:$E$18="dispenser"),$I$7:$I$18) | C37: Should always be zero. A dispenser belongs on its cabinet row, not on a line of its own.
A38: Dispensers in total | B38: =$B$36+$B$37
A39: Connectors those dispensers carry | B39: =SUMPRODUCT(--($E$7:$E$18="power_cabinet"),$H$7:$H$18,$I$7:$I$18)
A40: DISTRIBUTED SYSTEM CHECK | B40: =IF(AND($B$34=0,$B$38=0),"n/a — no distributed system on this schedule",IF($B$34=0,"ERROR — DISPENSERS WITHOUT A POWER CABINET. A dispenser has no power of its own.",IF($B$38=0,"ERROR — POWER CABINET WITHOUT DISPENSERS. A cabinet has no connectors and cannot charge a vehicle on its own. Enter the dispensers in the last column of the table.",IF($B$38>$B$35,"ERROR — TOO MANY DISPENSERS. "&TEXT($B$38,"0")&" entered against a limit of "&TEXT($B$35,"0")&" for the cabinets on this schedule.","OK — "&TEXT($B$38,"0")&" dispenser(s) on "&TEXT($B$34,"0")&" cabinet(s), "&TEXT($B$35-$B$38,"0")&" more allowed, "&TEXT($B$39,"0")&" connectors"))))
A41: Dispenser value at list | B41: =SUMPRODUCT($I$7:$I$18,$N$7:$N$18,$P$7:$P$18) | C41: Dispensers x their price-book price. Included in the two equipment totals above.
A42: Is a dispenser SKU picked where dispensers are scheduled? | B42: {=IF(SUMPRODUCT(($E$7:$E$18="power_cabinet")*N($N$7:$N$18))=0,"n/a — no dispensers scheduled",IF(SUMPRODUCT((N($N$7:$N$18)>0)*($L$7:$L$18=""))>0,"ERROR — dispensers are scheduled on a cabinet row with no dispenser SKU picked, so they are costing this project nothing. Pick one from the dropdown.",IF(SUMPRODUCT((N($N$7:$N$18)>0)*(N($O$7:$O$18)=0))>0,"ERROR — dispensers are scheduled with no connectors-per-dispenser picked, so the site shows no charging positions. Pick 1 or 2.","OK — "&TEXT(SUMPRODUCT(N($I$7:$I$18),N($N$7:$N$18)),"0")&" dispenser(s) at their price-book price")))}
A43: Any dispenser on a line of its own? | B43: =IF(AND(SUMPRODUCT(--($E$7:$E$18="dispenser"),$I$7:$I$18)>0,$B$36>0),"ERROR — dispensers are entered BOTH on their own line and as a count on a cabinet row. Pick one route: the totals add them together and double-count ports and price.",IF(SUMPRODUCT(--($E$7:$E$18="dispenser"),$I$7:$I$18)>0,"OK — dispensers are on their own lines, priced from the price book","OK — no dispenser is on a line of its own")) | C43: It used to fire whenever a dispenser was on its own line at all, which is a legitimate entry now the dispenser SKU is in the price book. The thing that is actually wrong is using both routes, because the totals sum them.
A44: Level 2 units rated at their supply voltage? | B44: =IF(SUMPRODUCT(($E$7:$E$18="level_2")*$I$7:$I$18)=0,"n/a — no Level 2 on the schedule",IF(N($B$30)>0,"OK — Level 2 AC input derated to "&TEXT($B$30,"0")&" V ("&TEXT(MIN(1,$B$30/240),"0%")&" of the 240 V nameplate)",IF(N(Project!$B$29)<240,"ENTER IT — the service is "&TEXT(Project!$B$29,"0")&" V and a 240 V-rated unit delivers "&TEXT(Project!$B$29/240,"0%")&" of nameplate at that voltage; the schedule above is at nameplate until the Level 2 supply voltage is stated","OK — service at or above 240 V; state the Level 2 supply voltage if it is fed from a step-down panel")))
A46: ENTRY CHECKS — what a wrong entry looks like
...

Sheet Electrical
A1: 3 · SITE AND ELECTRICAL
A2: Distances and materials. This tab drives the largest single cost in the project — and it is built for you: the chargers are listed from the Equipment tab, you type the distances.
A3: HOW TO FILL THIS TAB. Three entries and the tab does the rest. (1) Block B lists every charger from the Equipment tab — type the DISTANCE from the switchgear or panel to each one; the conductor, breaker, ground, conduit and cost are sized and priced for you, with a verdict on every row. A Level 2 dual pedestal is two units on one circuit: give both the same circuit name in column E and the distance on the first. (2) Block C is for DISPENSERS, which exist only on a power-cabinet system; on any other site it reads NOT USED and is left alone. (3) Block D wants the switchgear frame you are quoting and block E the boards, panels and transformers between the service and the chargers. Override a conductor or a conduit only when the drawings say so. (4) If the schedule in block E has panels, transformers or remote disconnects, block I at the foot of the tab prices the feeders between them — one row each, FROM and TO picked from the schedule, distance typed.
A5: A · SIZING BASIS — materials and the conductor design
A6: Feeder conductor material | B6: Cu | C6: Cu or Al
A7: Conduit type | B7: PVC | C7: PVC or EMT
A8: Trench surface | B8: Mixed | C8: Asphalt / concrete / landscape / mixed
A9: Trench depth (in) | B9: 24 | C9: Sets the trench width used for the restoration figure (width = depth / 12 in feet).
A10: Design ambient (C) | C10: SITE DATA, no house default: the ASHRAE 2% design dry-bulb for the location, or the duct-bank temperature if the runs are buried. NEC 310.15(B)(1) corrects every ampacity on this tab from it — leave it blank and every verdict says so.
A11: Conductor insulation rating (C) | B11: 90 | C11: What the wire is rated for. THHN/XHHW-2 is 90 C. The ambient correction is applied to this column.
A12: Termination rating (C) | B12: 75 | C12: NEC 110.14(C). The corrected ampacity is capped here. 60 C lugs on the gear or the charger change every size on this tab.
A13: Allowable voltage drop (%) | B13: 0.03 | C13: NEC treats voltage drop as an informational note, not a requirement. On a long run it is usually what decides the size, and the auto-sizing honours it.
A15: B · CHARGER RUNS — switchgear or panel to every charger, built from the Equipment tab
A16: One row per charger unit — a standalone DC charger, a power cabinet or a Level 2 unit — listed in the order of the Equipment tab. Rows beyond the schedule stay blank. Type the DISTANCE (column F). Everything else is derived: the supply from the Project and Equipment tabs, the breaker from NEC 210/215 at 125%, the conductor from the corrected ampacity AND the voltage-drop allowance (block H shows the table), the ground from NEC 250.122, the conduit from RefData, the cost at RefData rates. A DC run carries a comms conduit; a Level 2 unit does not (it has its own modem). Overrides (L, M, R) are for the drawings; the verdict says when one is needed.
A17: Charger (auto) | B17: Equipment (auto) | C17: Supply (auto) | D17: kW (auto) | E17: Circuit (blank = own; same name = shared) | F17: Distance (ft) | G17: Shares a trench? (Yes) | H17: Design A (auto) | I17: 125% A (auto) | J17: Breaker A (auto) | K17: Conductor (auto) | L17: Conductor override | M17: Sets (blank = auto) | N17: Ampacity A (auto) | O17: Volt drop (auto) | P17: Ground (auto) | Q17: Conduit (auto) | R17: Conduit override | S17: Material $ (auto) | T17: Verdict (auto) | U17: Needs dist. (auto) | V17: Stream (auto) | W17: Line (auto) | X17: Sets in force (auto)
A18: =IF($W18="","","Charger 1") | B18: =IF($W18="","","Line "&$W18&" · "&INDEX(Equipment!$C$7:$C$18,$W18)&" · "&INDEX(Equipment!$B$7:$B$18,$W18)&" · #"&(1-INDEX(Equipment!$R$7:$R$18,$W18)+1)&" of "&INDEX(Equipment!$I$7:$I$18,$W18)) | C18: =IF($W18="","",IF($V18="L2",TEXT(N(Equipment!$B$30),"0")&" V 1-ph",TEXT(Project!$B$29,"0")&" V 3-ph")) | D18: =IF($W18="","",INDEX(Equipment!$G$7:$G$18,$W18)) | H18: =IF($U18<>1,"",IF($E18="",N($D18),SUMIF($E$18:$E$77,$E18,$D$18:$D$77))*1000/(IF($V18="L2",N(Equipment!$B$30),Project!$B$29)*IF($V18="L2",1,SQRT(3)))) | I18: =IF(N($H18)=0,"",N($H18)*1.25) | J18: =IF(N($I18)=0,"",IF(ISNUMBER(MATCH($I18,OCPD_LIST,0)),$I18,IF($I18>MAX(OCPD_LIST),"ABOVE LIST",INDEX(OCPD_LIST,MATCH($I18,OCPD_LIST,1)+1)))) | K18: =IF(OR(N($I18)=0,$B$10=""),"",IF(MAX(COUNTIF(SZ_AMP,"<"&(IF(N($J18)>800,N($J18),N($I18))/IF(N($M18)>0,N($M18),MAX(1,N(IFERROR(INDEX(SPEC_CIRC,MATCH(INDEX(Equipment!$C$7:$C$18,MAX(1,N($W18))),SPEC_SKU,0)),1))))))+1,IF(N($F18)=0,1,COUNTIF(SZ_Z,">"&($B$13*IF($V18="L2",N(Equipment!$B$30),Project!$B$29)*1000/(IF($V18="L2",2,SQRT(3))*N($H18)/IF(N($M18)>0,N($M18),MAX(1,N(IFERROR(INDEX(SPEC_CIRC,MATCH(INDEX(Equipment!$C$7:$C$18,MAX(1,N($W18))),SPEC_SKU,0)),1))))*N($F18))))+1))>ROWS(SZ_SIZE),"PARALLEL SETS",INDEX(SZ_SIZE,MAX(COUNTIF(SZ_AMP,"<"&(IF(N($J18)>800,N($J18),N($I18))/IF(N($M18)>0,N($M18),MAX(1,N(IFERROR(INDEX(SPEC_CIRC,MATCH(INDEX(Equipment!$C$7:$C$18,MAX(1,N($W18))),SPEC_SKU,0)),1))))))+1,IF(N($F18)=0,1,COUNTIF(SZ_Z,">"&($B$13*IF($V18="L2",N(Equipment!$B$30),Project!$B$29)*1000/(IF($V18="L2",2,SQRT(3))*N($H18)/IF(N($M18)>0,N($M18),MAX(1,N(IFERROR(INDEX(SPEC_CIRC,MATCH(INDEX(Equipment!$C$7:$C$18,MAX(1,N($W18))),SPEC_SKU,0)),1))))*N($F18))))+1))))) | N18: =IF(OR(IF($L18<>"",$L18,$K18)="",IF($L18<>"",$L18,$K18)="PARALLEL SETS"),"",IFERROR(INDEX(SZ_AMP,MATCH(IF($L18<>"",$L18,$K18),SZ_SIZE,0))*IF(N($M18)>0,N($M18),MAX(1,N(IFERROR(INDEX(SPEC_CIRC,MATCH(INDEX(Equipment!$C$7:$C$18,MAX(1,N($W18))),SPEC_SKU,0)),1)))),"")) | O18: =IF(OR(N($N18)=0,N($F18)=0),"",IFERROR(IF($V18="L2",2,SQRT(3))*N($H18)/IF(N($M18)>0,N($M18),MAX(1,N(IFERROR(INDEX(SPEC_CIRC,MATCH(INDEX(Equipment!$C$7:$C$18,MAX(1,N($W18))),SPEC_SKU,0)),1))))*N($F18)*INDEX(SZ_Z,MATCH(IF($L18<>"",$L18,$K18),SZ_SIZE,0))/1000/IF($V18="L2",N(Equipment!$B$30),Project!$B$29),"")) | P18: =IF(N($J18)=0,"",IFERROR(INDEX(IF($B$6="Cu",EGC_CU,EGC_AL),MATCH($J18,EGC_OCPD,1)+IF(ISNUMBER(MATCH($J18,EGC_OCPD,0)),0,1)),"")) | Q18: =IF(N($N18)=0,"",IFERROR(INDEX(IF($V18="L2",CND_2G,CND_3G),MATCH(IF($L18<>"",$L18,$K18),CND_SIZE,0)),"")) | S18: =IF(OR(N($F18)=0,N($N18)=0),0,IFERROR(N($F18)*IF(N($M18)>0,N($M18),MAX(1,N(IFERROR(INDEX(SPEC_CIRC,MATCH(INDEX(Equipment!$C$7:$C$18,MAX(1,N($W18))),SPEC_SKU,0)),1))))*IF($V18="L2",2,3)*INDEX(IF($B$6="Cu",WIRE_CU,WIRE_AL),MATCH(IF($L18<>"",$L18,$K18),WIRE_SIZE,0)),0)+IFERROR(N($F18)*IF(N($M18)>0,N($M18),MAX(1,N(IFERROR(INDEX(SPEC_CIRC,MATCH(INDEX(Equipment!$C$7:$C$18,MAX(1,N($W18))),SPEC_SKU,0)),1))))*INDEX(IF($B$6="Cu",WIRE_CU,WIRE_AL),MATCH($P18,WIRE_SIZE,0)),0)+IFERROR(N($F18)*IF(N($M18)>0,N($M18),MAX(1,N(IFERROR(INDEX(SPEC_CIRC,MATCH(INDEX(Equipment!$C$7:$C$18,MAX(1,N($W18))),SPEC_SKU,0)),1))))*INDEX(PVC_RATE,MATCH(IF($R18<>"",$R18,$Q18),PVC_SIZE,0)),0)+IF($V18="L2",0,IFERROR(N($F18)*INDEX(PVC_RATE,MATCH("(3/4"")",PVC_SIZE,0)),0))) | T18: =IF($W18="","",IF($U18=0,"shared — on circuit "&$E18&", sized and priced on its first unit",IF(N($F18)=0,"ENTER THE DISTANCE",IF($B$10="","SET THE DESIGN AMBIENT in block A — nothing on this row can be trusted until it is",IF(IF($L18<>"",$L18,$K18)="PARALLEL SETS","PARALLEL SETS NEEDED — no single conductor carries "&TEXT(N($I18),"#,##0")&" A within the drop allowance; enter sets in column M",IF(N($N18)=0,"no ampacity on file for the override size — NEC Table 310.16 does not list it",IF(N($N18)<IF(N($J18)>800,N($J18),N($I18)),"UNDERSIZED — "&TEXT(N($N18),"#,##0")&" A provided against a floor of "&TEXT(IF(N($J18)>800,N($J18),N($I18)),"#,##0")&" A",IF(N($O18)>$B$13,"ampacity OK but voltage drop "&TEXT(N($O18),"0.0%")&" exceeds the allowance — ADVISORY, upsize the override","OK — "&IF(IF(N($M18)>0,N($M18),MAX(1,N(IFERROR(INDEX(SPEC_CIRC,MATCH(INDEX(Equipment!$C$7:$C$18,MAX(1,N($W18))),SPEC_SKU,0)),1))))>1,TEXT(IF(N($M18)>0,N($M18),MAX(1,N(IFERROR(INDEX(SPEC_CIRC,MATCH(INDEX(Equipment!$C$7:$C$18,MAX(1,N($W18))),SPEC_SKU,0)),1)))),"0")&" sets of ","")&IF($L18<>"",$L18,$K18)&IF($L18<>""," (override)","")&", "&TEXT(N($N18),"#,##0")&" A against a "&TEXT(IF(N($J18)>800,N($J18),N($I18)),"#,##0")&" A floor; drop "&TEXT(N($O18),"0.0%")&" (ADVISORY)")))))))) | U18: =IF($W18="",0,IF($E18="",1,IF(MATCH($E18,$E$18:$E$77,0)=1,1,0))) | V18: =IF($W18="","",IF(INDEX(Equipment!$E$7:$E$18,$W18)="level_2","L2",IF(INDEX(Equipment!$E$7:$E$18,$W18)="power_cabinet","CAB","DC"))) | W18: =IF(N($B$80)>=1,COUNTIF(Equipment!$S$7:$S$18,"<1")+1,"") | X18: =IF($U18<>1,"",IF(N($M18)>0,N($M18),MAX(1,N(IFERROR(INDEX(SPEC_CIRC,MATCH(INDEX(Equipment!$C$7:$C$18,MAX(1,N($W18))),SPEC_SKU,0)),1)))))
