Workbook
Name ModelTable: RateCard!$A$4:$K$19
Name SgSizes: RateCard!$A$24:$A$33
Name SgTable: RateCard!$A$24:$B$33
Name PnlSizes: RateCard!$A$37:$A$42
Name PnlTable: RateCard!$A$37:$B$42
Name TxSizes: RateCard!$A$46:$A$52
Name TxTable: RateCard!$A$46:$B$52
Name Brk480Sizes: RateCard!$A$56:$A$67
Name BrkTbl480: RateCard!$A$56:$B$67
Name Brk208Sizes: RateCard!$A$71:$A$73
Name BrkTbl208: RateCard!$A$71:$B$73
Name StdBrk: RateCard!$A$76:$A$111
Name TerrainTable: RateCard!$L$4:$P$7
Name TrenchRate: RateCard!$M$10
Name ContingencyPct: RateCard!$M$11
Name TaxPct: RateCard!$M$12
Name LaborDayRate: RateCard!$M$13
Name PmRate: RateCard!$M$14
Name CpmPct: RateCard!$M$15
Name GprDayRate: RateCard!$M$16
Name GprFtPerDay: RateCard!$M$17
Name AdaVanCost: RateCard!$M$18
Name AdaStdCost: RateCard!$M$19
Name AdaAmbCost: RateCard!$M$20
Name AdaRampCost: RateCard!$M$21
Name CivilBase: RateCard!$M$22
Name CivilDcfc: RateCard!$M$23
Name CivilL2: RateCard!$M$24
Name SignageDcfc: RateCard!$M$25
Name SignageL2: RateCard!$M$26
Name TransformerPad: RateCard!$M$27
Name CommDcfc: RateCard!$M$28
Name CommL2: RateCard!$M$29
Name EquipBase: RateCard!$M$30
Name EquipPerDay: RateCard!$M$31
Name NTotal: Intake!$B$30
Name NDcfc: Intake!$B$31
Name NumL2: Intake!$B$32
Name NPorts: Intake!$B$33
Name FirstRunFt: Intake!$B$36
Name StepFt: Intake!$B$37
Name Terrain: Intake!$B$38
Name TrenchFt: Intake!$B$39
Name IncHardware: Intake!$B$42
Name IncSitePlan: Intake!$B$43
Name IncSLD: Intake!$B$44
Name IncCpm: Intake!$B$45
Name IncPermits: Intake!$B$46
Name IncGpr: Intake!$B$47
Name HardwareFactor: Intake!$B$50
Name RebateAmt: Intake!$B$51
Name NetworkFeeMo: Intake!$B$52
Name ContractYears: Intake!$B$53
Name ServicePlanYr: Intake!$B$54
Name FinanceApr: Intake!$B$55
Name FinanceYears: Intake!$B$56
Name SgSuggested: Panel!$F$15
Name TxKvaConnected: Panel!$F$33
Name TxKvaSuggested: Panel!$F$35
Name GearTotal: Panel!$F$51

Sheet Intake
A1: RFC INTAKE — EV Charging Project
A2: Fill the yellow cells only — Panel, Estimate, Revenue, Financing, ADA and Timeline calculate from them.
A4: OUR DETAILS
A5: Company
A6: Prepared by (CPM)
A7: CRA
A8: Phone
A9: Email
A11: PROJECT
A12: Client
A13: Site address
A14: City / AHJ
... A17: Application / project ID
A18: Date | B18: =TODAY()
A19: Scope of work
A21: CHARGERS
A22: Model | B22: Qty | C22: Hardware $/u | D22: Category | E22: Make-ready $ | F22: Hardware $ | G22: Ports
A23: DCFC 200kW | B23: 6 | C23: =IFERROR(VLOOKUP($A23,ModelTable,2,FALSE),"") | D23: =IFERROR(VLOOKUP($A23,ModelTable,4,FALSE),"") | E23: =IFERROR($B23*VLOOKUP($A23,ModelTable,3,FALSE),0) | F23: =IFERROR($B23*VLOOKUP($A23,ModelTable,2,FALSE),0) | G23: =IFERROR($B23*VLOOKUP($A23,ModelTable,9,FALSE),0)
A24: L2 Single 40A | B24: 5 | C24: =IFERROR(VLOOKUP($A24,ModelTable,2,FALSE),"") | D24: =IFERROR(VLOOKUP($A24,ModelTable,4,FALSE),"") | E24: =IFERROR($B24*VLOOKUP($A24,ModelTable,3,FALSE),0) | F24: =IFERROR($B24*VLOOKUP($A24,ModelTable,2,FALSE),0) | G24: =IFERROR($B24*VLOOKUP($A24,ModelTable,9,FALSE),0)
C25: =IFERROR(VLOOKUP($A25,ModelTable,2,FALSE),"") | D25: =IFERROR(VLOOKUP($A25,ModelTable,4,FALSE),"") | E25: =IFERROR($B25*VLOOKUP($A25,ModelTable,3,FALSE),0) | F25: =IFERROR($B25*VLOOKUP($A25,ModelTable,2,FALSE),0) | G25: =IFERROR($B25*VLOOKUP($A25,ModelTable,9,FALSE),0)
C26: =IFERROR(VLOOKUP($A26,ModelTable,2,FALSE),"") | D26: =IFERROR(VLOOKUP($A26,ModelTable,4,FALSE),"") | E26: =IFERROR($B26*VLOOKUP($A26,ModelTable,3,FALSE),0) | F26: =IFERROR($B26*VLOOKUP($A26,ModelTable,2,FALSE),0) | G26: =IFERROR($B26*VLOOKUP($A26,ModelTable,9,FALSE),0)
C27: =IFERROR(VLOOKUP($A27,ModelTable,2,FALSE),"") | D27: =IFERROR(VLOOKUP($A27,ModelTable,4,FALSE),"") | E27: =IFERROR($B27*VLOOKUP($A27,ModelTable,3,FALSE),0) | F27: =IFERROR($B27*VLOOKUP($A27,ModelTable,2,FALSE),0) | G27: =IFERROR($B27*VLOOKUP($A27,ModelTable,9,FALSE),0)
C28: =IFERROR(VLOOKUP($A28,ModelTable,2,FALSE),"") | D28: =IFERROR(VLOOKUP($A28,ModelTable,4,FALSE),"") | E28: =IFERROR($B28*VLOOKUP($A28,ModelTable,3,FALSE),0) | F28: =IFERROR($B28*VLOOKUP($A28,ModelTable,2,FALSE),0) | G28: =IFERROR($B28*VLOOKUP($A28,ModelTable,9,FALSE),0)
A30: Total chargers | B30: =SUM(B23:B28)
A31: DCFC count | B31: =SUMPRODUCT((D23:D28="DCFC")*B23:B28)
A32: L2 count | B32: =SUMPRODUCT((D23:D28="L2")*B23:B28)
A33: Total ports | B33: =SUM(G23:G28)
A35: SITE
A36: Distance to nearest charger (ft) | B36: 100
A37: Spacing per extra charger (ft) | B37: 15
A38: Terrain | B38: flat
A39: Trench length (ft) — overtype if surveyed | B39: =B36+B37*MAX(0,NTotal-1)
A41: INCLUDED SERVICES (Yes / No)
A42: Charger hardware | B42: Yes
A43: Site plan design (AutoCAD) | B43: Yes
A44: SLD / electrical design | B44: Yes
A45: Construction PM (CPM) | B45: Yes
A46: Permitting fees | B46: Yes
A47: Private utility scan (GPR) | B47: Yes
A49: COMMERCIAL TERMS (from the RFC_V18 / Hoopa proposal structure)
...

Sheet Panel
A1: Panel Schedules — auto from Intake (mirrors the app's algorithm, NEC 625 continuous loads at 125%)
A3: PANEL SCHEDULE 1 — 480V SWITCHGEAR (LEVEL 3 / DCFC)
A4: Model | B4: Qty | C4: Breaker A | D4: Circuits | E4: A per circuit | F4: Connected A
A5: =IF(Intake!$D23="DCFC",Intake!$A23,"") | B5: =IF(Intake!$D23="DCFC",Intake!$B23,0) | C5: =IF(B5>0,VLOOKUP(Intake!$A23,ModelTable,6,FALSE),"") | D5: =IF(B5>0,B5*VLOOKUP(Intake!$A23,ModelTable,7,FALSE),0) | E5: =IF(B5>0,VLOOKUP(Intake!$A23,ModelTable,8,FALSE),"") | F5: =IF(B5>0,B5*VLOOKUP(Intake!$A23,ModelTable,8,FALSE),0)
A6: =IF(Intake!$D24="DCFC",Intake!$A24,"") | B6: =IF(Intake!$D24="DCFC",Intake!$B24,0) | C6: =IF(B6>0,VLOOKUP(Intake!$A24,ModelTable,6,FALSE),"") | D6: =IF(B6>0,B6*VLOOKUP(Intake!$A24,ModelTable,7,FALSE),0) | E6: =IF(B6>0,VLOOKUP(Intake!$A24,ModelTable,8,FALSE),"") | F6: =IF(B6>0,B6*VLOOKUP(Intake!$A24,ModelTable,8,FALSE),0)
A7: =IF(Intake!$D25="DCFC",Intake!$A25,"") | B7: =IF(Intake!$D25="DCFC",Intake!$B25,0) | C7: =IF(B7>0,VLOOKUP(Intake!$A25,ModelTable,6,FALSE),"") | D7: =IF(B7>0,B7*VLOOKUP(Intake!$A25,ModelTable,7,FALSE),0) | E7: =IF(B7>0,VLOOKUP(Intake!$A25,ModelTable,8,FALSE),"") | F7: =IF(B7>0,B7*VLOOKUP(Intake!$A25,ModelTable,8,FALSE),0)
A8: =IF(Intake!$D26="DCFC",Intake!$A26,"") | B8: =IF(Intake!$D26="DCFC",Intake!$B26,0) | C8: =IF(B8>0,VLOOKUP(Intake!$A26,ModelTable,6,FALSE),"") | D8: =IF(B8>0,B8*VLOOKUP(Intake!$A26,ModelTable,7,FALSE),0) | E8: =IF(B8>0,VLOOKUP(Intake!$A26,ModelTable,8,FALSE),"") | F8: =IF(B8>0,B8*VLOOKUP(Intake!$A26,ModelTable,8,FALSE),0)
A9: =IF(Intake!$D27="DCFC",Intake!$A27,"") | B9: =IF(Intake!$D27="DCFC",Intake!$B27,0) | C9: =IF(B9>0,VLOOKUP(Intake!$A27,ModelTable,6,FALSE),"") | D9: =IF(B9>0,B9*VLOOKUP(Intake!$A27,ModelTable,7,FALSE),0) | E9: =IF(B9>0,VLOOKUP(Intake!$A27,ModelTable,8,FALSE),"") | F9: =IF(B9>0,B9*VLOOKUP(Intake!$A27,ModelTable,8,FALSE),0)
A10: =IF(Intake!$D28="DCFC",Intake!$A28,"") | B10: =IF(Intake!$D28="DCFC",Intake!$B28,0) | C10: =IF(B10>0,VLOOKUP(Intake!$A28,ModelTable,6,FALSE),"") | D10: =IF(B10>0,B10*VLOOKUP(Intake!$A28,ModelTable,7,FALSE),0) | E10: =IF(B10>0,VLOOKUP(Intake!$A28,ModelTable,8,FALSE),"") | F10: =IF(B10>0,B10*VLOOKUP(Intake!$A28,ModelTable,8,FALSE),0)
A11: DCFC connected amps | F11: =SUM(F5:F10)
A12: + Transformer primary reflection (raw) | F12: =IF(AND(NDcfc>0,NumL2>0),TxKvaConnected*1000/(480*SQRT(3)),0)
A13: 480V bus connected amps | F13: =F11+F12
A14: 480V bus demand amps (×125%) | F14: =F13*1.25
A15: Suggested main switchgear (A) | F15: =IF(NDcfc>0,INDEX(SgSizes,MIN(ROWS(SgSizes),COUNTIF(SgSizes,"<"&F14)+1)),0)
A16: Switchgear price (website catalog) | F16: =IF(NDcfc>0,VLOOKUP(SgSuggested,SgTable,2,FALSE),0)
A18: PANEL SCHEDULE 2 — 208V PANEL (LEVEL 2)
A19: Model | B19: Qty | C19: Breaker A | D19: Circuits | E19: A per circuit | F19: Connected A
A20: =IF(Intake!$D23="L2",Intake!$A23,"") | B20: =IF(Intake!$D23="L2",Intake!$B23,0) | C20: =IF(B20>0,VLOOKUP(Intake!$A23,ModelTable,6,FALSE),"") | D20: =IF(B20>0,B20*VLOOKUP(Intake!$A23,ModelTable,7,FALSE),0) | E20: =IF(B20>0,VLOOKUP(Intake!$A23,ModelTable,8,FALSE),"") | F20: =IF(B20>0,B20*VLOOKUP(Intake!$A23,ModelTable,8,FALSE),0)
A21: =IF(Intake!$D24="L2",Intake!$A24,"") | B21: =IF(Intake!$D24="L2",Intake!$B24,0) | C21: =IF(B21>0,VLOOKUP(Intake!$A24,ModelTable,6,FALSE),"") | D21: =IF(B21>0,B21*VLOOKUP(Intake!$A24,ModelTable,7,FALSE),0) | E21: =IF(B21>0,VLOOKUP(Intake!$A24,ModelTable,8,FALSE),"") | F21: =IF(B21>0,B21*VLOOKUP(Intake!$A24,ModelTable,8,FALSE),0)
A22: =IF(Intake!$D25="L2",Intake!$A25,"") | B22: =IF(Intake!$D25="L2",Intake!$B25,0) | C22: =IF(B22>0,VLOOKUP(Intake!$A25,ModelTable,6,FALSE),"") | D22: =IF(B22>0,B22*VLOOKUP(Intake!$A25,ModelTable,7,FALSE),0) | E22: =IF(B22>0,VLOOKUP(Intake!$A25,ModelTable,8,FALSE),"") | F22: =IF(B22>0,B22*VLOOKUP(Intake!$A25,ModelTable,8,FALSE),0)
A23: =IF(Intake!$D26="L2",Intake!$A26,"") | B23: =IF(Intake!$D26="L2",Intake!$B26,0) | C23: =IF(B23>0,VLOOKUP(Intake!$A26,ModelTable,6,FALSE),"") | D23: =IF(B23>0,B23*VLOOKUP(Intake!$A26,ModelTable,7,FALSE),0) | E23: =IF(B23>0,VLOOKUP(Intake!$A26,ModelTable,8,FALSE),"") | F23: =IF(B23>0,B23*VLOOKUP(Intake!$A26,ModelTable,8,FALSE),0)
A24: =IF(Intake!$D27="L2",Intake!$A27,"") | B24: =IF(Intake!$D27="L2",Intake!$B27,0) | C24: =IF(B24>0,VLOOKUP(Intake!$A27,ModelTable,6,FALSE),"") | D24: =IF(B24>0,B24*VLOOKUP(Intake!$A27,ModelTable,7,FALSE),0) | E24: =IF(B24>0,VLOOKUP(Intake!$A27,ModelTable,8,FALSE),"") | F24: =IF(B24>0,B24*VLOOKUP(Intake!$A27,ModelTable,8,FALSE),0)
A25: =IF(Intake!$D28="L2",Intake!$A28,"") | B25: =IF(Intake!$D28="L2",Intake!$B28,0) | C25: =IF(B25>0,VLOOKUP(Intake!$A28,ModelTable,6,FALSE),"") | D25: =IF(B25>0,B25*VLOOKUP(Intake!$A28,ModelTable,7,FALSE),0) | E25: =IF(B25>0,VLOOKUP(Intake!$A28,ModelTable,8,FALSE),"") | F25: =IF(B25>0,B25*VLOOKUP(Intake!$A28,ModelTable,8,FALSE),0)
A26: 208V bus connected amps | F26: =SUM(F20:F25)
A27: 208V bus demand amps (×125%) | F27: =F26*1.25
A28: Suggested 208V panel (A) | F28: =IF(NumL2>0,INDEX(PnlSizes,MIN(ROWS(PnlSizes),COUNTIF(PnlSizes,"<"&F27)+1)),0)
A29: Panel type | F29: =IF(NumL2=0,"—",IF(F28>=1000,"Distribution panel","Sub-panel"))
A30: Panel price | F30: =IF(NumL2>0,VLOOKUP(F28,PnlTable,2,FALSE),0)
A32: STEP-DOWN TRANSFORMER (480V → 208V, only when both levels exist)
A33: Connected kVA (208V load) | F33: =IF(AND(NDcfc>0,NumL2>0),F26*208*SQRT(3)/1000,0)
A34: Demand kVA (×125%) | F34: =F33*1.25
A35: Suggested transformer (kVA) | F35: =IF(F33>0,INDEX(TxSizes,MIN(ROWS(TxSizes),COUNTIF(TxSizes,"<"&F34)+1)),0)
A36: Transformer price | F36: =IF(F35>0,VLOOKUP(F35,TxTable,2,FALSE),0)
A37: Primary FLA at 480V (selected TX) | F37: =IF(F35>0,F35*1000/(480*SQRT(3)),0)
A38: Primary breaker (125% of FLA, next standard) | F38: =IF(F35>0,INDEX(StdBrk,MIN(ROWS(StdBrk),COUNTIF(StdBrk,"<"&F37*1.25)+1)),0)
A39: Primary breaker price | F39: =IF(F38>0,IFERROR(VLOOKUP(F38,BrkTbl480,2,FALSE),0),0)
A41: BRANCH BREAKERS
A42: Model | B42: Breaker A | C42: Voltage | D42: Circuits | E42: Unit $ | F42: Total $
A43: =IF(Intake!$B23>0,Intake!$A23,"") | B43: =IF(Intake!$B23>0,VLOOKUP(Intake!$A23,ModelTable,6,FALSE),"") | C43: =IF(Intake!$B23>0,VLOOKUP(Intake!$A23,ModelTable,5,FALSE),"") | D43: =IF(Intake!$B23>0,Intake!$B23*VLOOKUP(Intake!$A23,ModelTable,7,FALSE),0) | E43: =IF(D43>0,IF(C43=480,IFERROR(VLOOKUP(B43,BrkTbl480,2,FALSE),0),IFERROR(VLOOKUP(B43,BrkTbl208,2,FALSE),0)),0) | F43: =D43*E43
A44: =IF(Intake!$B24>0,Intake!$A24,"") | B44: =IF(Intake!$B24>0,VLOOKUP(Intake!$A24,ModelTable,6,FALSE),"") | C44: =IF(Intake!$B24>0,VLOOKUP(Intake!$A24,ModelTable,5,FALSE),"") | D44: =IF(Intake!$B24>0,Intake!$B24*VLOOKUP(Intake!$A24,ModelTable,7,FALSE),0) | E44: =IF(D44>0,IF(C44=480,IFERROR(VLOOKUP(B44,BrkTbl480,2,FALSE),0),IFERROR(VLOOKUP(B44,BrkTbl208,2,FALSE),0)),0) | F44: =D44*E44
...

Sheet Panel 480V
B1: PANEL SCHEDULE
R2: engine — do not edit
B3: NAME | C3: EV_MAIN | D3: LOCATION | E3: OUTDOOR | H3: VOLTAGE | I3: 277 / 480 3PH 4W | M3: MAIN | N3: =SgSuggested&" A 3P" | S3: =IF(Intake!$D$23="DCFC",Intake!$B$23*IFERROR(VLOOKUP(Intake!$A$23,ModelTable,7,FALSE),0),0) | T3: 0
D4: FED BY | E4: ="UTILITY" | H4: ENCLOSURE | I4: NEMA3R | M4: BUS BAR | N4: =SgSuggested&" A" | S4: =IF(Intake!$D$24="DCFC",Intake!$B$24*IFERROR(VLOOKUP(Intake!$A$24,ModelTable,7,FALSE),0),0) | T4: =T3+S3
D5: MOUNTING | E5: SURFACE | H5: PANEL TYPE | I5: NF | M5: MAIN AIC | N5: 65,000 | S5: =IF(Intake!$D$25="DCFC",Intake!$B$25*IFERROR(VLOOKUP(Intake!$A$25,ModelTable,7,FALSE),0),0) | T5: =T4+S4
S6: =IF(Intake!$D$26="DCFC",Intake!$B$26*IFERROR(VLOOKUP(Intake!$A$26,ModelTable,7,FALSE),0),0) | T6: =T5+S5
B7: CKT | C7: DESCRIPTION | D7: BREAKER | E7: POLES | F7: A | H7: B | J7: C | L7: POLES | M7: BREAKER | N7: DESCRIPTION | O7: CKT | S7: =IF(Intake!$D$27="DCFC",Intake!$B$27*IFERROR(VLOOKUP(Intake!$A$27,ModelTable,7,FALSE),0),0) | T7: =T6+S6
A8: A | B8: 1 | C8: =IF($AA$12=1,$X$12,"") | D8: =IF($AA$12=1,$Y$12,"") | E8: =IF($AA$12=1,3,"") | F8: =IF($AA$12=1,ROUND($Z$12,0),"") | G8: =IF($AA$13=1,ROUND($Z$13,0),"") | L8: =IF($AA$13=1,3,"") | M8: =IF($AA$13=1,$Y$13,"") | N8: =IF($AA$13=1,$X$13,"") | O8: 2 | P8: A | S8: =IF(Intake!$D$28="DCFC",Intake!$B$28*IFERROR(VLOOKUP(Intake!$A$28,ModelTable,7,FALSE),0),0) | T8: =T7+S7
A9: B | B9: 3 | C9: =IF($AA$12=1,"---","") | H9: =IF($AA$12=1,ROUND($Z$12,0),"") | I9: =IF($AA$13=1,ROUND($Z$13,0),"") | N9: =IF($AA$13=1,"---","") | O9: 4 | P9: B | R9: total circuits | S9: =SUM(S3:S8)
A10: C | B10: 5 | C10: =IF($AA$12=1,"---","") | J10: =IF($AA$12=1,ROUND($Z$12,0),"") | K10: =IF($AA$13=1,ROUND($Z$13,0),"") | N10: =IF($AA$13=1,"---","") | O10: 6 | P10: C
A11: A | B11: 7 | C11: =IF($AA$14=1,$X$14,"") | D11: =IF($AA$14=1,$Y$14,"") | E11: =IF($AA$14=1,3,"") | F11: =IF($AA$14=1,ROUND($Z$14,0),"") | G11: =IF($AA$15=1,ROUND($Z$15,0),"") | L11: =IF($AA$15=1,3,"") | M11: =IF($AA$15=1,$Y$15,"") | N11: =IF($AA$15=1,$X$15,"") | O11: 8 | P11: A
A12: B | B12: 9 | C12: =IF($AA$14=1,"---","") | H12: =IF($AA$14=1,ROUND($Z$14,0),"") | I12: =IF($AA$15=1,ROUND($Z$15,0),"") | N12: =IF($AA$15=1,"---","") | O12: 10 | P12: B | S12: 1 | T12: =IF(S12<=$S$9,MATCH(S12-0.5,$T$3:$T$8,1),0) | U12: =IF(T12>0,S12-INDEX($T$3:$T$8,T12),0) | V12: =IF(T12>0,INDEX(Intake!$A$23:$A$28,T12),"") | W12: =IF(T12>0,IFERROR(VLOOKUP(V12,ModelTable,7,FALSE),1),1) | X12: =IF(T12>0,UPPER(V12)&" #"&U12,IF(S12=$S$9+1,IF(TxKvaSuggested>0,"XFMR "&TxKvaSuggested&" KVA - EV_SUB (208V)",""),"")) | Y12: =IF(T12>0,IFERROR(VLOOKUP(V12,ModelTable,6,FALSE),0),IF(S12=$S$9+1,IF(TxKvaSuggested>0,Panel!$F$38,0),0)) | Z12: =IF(T12>0,IFERROR(VLOOKUP(V12,ModelTable,11,FALSE),0)*480/SQRT(3),IF(S12=$S$9+1,IF(TxKvaSuggested>0,TxKvaConnected*1000/3,0),0)) | AA12: =IF(S12<=$S$9,1,IF(S12=$S$9+1,IF(TxKvaSuggested>0,1,0),0))
A13: C | B13: 11 | C13: =IF($AA$14=1,"---","") | J13: =IF($AA$14=1,ROUND($Z$14,0),"") | K13: =IF($AA$15=1,ROUND($Z$15,0),"") | N13: =IF($AA$15=1,"---","") | O13: 12 | P13: C | S13: 2 | T13: =IF(S13<=$S$9,MATCH(S13-0.5,$T$3:$T$8,1),0) | U13: =IF(T13>0,S13-INDEX($T$3:$T$8,T13),0) | V13: =IF(T13>0,INDEX(Intake!$A$23:$A$28,T13),"") | W13: =IF(T13>0,IFERROR(VLOOKUP(V13,ModelTable,7,FALSE),1),1) | X13: =IF(T13>0,UPPER(V13)&" #"&U13,IF(S13=$S$9+1,IF(TxKvaSuggested>0,"XFMR "&TxKvaSuggested&" KVA - EV_SUB (208V)",""),"")) | Y13: =IF(T13>0,IFERROR(VLOOKUP(V13,ModelTable,6,FALSE),0),IF(S13=$S$9+1,IF(TxKvaSuggested>0,Panel!$F$38,0),0)) | Z13: =IF(T13>0,IFERROR(VLOOKUP(V13,ModelTable,11,FALSE),0)*480/SQRT(3),IF(S13=$S$9+1,IF(TxKvaSuggested>0,TxKvaConnected*1000/3,0),0)) | AA13: =IF(S13<=$S$9,1,IF(S13=$S$9+1,IF(TxKvaSuggested>0,1,0),0))
A14: A | B14: 13 | C14: =IF($AA$16=1,$X$16,"") | D14: =IF($AA$16=1,$Y$16,"") | E14: =IF($AA$16=1,3,"") | F14: =IF($AA$16=1,ROUND($Z$16,0),"") | G14: =IF($AA$17=1,ROUND($Z$17,0),"") | L14: =IF($AA$17=1,3,"") | M14: =IF($AA$17=1,$Y$17,"") | N14: =IF($AA$17=1,$X$17,"") | O14: 14 | P14: A | S14: 3 | T14: =IF(S14<=$S$9,MATCH(S14-0.5,$T$3:$T$8,1),0) | U14: =IF(T14>0,S14-INDEX($T$3:$T$8,T14),0) | V14: =IF(T14>0,INDEX(Intake!$A$23:$A$28,T14),"") | W14: =IF(T14>0,IFERROR(VLOOKUP(V14,ModelTable,7,FALSE),1),1) | X14: =IF(T14>0,UPPER(V14)&" #"&U14,IF(S14=$S$9+1,IF(TxKvaSuggested>0,"XFMR "&TxKvaSuggested&" KVA - EV_SUB (208V)",""),"")) | Y14: =IF(T14>0,IFERROR(VLOOKUP(V14,ModelTable,6,FALSE),0),IF(S14=$S$9+1,IF(TxKvaSuggested>0,Panel!$F$38,0),0)) | Z14: =IF(T14>0,IFERROR(VLOOKUP(V14,ModelTable,11,FALSE),0)*480/SQRT(3),IF(S14=$S$9+1,IF(TxKvaSuggested>0,TxKvaConnected*1000/3,0),0)) | AA14: =IF(S14<=$S$9,1,IF(S14=$S$9+1,IF(TxKvaSuggested>0,1,0),0))
A15: B | B15: 15 | C15: =IF($AA$16=1,"---","") | H15: =IF($AA$16=1,ROUND($Z$16,0),"") | I15: =IF($AA$17=1,ROUND($Z$17,0),"") | N15: =IF($AA$17=1,"---","") | O15: 16 | P15: B | S15: 4 | T15: =IF(S15<=$S$9,MATCH(S15-0.5,$T$3:$T$8,1),0) | U15: =IF(T15>0,S15-INDEX($T$3:$T$8,T15),0) | V15: =IF(T15>0,INDEX(Intake!$A$23:$A$28,T15),"") | W15: =IF(T15>0,IFERROR(VLOOKUP(V15,ModelTable,7,FALSE),1),1) | X15: =IF(T15>0,UPPER(V15)&" #"&U15,IF(S15=$S$9+1,IF(TxKvaSuggested>0,"XFMR "&TxKvaSuggested&" KVA - EV_SUB (208V)",""),"")) | Y15: =IF(T15>0,IFERROR(VLOOKUP(V15,ModelTable,6,FALSE),0),IF(S15=$S$9+1,IF(TxKvaSuggested>0,Panel!$F$38,0),0)) | Z15: =IF(T15>0,IFERROR(VLOOKUP(V15,ModelTable,11,FALSE),0)*480/SQRT(3),IF(S15=$S$9+1,IF(TxKvaSuggested>0,TxKvaConnected*1000/3,0),0)) | AA15: =IF(S15<=$S$9,1,IF(S15=$S$9+1,IF(TxKvaSuggested>0,1,0),0))
A16: C | B16: 17 | C16: =IF($AA$16=1,"---","") | J16: =IF($AA$16=1,ROUND($Z$16,0),"") | K16: =IF($AA$17=1,ROUND($Z$17,0),"") | N16: =IF($AA$17=1,"---","") | O16: 18 | P16: C | S16: 5 | T16: =IF(S16<=$S$9,MATCH(S16-0.5,$T$3:$T$8,1),0) | U16: =IF(T16>0,S16-INDEX($T$3:$T$8,T16),0) | V16: =IF(T16>0,INDEX(Intake!$A$23:$A$28,T16),"") | W16: =IF(T16>0,IFERROR(VLOOKUP(V16,ModelTable,7,FALSE),1),1) | X16: =IF(T16>0,UPPER(V16)&" #"&U16,IF(S16=$S$9+1,IF(TxKvaSuggested>0,"XFMR "&TxKvaSuggested&" KVA - EV_SUB (208V)",""),"")) | Y16: =IF(T16>0,IFERROR(VLOOKUP(V16,ModelTable,6,FALSE),0),IF(S16=$S$9+1,IF(TxKvaSuggested>0,Panel!$F$38,0),0)) | Z16: =IF(T16>0,IFERROR(VLOOKUP(V16,ModelTable,11,FALSE),0)*480/SQRT(3),IF(S16=$S$9+1,IF(TxKvaSuggested>0,TxKvaConnected*1000/3,0),0)) | AA16: =IF(S16<=$S$9,1,IF(S16=$S$9+1,IF(TxKvaSuggested>0,1,0),0))
A17: A | B17: 19 | C17: =IF($AA$18=1,$X$18,"") | D17: =IF($AA$18=1,$Y$18,"") | E17: =IF($AA$18=1,3,"") | F17: =IF($AA$18=1,ROUND($Z$18,0),"") | G17: =IF($AA$19=1,ROUND($Z$19,0),"") | L17: =IF($AA$19=1,3,"") | M17: =IF($AA$19=1,$Y$19,"") | N17: =IF($AA$19=1,$X$19,"") | O17: 20 | P17: A | S17: 6 | T17: =IF(S17<=$S$9,MATCH(S17-0.5,$T$3:$T$8,1),0) | U17: =IF(T17>0,S17-INDEX($T$3:$T$8,T17),0) | V17: =IF(T17>0,INDEX(Intake!$A$23:$A$28,T17),"") | W17: =IF(T17>0,IFERROR(VLOOKUP(V17,ModelTable,7,FALSE),1),1) | X17: =IF(T17>0,UPPER(V17)&" #"&U17,IF(S17=$S$9+1,IF(TxKvaSuggested>0,"XFMR "&TxKvaSuggested&" KVA - EV_SUB (208V)",""),"")) | Y17: =IF(T17>0,IFERROR(VLOOKUP(V17,ModelTable,6,FALSE),0),IF(S17=$S$9+1,IF(TxKvaSuggested>0,Panel!$F$38,0),0)) | Z17: =IF(T17>0,IFERROR(VLOOKUP(V17,ModelTable,11,FALSE),0)*480/SQRT(3),IF(S17=$S$9+1,IF(TxKvaSuggested>0,TxKvaConnected*1000/3,0),0)) | AA17: =IF(S17<=$S$9,1,IF(S17=$S$9+1,IF(TxKvaSuggested>0,1,0),0))
A18: B | B18: 21 | C18: =IF($AA$18=1,"---","") | H18: =IF($AA$18=1,ROUND($Z$18,0),"") | I18: =IF($AA$19=1,ROUND($Z$19,0),"") | N18: =IF($AA$19=1,"---","") | O18: 22 | P18: B | S18: 7 | T18: =IF(S18<=$S$9,MATCH(S18-0.5,$T$3:$T$8,1),0) | U18: =IF(T18>0,S18-INDEX($T$3:$T$8,T18),0) | V18: =IF(T18>0,INDEX(Intake!$A$23:$A$28,T18),"") | W18: =IF(T18>0,IFERROR(VLOOKUP(V18,ModelTable,7,FALSE),1),1) | X18: =IF(T18>0,UPPER(V18)&" #"&U18,IF(S18=$S$9+1,IF(TxKvaSuggested>0,"XFMR "&TxKvaSuggested&" KVA - EV_SUB (208V)",""),"")) | Y18: =IF(T18>0,IFERROR(VLOOKUP(V18,ModelTable,6,FALSE),0),IF(S18=$S$9+1,IF(TxKvaSuggested>0,Panel!$F$38,0),0)) | Z18: =IF(T18>0,IFERROR(VLOOKUP(V18,ModelTable,11,FALSE),0)*480/SQRT(3),IF(S18=$S$9+1,IF(TxKvaSuggested>0,TxKvaConnected*1000/3,0),0)) | AA18: =IF(S18<=$S$9,1,IF(S18=$S$9+1,IF(TxKvaSuggested>0,1,0),0))
A19: C | B19: 23 | C19: =IF($AA$18=1,"---","") | J19: =IF($AA$18=1,ROUND($Z$18,0),"") | K19: =IF($AA$19=1,ROUND($Z$19,0),"") | N19: =IF($AA$19=1,"---","") | O19: 24 | P19: C | S19: 8 | T19: =IF(S19<=$S$9,MATCH(S19-0.5,$T$3:$T$8,1),0) | U19: =IF(T19>0,S19-INDEX($T$3:$T$8,T19),0) | V19: =IF(T19>0,INDEX(Intake!$A$23:$A$28,T19),"") | W19: =IF(T19>0,IFERROR(VLOOKUP(V19,ModelTable,7,FALSE),1),1) | X19: =IF(T19>0,UPPER(V19)&" #"&U19,IF(S19=$S$9+1,IF(TxKvaSuggested>0,"XFMR "&TxKvaSuggested&" KVA - EV_SUB (208V)",""),"")) | Y19: =IF(T19>0,IFERROR(VLOOKUP(V19,ModelTable,6,FALSE),0),IF(S19=$S$9+1,IF(TxKvaSuggested>0,Panel!$F$38,0),0)) | Z19: =IF(T19>0,IFERROR(VLOOKUP(V19,ModelTable,11,FALSE),0)*480/SQRT(3),IF(S19=$S$9+1,IF(TxKvaSuggested>0,TxKvaConnected*1000/3,0),0)) | AA19: =IF(S19<=$S$9,1,IF(S19=$S$9+1,IF(TxKvaSuggested>0,1,0),0))
A20: A | B20: 25 | C20: =IF($AA$20=1,$X$20,"") | D20: =IF($AA$20=1,$Y$20,"") | E20: =IF($AA$20=1,3,"") | F20: =IF($AA$20=1,ROUND($Z$20,0),"") | G20: =IF($AA$21=1,ROUND($Z$21,0),"") | L20: =IF($AA$21=1,3,"") | M20: =IF($AA$21=1,$Y$21,"") | N20: =IF($AA$21=1,$X$21,"") | O20: 26 | P20: A | S20: 9 | T20: =IF(S20<=$S$9,MATCH(S20-0.5,$T$3:$T$8,1),0) | U20: =IF(T20>0,S20-INDEX($T$3:$T$8,T20),0) | V20: =IF(T20>0,INDEX(Intake!$A$23:$A$28,T20),"") | W20: =IF(T20>0,IFERROR(VLOOKUP(V20,ModelTable,7,FALSE),1),1) | X20: =IF(T20>0,UPPER(V20)&" #"&U20,IF(S20=$S$9+1,IF(TxKvaSuggested>0,"XFMR "&TxKvaSuggested&" KVA - EV_SUB (208V)",""),"")) | Y20: =IF(T20>0,IFERROR(VLOOKUP(V20,ModelTable,6,FALSE),0),IF(S20=$S$9+1,IF(TxKvaSuggested>0,Panel!$F$38,0),0)) | Z20: =IF(T20>0,IFERROR(VLOOKUP(V20,ModelTable,11,FALSE),0)*480/SQRT(3),IF(S20=$S$9+1,IF(TxKvaSuggested>0,TxKvaConnected*1000/3,0),0)) | AA20: =IF(S20<=$S$9,1,IF(S20=$S$9+1,IF(TxKvaSuggested>0,1,0),0))
A21: B | B21: 27 | C21: =IF($AA$20=1,"---","") | H21: =IF($AA$20=1,ROUND($Z$20,0),"") | I21: =IF($AA$21=1,ROUND($Z$21,0),"") | N21: =IF($AA$21=1,"---","") | O21: 28 | P21: B | S21: 10 | T21: =IF(S21<=$S$9,MATCH(S21-0.5,$T$3:$T$8,1),0) | U21: =IF(T21>0,S21-INDEX($T$3:$T$8,T21),0) | V21: =IF(T21>0,INDEX(Intake!$A$23:$A$28,T21),"") | W21: =IF(T21>0,IFERROR(VLOOKUP(V21,ModelTable,7,FALSE),1),1) | X21: =IF(T21>0,UPPER(V21)&" #"&U21,IF(S21=$S$9+1,IF(TxKvaSuggested>0,"XFMR "&TxKvaSuggested&" KVA - EV_SUB (208V)",""),"")) | Y21: =IF(T21>0,IFERROR(VLOOKUP(V21,ModelTable,6,FALSE),0),IF(S21=$S$9+1,IF(TxKvaSuggested>0,Panel!$F$38,0),0)) | Z21: =IF(T21>0,IFERROR(VLOOKUP(V21,ModelTable,11,FALSE),0)*480/SQRT(3),IF(S21=$S$9+1,IF(TxKvaSuggested>0,TxKvaConnected*1000/3,0),0)) | AA21: =IF(S21<=$S$9,1,IF(S21=$S$9+1,IF(TxKvaSuggested>0,1,0),0))
A22: C | B22: 29 | C22: =IF($AA$20=1,"---","") | J22: =IF($AA$20=1,ROUND($Z$20,0),"") | K22: =IF($AA$21=1,ROUND($Z$21,0),"") | N22: =IF($AA$21=1,"---","") | O22: 30 | P22: C | S22: 11 | T22: =IF(S22<=$S$9,MATCH(S22-0.5,$T$3:$T$8,1),0) | U22: =IF(T22>0,S22-INDEX($T$3:$T$8,T22),0) | V22: =IF(T22>0,INDEX(Intake!$A$23:$A$28,T22),"") | W22: =IF(T22>0,IFERROR(VLOOKUP(V22,ModelTable,7,FALSE),1),1) | X22: =IF(T22>0,UPPER(V22)&" #"&U22,IF(S22=$S$9+1,IF(TxKvaSuggested>0,"XFMR "&TxKvaSuggested&" KVA - EV_SUB (208V)",""),"")) | Y22: =IF(T22>0,IFERROR(VLOOKUP(V22,ModelTable,6,FALSE),0),IF(S22=$S$9+1,IF(TxKvaSuggested>0,Panel!$F$38,0),0)) | Z22: =IF(T22>0,IFERROR(VLOOKUP(V22,ModelTable,11,FALSE),0)*480/SQRT(3),IF(S22=$S$9+1,IF(TxKvaSuggested>0,TxKvaConnected*1000/3,0),0)) | AA22: =IF(S22<=$S$9,1,IF(S22=$S$9+1,IF(TxKvaSuggested>0,1,0),0))
A23: A | B23: 31 | C23: =IF($AA$22=1,$X$22,"") | D23: =IF($AA$22=1,$Y$22,"") | E23: =IF($AA$22=1,3,"") | F23: =IF($AA$22=1,ROUND($Z$22,0),"") | G23: =IF($AA$23=1,ROUND($Z$23,0),"") | L23: =IF($AA$23=1,3,"") | M23: =IF($AA$23=1,$Y$23,"") | N23: =IF($AA$23=1,$X$23,"") | O23: 32 | P23: A | S23: 12 | T23: =IF(S23<=$S$9,MATCH(S23-0.5,$T$3:$T$8,1),0) | U23: =IF(T23>0,S23-INDEX($T$3:$T$8,T23),0) | V23: =IF(T23>0,INDEX(Intake!$A$23:$A$28,T23),"") | W23: =IF(T23>0,IFERROR(VLOOKUP(V23,ModelTable,7,FALSE),1),1) | X23: =IF(T23>0,UPPER(V23)&" #"&U23,IF(S23=$S$9+1,IF(TxKvaSuggested>0,"XFMR "&TxKvaSuggested&" KVA - EV_SUB (208V)",""),"")) | Y23: =IF(T23>0,IFERROR(VLOOKUP(V23,ModelTable,6,FALSE),0),IF(S23=$S$9+1,IF(TxKvaSuggested>0,Panel!$F$38,0),0)) | Z23: =IF(T23>0,IFERROR(VLOOKUP(V23,ModelTable,11,FALSE),0)*480/SQRT(3),IF(S23=$S$9+1,IF(TxKvaSuggested>0,TxKvaConnected*1000/3,0),0)) | AA23: =IF(S23<=$S$9,1,IF(S23=$S$9+1,IF(TxKvaSuggested>0,1,0),0))
A24: B | B24: 33 | C24: =IF($AA$22=1,"---","") | H24: =IF($AA$22=1,ROUND($Z$22,0),"") | I24: =IF($AA$23=1,ROUND($Z$23,0),"") | N24: =IF($AA$23=1,"---","") | O24: 34 | P24: B | S24: 13 | T24: =IF(S24<=$S$9,MATCH(S24-0.5,$T$3:$T$8,1),0) | U24: =IF(T24>0,S24-INDEX($T$3:$T$8,T24),0) | V24: =IF(T24>0,INDEX(Intake!$A$23:$A$28,T24),"") | W24: =IF(T24>0,IFERROR(VLOOKUP(V24,ModelTable,7,FALSE),1),1) | X24: =IF(T24>0,UPPER(V24)&" #"&U24,IF(S24=$S$9+1,IF(TxKvaSuggested>0,"XFMR "&TxKvaSuggested&" KVA - EV_SUB (208V)",""),"")) | Y24: =IF(T24>0,IFERROR(VLOOKUP(V24,ModelTable,6,FALSE),0),IF(S24=$S$9+1,IF(TxKvaSuggested>0,Panel!$F$38,0),0)) | Z24: =IF(T24>0,IFERROR(VLOOKUP(V24,ModelTable,11,FALSE),0)*480/SQRT(3),IF(S24=$S$9+1,IF(TxKvaSuggested>0,TxKvaConnected*1000/3,0),0)) | AA24: =IF(S24<=$S$9,1,IF(S24=$S$9+1,IF(TxKvaSuggested>0,1,0),0))
A25: C | B25: 35 | C25: =IF($AA$22=1,"---","") | J25: =IF($AA$22=1,ROUND($Z$22,0),"") | K25: =IF($AA$23=1,ROUND($Z$23,0),"") | N25: =IF($AA$23=1,"---","") | O25: 36 | P25: C | S25: 14 | T25: =IF(S25<=$S$9,MATCH(S25-0.5,$T$3:$T$8,1),0) | U25: =IF(T25>0,S25-INDEX($T$3:$T$8,T25),0) | V25: =IF(T25>0,INDEX(Intake!$A$23:$A$28,T25),"") | W25: =IF(T25>0,IFERROR(VLOOKUP(V25,ModelTable,7,FALSE),1),1) | X25: =IF(T25>0,UPPER(V25)&" #"&U25,IF(S25=$S$9+1,IF(TxKvaSuggested>0,"XFMR "&TxKvaSuggested&" KVA - EV_SUB (208V)",""),"")) | Y25: =IF(T25>0,IFERROR(VLOOKUP(V25,ModelTable,6,FALSE),0),IF(S25=$S$9+1,IF(TxKvaSuggested>0,Panel!$F$38,0),0)) | Z25: =IF(T25>0,IFERROR(VLOOKUP(V25,ModelTable,11,FALSE),0)*480/SQRT(3),IF(S25=$S$9+1,IF(TxKvaSuggested>0,TxKvaConnected*1000/3,0),0)) | AA25: =IF(S25<=$S$9,1,IF(S25=$S$9+1,IF(TxKvaSuggested>0,1,0),0))
A26: A | B26: 37 | C26: =IF($AA$24=1,$X$24,"") | D26: =IF($AA$24=1,$Y$24,"") | E26: =IF($AA$24=1,3,"") | F26: =IF($AA$24=1,ROUND($Z$24,0),"") | G26: =IF($AA$25=1,ROUND($Z$25,0),"") | L26: =IF($AA$25=1,3,"") | M26: =IF($AA$25=1,$Y$25,"") | N26: =IF($AA$25=1,$X$25,"") | O26: 38 | P26: A | S26: 15 | T26: =IF(S26<=$S$9,MATCH(S26-0.5,$T$3:$T$8,1),0) | U26: =IF(T26>0,S26-INDEX($T$3:$T$8,T26),0) | V26: =IF(T26>0,INDEX(Intake!$A$23:$A$28,T26),"") | W26: =IF(T26>0,IFERROR(VLOOKUP(V26,ModelTable,7,FALSE),1),1) | X26: =IF(T26>0,UPPER(V26)&" #"&U26,IF(S26=$S$9+1,IF(TxKvaSuggested>0,"XFMR "&TxKvaSuggested&" KVA - EV_SUB (208V)",""),"")) | Y26: =IF(T26>0,IFERROR(VLOOKUP(V26,ModelTable,6,FALSE),0),IF(S26=$S$9+1,IF(TxKvaSuggested>0,Panel!$F$38,0),0)) | Z26: =IF(T26>0,IFERROR(VLOOKUP(V26,ModelTable,11,FALSE),0)*480/SQRT(3),IF(S26=$S$9+1,IF(TxKvaSuggested>0,TxKvaConnected*1000/3,0),0)) | AA26: =IF(S26<=$S$9,1,IF(S26=$S$9+1,IF(TxKvaSuggested>0,1,0),0))
A27: B | B27: 39 | C27: =IF($AA$24=1,"---","") | H27: =IF($AA$24=1,ROUND($Z$24,0),"") | I27: =IF($AA$25=1,ROUND($Z$25,0),"") | N27: =IF($AA$25=1,"---","") | O27: 40 | P27: B | S27: 16 | T27: =IF(S27<=$S$9,MATCH(S27-0.5,$T$3:$T$8,1),0) | U27: =IF(T27>0,S27-INDEX($T$3:$T$8,T27),0) | V27: =IF(T27>0,INDEX(Intake!$A$23:$A$28,T27),"") | W27: =IF(T27>0,IFERROR(VLOOKUP(V27,ModelTable,7,FALSE),1),1) | X27: =IF(T27>0,UPPER(V27)&" #"&U27,IF(S27=$S$9+1,IF(TxKvaSuggested>0,"XFMR "&TxKvaSuggested&" KVA - EV_SUB (208V)",""),"")) | Y27: =IF(T27>0,IFERROR(VLOOKUP(V27,ModelTable,6,FALSE),0),IF(S27=$S$9+1,IF(TxKvaSuggested>0,Panel!$F$38,0),0)) | Z27: =IF(T27>0,IFERROR(VLOOKUP(V27,ModelTable,11,FALSE),0)*480/SQRT(3),IF(S27=$S$9+1,IF(TxKvaSuggested>0,TxKvaConnected*1000/3,0),0)) | AA27: =IF(S27<=$S$9,1,IF(S27=$S$9+1,IF(TxKvaSuggested>0,1,0),0))
A28: C | B28: 41 | C28: =IF($AA$24=1,"---","") | J28: =IF($AA$24=1,ROUND($Z$24,0),"") | K28: =IF($AA$25=1,ROUND($Z$25,0),"") | N28: =IF($AA$25=1,"---","") | O28: 42 | P28: C
A29: A | B29: 43 | C29: =IF($AA$26=1,$X$26,"") | D29: =IF($AA$26=1,$Y$26,"") | E29: =IF($AA$26=1,3,"") | F29: =IF($AA$26=1,ROUND($Z$26,0),"") | G29: =IF($AA$27=1,ROUND($Z$27,0),"") | L29: =IF($AA$27=1,3,"") | M29: =IF($AA$27=1,$Y$27,"") | N29: =IF($AA$27=1,$X$27,"") | O29: 44 | P29: A
A30: B | B30: 45 | C30: =IF($AA$26=1,"---","") | H30: =IF($AA$26=1,ROUND($Z$26,0),"") | I30: =IF($AA$27=1,ROUND($Z$27,0),"") | N30: =IF($AA$27=1,"---","") | O30: 46 | P30: B
A31: C | B31: 47 | C31: =IF($AA$26=1,"---","") | J31: =IF($AA$26=1,ROUND($Z$26,0),"") | K31: =IF($AA$27=1,ROUND($Z$27,0),"") | N31: =IF($AA$27=1,"---","") | O31: 48 | P31: C
C33: TOTAL VA | F33: =SUM(F8:G31) | H33: =SUM(H8:I31) | J33: =SUM(J8:K31) | L33: TOTAL 3PH VA | N33: =F33+H33+J33
C34: DEMAND VA | F34: =F33*1.25 | H34: =H33*1.25 | J34: =J33*1.25 | L34: TOTAL DEMAND VA | N34: =N33*1.25
C35: HIGH PH VA | F35: =MAX($F$34,$H$34,$J$34) | H35: =MAX($F$34,$H$34,$J$34) | J35: =MAX($F$34,$H$34,$J$34) | L35: TOTAL AMP | N35: =N34/(480*SQRT(3))
C36: HIGH PH AMP | F36: =F35/(480/SQRT(3)) | H36: =H35/(480/SQRT(3)) | J36: =J35/(480/SQRT(3)) | L36: MAIN BREAKER | N36: =SgSuggested
B38: =IF($S$9+IF(TxKvaSuggested>0,1,0)>16,"⚠ More than 16 circuits — grid truncated, use the app's Excel export","")

Sheet Panel 208V
B1: PANEL SCHEDULE
R2: engine — do not edit
B3: NAME | C3: EV_SUB | D3: LOCATION | E3: OUTDOOR | H3: VOLTAGE | I3: 120 / 208 3PH 4W | M3: MAIN | N3: =Panel!$F$28&" A 3P" | S3: =IF(Intake!$D$23="L2",Intake!$B$23*IFERROR(VLOOKUP(Intake!$A$23,ModelTable,7,FALSE),0),0) | T3: 0
D4: FED BY | E4: =IF(TxKvaSuggested>0,"EV_MAIN VIA "&TxKvaSuggested&" KVA XFMR","UTILITY") | H4: ENCLOSURE | I4: NEMA3R | M4: BUS BAR | N4: =Panel!$F$28&" A" | S4: =IF(Intake!$D$24="L2",Intake!$B$24*IFERROR(VLOOKUP(Intake!$A$24,ModelTable,7,FALSE),0),0) | T4: =T3+S3
D5: MOUNTING | E5: SURFACE | H5: PANEL TYPE | I5: NF | M5: MAIN AIC | N5: 22,000 | S5: =IF(Intake!$D$25="L2",Intake!$B$25*IFERROR(VLOOKUP(Intake!$A$25,ModelTable,7,FALSE),0),0) | T5: =T4+S4
S6: =IF(Intake!$D$26="L2",Intake!$B$26*IFERROR(VLOOKUP(Intake!$A$26,ModelTable,7,FALSE),0),0) | T6: =T5+S5
B7: CKT | C7: DESCRIPTION | D7: BREAKER | E7: POLES | F7: A | H7: B | J7: C | L7: POLES | M7: BREAKER | N7: DESCRIPTION | O7: CKT | S7: =IF(Intake!$D$27="L2",Intake!$B$27*IFERROR(VLOOKUP(Intake!$A$27,ModelTable,7,FALSE),0),0) | T7: =T6+S6
A8: A | B8: 1 | C8: =IF($AA$12=1,$X$12,"") | D8: =IF($AA$12=1,$Y$12,"") | E8: =IF($AA$12=1,2,"") | F8: =IF($AA$12=1,ROUND($Z$12,0),"") | G8: =IF($AA$13=1,ROUND($Z$13,0),"") | L8: =IF($AA$13=1,2,"") | M8: =IF($AA$13=1,$Y$13,"") | N8: =IF($AA$13=1,$X$13,"") | O8: 2 | P8: A | S8: =IF(Intake!$D$28="L2",Intake!$B$28*IFERROR(VLOOKUP(Intake!$A$28,ModelTable,7,FALSE),0),0) | T8: =T7+S7
A9: B | B9: 3 | C9: =IF($AA$12=1,"---","") | H9: =IF($AA$12=1,ROUND($Z$12,0),"") | I9: =IF($AA$13=1,ROUND($Z$13,0),"") | N9: =IF($AA$13=1,"---","") | O9: 4 | P9: B | R9: total circuits | S9: =SUM(S3:S8)
A10: C | B10: 5 | C10: =IF($AA$14=1,$X$14,"") | D10: =IF($AA$14=1,$Y$14,"") | E10: =IF($AA$14=1,2,"") | J10: =IF($AA$14=1,ROUND($Z$14,0),"") | K10: =IF($AA$15=1,ROUND($Z$15,0),"") | L10: =IF($AA$15=1,2,"") | M10: =IF($AA$15=1,$Y$15,"") | N10: =IF($AA$15=1,$X$15,"") | O10: 6 | P10: C
A11: A | B11: 7 | C11: =IF($AA$14=1,"---","") | F11: =IF($AA$14=1,ROUND($Z$14,0),"") | G11: =IF($AA$15=1,ROUND($Z$15,0),"") | N11: =IF($AA$15=1,"---","") | O11: 8 | P11: A
A12: B | B12: 9 | C12: =IF($AA$16=1,$X$16,"") | D12: =IF($AA$16=1,$Y$16,"") | E12: =IF($AA$16=1,2,"") | H12: =IF($AA$16=1,ROUND($Z$16,0),"") | I12: =IF($AA$17=1,ROUND($Z$17,0),"") | L12: =IF($AA$17=1,2,"") | M12: =IF($AA$17=1,$Y$17,"") | N12: =IF($AA$17=1,$X$17,"") | O12: 10 | P12: B | S12: 1 | T12: =IF(S12<=$S$9,MATCH(S12-0.5,$T$3:$T$8,1),0) | U12: =IF(T12>0,S12-INDEX($T$3:$T$8,T12),0) | V12: =IF(T12>0,INDEX(Intake!$A$23:$A$28,T12),"") | W12: =IF(T12>0,IFERROR(VLOOKUP(V12,ModelTable,7,FALSE),1),1) | X12: =IF(T12>0,UPPER(V12)&" #"&ROUNDUP(U12/W12,0)&IF(W12>1,CHAR(64+U12-(ROUNDUP(U12/W12,0)-1)*W12),""),"") | Y12: =IF(T12>0,IFERROR(VLOOKUP(V12,ModelTable,6,FALSE),0),0) | Z12: =IF(T12>0,IFERROR(VLOOKUP(V12,ModelTable,11,FALSE),0)*208/2,0) | AA12: =IF(S12<=$S$9,1,0)
A13: C | B13: 11 | C13: =IF($AA$16=1,"---","") | J13: =IF($AA$16=1,ROUND($Z$16,0),"") | K13: =IF($AA$17=1,ROUND($Z$17,0),"") | N13: =IF($AA$17=1,"---","") | O13: 12 | P13: C | S13: 2 | T13: =IF(S13<=$S$9,MATCH(S13-0.5,$T$3:$T$8,1),0) | U13: =IF(T13>0,S13-INDEX($T$3:$T$8,T13),0) | V13: =IF(T13>0,INDEX(Intake!$A$23:$A$28,T13),"") | W13: =IF(T13>0,IFERROR(VLOOKUP(V13,ModelTable,7,FALSE),1),1) | X13: =IF(T13>0,UPPER(V13)&" #"&ROUNDUP(U13/W13,0)&IF(W13>1,CHAR(64+U13-(ROUNDUP(U13/W13,0)-1)*W13),""),"") | Y13: =IF(T13>0,IFERROR(VLOOKUP(V13,ModelTable,6,FALSE),0),0) | Z13: =IF(T13>0,IFERROR(VLOOKUP(V13,ModelTable,11,FALSE),0)*208/2,0) | AA13: =IF(S13<=$S$9,1,0)
A14: A | B14: 13 | C14: =IF($AA$18=1,$X$18,"") | D14: =IF($AA$18=1,$Y$18,"") | E14: =IF($AA$18=1,2,"") | F14: =IF($AA$18=1,ROUND($Z$18,0),"") | G14: =IF($AA$19=1,ROUND($Z$19,0),"") | L14: =IF($AA$19=1,2,"") | M14: =IF($AA$19=1,$Y$19,"") | N14: =IF($AA$19=1,$X$19,"") | O14: 14 | P14: A | S14: 3 | T14: =IF(S14<=$S$9,MATCH(S14-0.5,$T$3:$T$8,1),0) | U14: =IF(T14>0,S14-INDEX($T$3:$T$8,T14),0) | V14: =IF(T14>0,INDEX(Intake!$A$23:$A$28,T14),"") | W14: =IF(T14>0,IFERROR(VLOOKUP(V14,ModelTable,7,FALSE),1),1) | X14: =IF(T14>0,UPPER(V14)&" #"&ROUNDUP(U14/W14,0)&IF(W14>1,CHAR(64+U14-(ROUNDUP(U14/W14,0)-1)*W14),""),"") | Y14: =IF(T14>0,IFERROR(VLOOKUP(V14,ModelTable,6,FALSE),0),0) | Z14: =IF(T14>0,IFERROR(VLOOKUP(V14,ModelTable,11,FALSE),0)*208/2,0) | AA14: =IF(S14<=$S$9,1,0)
A15: B | B15: 15 | C15: =IF($AA$18=1,"---","") | H15: =IF($AA$18=1,ROUND($Z$18,0),"") | I15: =IF($AA$19=1,ROUND($Z$19,0),"") | N15: =IF($AA$19=1,"---","") | O15: 16 | P15: B | S15: 4 | T15: =IF(S15<=$S$9,MATCH(S15-0.5,$T$3:$T$8,1),0) | U15: =IF(T15>0,S15-INDEX($T$3:$T$8,T15),0) | V15: =IF(T15>0,INDEX(Intake!$A$23:$A$28,T15),"") | W15: =IF(T15>0,IFERROR(VLOOKUP(V15,ModelTable,7,FALSE),1),1) | X15: =IF(T15>0,UPPER(V15)&" #"&ROUNDUP(U15/W15,0)&IF(W15>1,CHAR(64+U15-(ROUNDUP(U15/W15,0)-1)*W15),""),"") | Y15: =IF(T15>0,IFERROR(VLOOKUP(V15,ModelTable,6,FALSE),0),0) | Z15: =IF(T15>0,IFERROR(VLOOKUP(V15,ModelTable,11,FALSE),0)*208/2,0) | AA15: =IF(S15<=$S$9,1,0)
A16: C | B16: 17 | C16: =IF($AA$20=1,$X$20,"") | D16: =IF($AA$20=1,$Y$20,"") | E16: =IF($AA$20=1,2,"") | J16: =IF($AA$20=1,ROUND($Z$20,0),"") | K16: =IF($AA$21=1,ROUND($Z$21,0),"") | L16: =IF($AA$21=1,2,"") | M16: =IF($AA$21=1,$Y$21,"") | N16: =IF($AA$21=1,$X$21,"") | O16: 18 | P16: C | S16: 5 | T16: =IF(S16<=$S$9,MATCH(S16-0.5,$T$3:$T$8,1),0) | U16: =IF(T16>0,S16-INDEX($T$3:$T$8,T16),0) | V16: =IF(T16>0,INDEX(Intake!$A$23:$A$28,T16),"") | W16: =IF(T16>0,IFERROR(VLOOKUP(V16,ModelTable,7,FALSE),1),1) | X16: =IF(T16>0,UPPER(V16)&" #"&ROUNDUP(U16/W16,0)&IF(W16>1,CHAR(64+U16-(ROUNDUP(U16/W16,0)-1)*W16),""),"") | Y16: =IF(T16>0,IFERROR(VLOOKUP(V16,ModelTable,6,FALSE),0),0) | Z16: =IF(T16>0,IFERROR(VLOOKUP(V16,ModelTable,11,FALSE),0)*208/2,0) | AA16: =IF(S16<=$S$9,1,0)
A17: A | B17: 19 | C17: =IF($AA$20=1,"---","") | F17: =IF($AA$20=1,ROUND($Z$20,0),"") | G17: =IF($AA$21=1,ROUND($Z$21,0),"") | N17: =IF($AA$21=1,"---","") | O17: 20 | P17: A | S17: 6 | T17: =IF(S17<=$S$9,MATCH(S17-0.5,$T$3:$T$8,1),0) | U17: =IF(T17>0,S17-INDEX($T$3:$T$8,T17),0) | V17: =IF(T17>0,INDEX(Intake!$A$23:$A$28,T17),"") | W17: =IF(T17>0,IFERROR(VLOOKUP(V17,ModelTable,7,FALSE),1),1) | X17: =IF(T17>0,UPPER(V17)&" #"&ROUNDUP(U17/W17,0)&IF(W17>1,CHAR(64+U17-(ROUNDUP(U17/W17,0)-1)*W17),""),"") | Y17: =IF(T17>0,IFERROR(VLOOKUP(V17,ModelTable,6,FALSE),0),0) | Z17: =IF(T17>0,IFERROR(VLOOKUP(V17,ModelTable,11,FALSE),0)*208/2,0) | AA17: =IF(S17<=$S$9,1,0)
A18: B | B18: 21 | C18: =IF($AA$22=1,$X$22,"") | D18: =IF($AA$22=1,$Y$22,"") | E18: =IF($AA$22=1,2,"") | H18: =IF($AA$22=1,ROUND($Z$22,0),"") | I18: =IF($AA$23=1,ROUND($Z$23,0),"") | L18: =IF($AA$23=1,2,"") | M18: =IF($AA$23=1,$Y$23,"") | N18: =IF($AA$23=1,$X$23,"") | O18: 22 | P18: B | S18: 7 | T18: =IF(S18<=$S$9,MATCH(S18-0.5,$T$3:$T$8,1),0) | U18: =IF(T18>0,S18-INDEX($T$3:$T$8,T18),0) | V18: =IF(T18>0,INDEX(Intake!$A$23:$A$28,T18),"") | W18: =IF(T18>0,IFERROR(VLOOKUP(V18,ModelTable,7,FALSE),1),1) | X18: =IF(T18>0,UPPER(V18)&" #"&ROUNDUP(U18/W18,0)&IF(W18>1,CHAR(64+U18-(ROUNDUP(U18/W18,0)-1)*W18),""),"") | Y18: =IF(T18>0,IFERROR(VLOOKUP(V18,ModelTable,6,FALSE),0),0) | Z18: =IF(T18>0,IFERROR(VLOOKUP(V18,ModelTable,11,FALSE),0)*208/2,0) | AA18: =IF(S18<=$S$9,1,0)
A19: C | B19: 23 | C19: =IF($AA$22=1,"---","") | J19: =IF($AA$22=1,ROUND($Z$22,0),"") | K19: =IF($AA$23=1,ROUND($Z$23,0),"") | N19: =IF($AA$23=1,"---","") | O19: 24 | P19: C | S19: 8 | T19: =IF(S19<=$S$9,MATCH(S19-0.5,$T$3:$T$8,1),0) | U19: =IF(T19>0,S19-INDEX($T$3:$T$8,T19),0) | V19: =IF(T19>0,INDEX(Intake!$A$23:$A$28,T19),"") | W19: =IF(T19>0,IFERROR(VLOOKUP(V19,ModelTable,7,FALSE),1),1) | X19: =IF(T19>0,UPPER(V19)&" #"&ROUNDUP(U19/W19,0)&IF(W19>1,CHAR(64+U19-(ROUNDUP(U19/W19,0)-1)*W19),""),"") | Y19: =IF(T19>0,IFERROR(VLOOKUP(V19,ModelTable,6,FALSE),0),0) | Z19: =IF(T19>0,IFERROR(VLOOKUP(V19,ModelTable,11,FALSE),0)*208/2,0) | AA19: =IF(S19<=$S$9,1,0)
A20: A | B20: 25 | C20: =IF($AA$24=1,$X$24,"") | D20: =IF($AA$24=1,$Y$24,"") | E20: =IF($AA$24=1,2,"") | F20: =IF($AA$24=1,ROUND($Z$24,0),"") | G20: =IF($AA$25=1,ROUND($Z$25,0),"") | L20: =IF($AA$25=1,2,"") | M20: =IF($AA$25=1,$Y$25,"") | N20: =IF($AA$25=1,$X$25,"") | O20: 26 | P20: A | S20: 9 | T20: =IF(S20<=$S$9,MATCH(S20-0.5,$T$3:$T$8,1),0) | U20: =IF(T20>0,S20-INDEX($T$3:$T$8,T20),0) | V20: =IF(T20>0,INDEX(Intake!$A$23:$A$28,T20),"") | W20: =IF(T20>0,IFERROR(VLOOKUP(V20,ModelTable,7,FALSE),1),1) | X20: =IF(T20>0,UPPER(V20)&" #"&ROUNDUP(U20/W20,0)&IF(W20>1,CHAR(64+U20-(ROUNDUP(U20/W20,0)-1)*W20),""),"") | Y20: =IF(T20>0,IFERROR(VLOOKUP(V20,ModelTable,6,FALSE),0),0) | Z20: =IF(T20>0,IFERROR(VLOOKUP(V20,ModelTable,11,FALSE),0)*208/2,0) | AA20: =IF(S20<=$S$9,1,0)
A21: B | B21: 27 | C21: =IF($AA$24=1,"---","") | H21: =IF($AA$24=1,ROUND($Z$24,0),"") | I21: =IF($AA$25=1,ROUND($Z$25,0),"") | N21: =IF($AA$25=1,"---","") | O21: 28 | P21: B | S21: 10 | T21: =IF(S21<=$S$9,MATCH(S21-0.5,$T$3:$T$8,1),0) | U21: =IF(T21>0,S21-INDEX($T$3:$T$8,T21),0) | V21: =IF(T21>0,INDEX(Intake!$A$23:$A$28,T21),"") | W21: =IF(T21>0,IFERROR(VLOOKUP(V21,ModelTable,7,FALSE),1),1) | X21: =IF(T21>0,UPPER(V21)&" #"&ROUNDUP(U21/W21,0)&IF(W21>1,CHAR(64+U21-(ROUNDUP(U21/W21,0)-1)*W21),""),"") | Y21: =IF(T21>0,IFERROR(VLOOKUP(V21,ModelTable,6,FALSE),0),0) | Z21: =IF(T21>0,IFERROR(VLOOKUP(V21,ModelTable,11,FALSE),0)*208/2,0) | AA21: =IF(S21<=$S$9,1,0)
A22: C | B22: 29 | C22: =IF($AA$26=1,$X$26,"") | D22: =IF($AA$26=1,$Y$26,"") | E22: =IF($AA$26=1,2,"") | J22: =IF($AA$26=1,ROUND($Z$26,0),"") | K22: =IF($AA$27=1,ROUND($Z$27,0),"") | L22: =IF($AA$27=1,2,"") | M22: =IF($AA$27=1,$Y$27,"") | N22: =IF($AA$27=1,$X$27,"") | O22: 30 | P22: C | S22: 11 | T22: =IF(S22<=$S$9,MATCH(S22-0.5,$T$3:$T$8,1),0) | U22: =IF(T22>0,S22-INDEX($T$3:$T$8,T22),0) | V22: =IF(T22>0,INDEX(Intake!$A$23:$A$28,T22),"") | W22: =IF(T22>0,IFERROR(VLOOKUP(V22,ModelTable,7,FALSE),1),1) | X22: =IF(T22>0,UPPER(V22)&" #"&ROUNDUP(U22/W22,0)&IF(W22>1,CHAR(64+U22-(ROUNDUP(U22/W22,0)-1)*W22),""),"") | Y22: =IF(T22>0,IFERROR(VLOOKUP(V22,ModelTable,6,FALSE),0),0) | Z22: =IF(T22>0,IFERROR(VLOOKUP(V22,ModelTable,11,FALSE),0)*208/2,0) | AA22: =IF(S22<=$S$9,1,0)
A23: A | B23: 31 | C23: =IF($AA$26=1,"---","") | F23: =IF($AA$26=1,ROUND($Z$26,0),"") | G23: =IF($AA$27=1,ROUND($Z$27,0),"") | N23: =IF($AA$27=1,"---","") | O23: 32 | P23: A | S23: 12 | T23: =IF(S23<=$S$9,MATCH(S23-0.5,$T$3:$T$8,1),0) | U23: =IF(T23>0,S23-INDEX($T$3:$T$8,T23),0) | V23: =IF(T23>0,INDEX(Intake!$A$23:$A$28,T23),"") | W23: =IF(T23>0,IFERROR(VLOOKUP(V23,ModelTable,7,FALSE),1),1) | X23: =IF(T23>0,UPPER(V23)&" #"&ROUNDUP(U23/W23,0)&IF(W23>1,CHAR(64+U23-(ROUNDUP(U23/W23,0)-1)*W23),""),"") | Y23: =IF(T23>0,IFERROR(VLOOKUP(V23,ModelTable,6,FALSE),0),0) | Z23: =IF(T23>0,IFERROR(VLOOKUP(V23,ModelTable,11,FALSE),0)*208/2,0) | AA23: =IF(S23<=$S$9,1,0)
A24: B | B24: 33 | C24: =IF($AA$28=1,$X$28,"") | D24: =IF($AA$28=1,$Y$28,"") | E24: =IF($AA$28=1,2,"") | H24: =IF($AA$28=1,ROUND($Z$28,0),"") | I24: =IF($AA$29=1,ROUND($Z$29,0),"") | L24: =IF($AA$29=1,2,"") | M24: =IF($AA$29=1,$Y$29,"") | N24: =IF($AA$29=1,$X$29,"") | O24: 34 | P24: B | S24: 13 | T24: =IF(S24<=$S$9,MATCH(S24-0.5,$T$3:$T$8,1),0) | U24: =IF(T24>0,S24-INDEX($T$3:$T$8,T24),0) | V24: =IF(T24>0,INDEX(Intake!$A$23:$A$28,T24),"") | W24: =IF(T24>0,IFERROR(VLOOKUP(V24,ModelTable,7,FALSE),1),1) | X24: =IF(T24>0,UPPER(V24)&" #"&ROUNDUP(U24/W24,0)&IF(W24>1,CHAR(64+U24-(ROUNDUP(U24/W24,0)-1)*W24),""),"") | Y24: =IF(T24>0,IFERROR(VLOOKUP(V24,ModelTable,6,FALSE),0),0) | Z24: =IF(T24>0,IFERROR(VLOOKUP(V24,ModelTable,11,FALSE),0)*208/2,0) | AA24: =IF(S24<=$S$9,1,0)
A25: C | B25: 35 | C25: =IF($AA$28=1,"---","") | J25: =IF($AA$28=1,ROUND($Z$28,0),"") | K25: =IF($AA$29=1,ROUND($Z$29,0),"") | N25: =IF($AA$29=1,"---","") | O25: 36 | P25: C | S25: 14 | T25: =IF(S25<=$S$9,MATCH(S25-0.5,$T$3:$T$8,1),0) | U25: =IF(T25>0,S25-INDEX($T$3:$T$8,T25),0) | V25: =IF(T25>0,INDEX(Intake!$A$23:$A$28,T25),"") | W25: =IF(T25>0,IFERROR(VLOOKUP(V25,ModelTable,7,FALSE),1),1) | X25: =IF(T25>0,UPPER(V25)&" #"&ROUNDUP(U25/W25,0)&IF(W25>1,CHAR(64+U25-(ROUNDUP(U25/W25,0)-1)*W25),""),"") | Y25: =IF(T25>0,IFERROR(VLOOKUP(V25,ModelTable,6,FALSE),0),0) | Z25: =IF(T25>0,IFERROR(VLOOKUP(V25,ModelTable,11,FALSE),0)*208/2,0) | AA25: =IF(S25<=$S$9,1,0)
A26: A | B26: 37 | C26: =IF($AA$30=1,$X$30,"") | D26: =IF($AA$30=1,$Y$30,"") | E26: =IF($AA$30=1,2,"") | F26: =IF($AA$30=1,ROUND($Z$30,0),"") | G26: =IF($AA$31=1,ROUND($Z$31,0),"") | L26: =IF($AA$31=1,2,"") | M26: =IF($AA$31=1,$Y$31,"") | N26: =IF($AA$31=1,$X$31,"") | O26: 38 | P26: A | S26: 15 | T26: =IF(S26<=$S$9,MATCH(S26-0.5,$T$3:$T$8,1),0) | U26: =IF(T26>0,S26-INDEX($T$3:$T$8,T26),0) | V26: =IF(T26>0,INDEX(Intake!$A$23:$A$28,T26),"") | W26: =IF(T26>0,IFERROR(VLOOKUP(V26,ModelTable,7,FALSE),1),1) | X26: =IF(T26>0,UPPER(V26)&" #"&ROUNDUP(U26/W26,0)&IF(W26>1,CHAR(64+U26-(ROUNDUP(U26/W26,0)-1)*W26),""),"") | Y26: =IF(T26>0,IFERROR(VLOOKUP(V26,ModelTable,6,FALSE),0),0) | Z26: =IF(T26>0,IFERROR(VLOOKUP(V26,ModelTable,11,FALSE),0)*208/2,0) | AA26: =IF(S26<=$S$9,1,0)
A27: B | B27: 39 | C27: =IF($AA$30=1,"---","") | H27: =IF($AA$30=1,ROUND($Z$30,0),"") | I27: =IF($AA$31=1,ROUND($Z$31,0),"") | N27: =IF($AA$31=1,"---","") | O27: 40 | P27: B | S27: 16 | T27: =IF(S27<=$S$9,MATCH(S27-0.5,$T$3:$T$8,1),0) | U27: =IF(T27>0,S27-INDEX($T$3:$T$8,T27),0) | V27: =IF(T27>0,INDEX(Intake!$A$23:$A$28,T27),"") | W27: =IF(T27>0,IFERROR(VLOOKUP(V27,ModelTable,7,FALSE),1),1) | X27: =IF(T27>0,UPPER(V27)&" #"&ROUNDUP(U27/W27,0)&IF(W27>1,CHAR(64+U27-(ROUNDUP(U27/W27,0)-1)*W27),""),"") | Y27: =IF(T27>0,IFERROR(VLOOKUP(V27,ModelTable,6,FALSE),0),0) | Z27: =IF(T27>0,IFERROR(VLOOKUP(V27,ModelTable,11,FALSE),0)*208/2,0) | AA27: =IF(S27<=$S$9,1,0)
A28: C | B28: 41 | C28: =IF($AA$32=1,$X$32,"") | D28: =IF($AA$32=1,$Y$32,"") | E28: =IF($AA$32=1,2,"") | J28: =IF($AA$32=1,ROUND($Z$32,0),"") | K28: =IF($AA$33=1,ROUND($Z$33,0),"") | L28: =IF($AA$33=1,2,"") | M28: =IF($AA$33=1,$Y$33,"") | N28: =IF($AA$33=1,$X$33,"") | O28: 42 | P28: C | S28: 17 | T28: =IF(S28<=$S$9,MATCH(S28-0.5,$T$3:$T$8,1),0) | U28: =IF(T28>0,S28-INDEX($T$3:$T$8,T28),0) | V28: =IF(T28>0,INDEX(Intake!$A$23:$A$28,T28),"") | W28: =IF(T28>0,IFERROR(VLOOKUP(V28,ModelTable,7,FALSE),1),1) | X28: =IF(T28>0,UPPER(V28)&" #"&ROUNDUP(U28/W28,0)&IF(W28>1,CHAR(64+U28-(ROUNDUP(U28/W28,0)-1)*W28),""),"") | Y28: =IF(T28>0,IFERROR(VLOOKUP(V28,ModelTable,6,FALSE),0),0) | Z28: =IF(T28>0,IFERROR(VLOOKUP(V28,ModelTable,11,FALSE),0)*208/2,0) | AA28: =IF(S28<=$S$9,1,0)
A29: A | B29: 43 | C29: =IF($AA$32=1,"---","") | F29: =IF($AA$32=1,ROUND($Z$32,0),"") | G29: =IF($AA$33=1,ROUND($Z$33,0),"") | N29: =IF($AA$33=1,"---","") | O29: 44 | P29: A | S29: 18 | T29: =IF(S29<=$S$9,MATCH(S29-0.5,$T$3:$T$8,1),0) | U29: =IF(T29>0,S29-INDEX($T$3:$T$8,T29),0) | V29: =IF(T29>0,INDEX(Intake!$A$23:$A$28,T29),"") | W29: =IF(T29>0,IFERROR(VLOOKUP(V29,ModelTable,7,FALSE),1),1) | X29: =IF(T29>0,UPPER(V29)&" #"&ROUNDUP(U29/W29,0)&IF(W29>1,CHAR(64+U29-(ROUNDUP(U29/W29,0)-1)*W29),""),"") | Y29: =IF(T29>0,IFERROR(VLOOKUP(V29,ModelTable,6,FALSE),0),0) | Z29: =IF(T29>0,IFERROR(VLOOKUP(V29,ModelTable,11,FALSE),0)*208/2,0) | AA29: =IF(S29<=$S$9,1,0)
A30: B | B30: 45 | C30: =IF($AA$34=1,$X$34,"") | D30: =IF($AA$34=1,$Y$34,"") | E30: =IF($AA$34=1,2,"") | H30: =IF($AA$34=1,ROUND($Z$34,0),"") | I30: =IF($AA$35=1,ROUND($Z$35,0),"") | L30: =IF($AA$35=1,2,"") | M30: =IF($AA$35=1,$Y$35,"") | N30: =IF($AA$35=1,$X$35,"") | O30: 46 | P30: B | S30: 19 | T30: =IF(S30<=$S$9,MATCH(S30-0.5,$T$3:$T$8,1),0) | U30: =IF(T30>0,S30-INDEX($T$3:$T$8,T30),0) | V30: =IF(T30>0,INDEX(Intake!$A$23:$A$28,T30),"") | W30: =IF(T30>0,IFERROR(VLOOKUP(V30,ModelTable,7,FALSE),1),1) | X30: =IF(T30>0,UPPER(V30)&" #"&ROUNDUP(U30/W30,0)&IF(W30>1,CHAR(64+U30-(ROUNDUP(U30/W30,0)-1)*W30),""),"") | Y30: =IF(T30>0,IFERROR(VLOOKUP(V30,ModelTable,6,FALSE),0),0) | Z30: =IF(T30>0,IFERROR(VLOOKUP(V30,ModelTable,11,FALSE),0)*208/2,0) | AA30: =IF(S30<=$S$9,1,0)
A31: C | B31: 47 | C31: =IF($AA$34=1,"---","") | J31: =IF($AA$34=1,ROUND($Z$34,0),"") | K31: =IF($AA$35=1,ROUND($Z$35,0),"") | N31: =IF($AA$35=1,"---","") | O31: 48 | P31: C | S31: 20 | T31: =IF(S31<=$S$9,MATCH(S31-0.5,$T$3:$T$8,1),0) | U31: =IF(T31>0,S31-INDEX($T$3:$T$8,T31),0) | V31: =IF(T31>0,INDEX(Intake!$A$23:$A$28,T31),"") | W31: =IF(T31>0,IFERROR(VLOOKUP(V31,ModelTable,7,FALSE),1),1) | X31: =IF(T31>0,UPPER(V31)&" #"&ROUNDUP(U31/W31,0)&IF(W31>1,CHAR(64+U31-(ROUNDUP(U31/W31,0)-1)*W31),""),"") | Y31: =IF(T31>0,IFERROR(VLOOKUP(V31,ModelTable,6,FALSE),0),0) | Z31: =IF(T31>0,IFERROR(VLOOKUP(V31,ModelTable,11,FALSE),0)*208/2,0) | AA31: =IF(S31<=$S$9,1,0)
S32: 21 | T32: =IF(S32<=$S$9,MATCH(S32-0.5,$T$3:$T$8,1),0) | U32: =IF(T32>0,S32-INDEX($T$3:$T$8,T32),0) | V32: =IF(T32>0,INDEX(Intake!$A$23:$A$28,T32),"") | W32: =IF(T32>0,IFERROR(VLOOKUP(V32,ModelTable,7,FALSE),1),1) | X32: =IF(T32>0,UPPER(V32)&" #"&ROUNDUP(U32/W32,0)&IF(W32>1,CHAR(64+U32-(ROUNDUP(U32/W32,0)-1)*W32),""),"") | Y32: =IF(T32>0,IFERROR(VLOOKUP(V32,ModelTable,6,FALSE),0),0) | Z32: =IF(T32>0,IFERROR(VLOOKUP(V32,ModelTable,11,FALSE),0)*208/2,0) | AA32: =IF(S32<=$S$9,1,0)
C33: TOTAL VA | F33: =SUM(F8:G31) | H33: =SUM(H8:I31) | J33: =SUM(J8:K31) | L33: TOTAL 3PH VA | N33: =F33+H33+J33 | S33: 22 | T33: =IF(S33<=$S$9,MATCH(S33-0.5,$T$3:$T$8,1),0) | U33: =IF(T33>0,S33-INDEX($T$3:$T$8,T33),0) | V33: =IF(T33>0,INDEX(Intake!$A$23:$A$28,T33),"") | W33: =IF(T33>0,IFERROR(VLOOKUP(V33,ModelTable,7,FALSE),1),1) | X33: =IF(T33>0,UPPER(V33)&" #"&ROUNDUP(U33/W33,0)&IF(W33>1,CHAR(64+U33-(ROUNDUP(U33/W33,0)-1)*W33),""),"") | Y33: =IF(T33>0,IFERROR(VLOOKUP(V33,ModelTable,6,FALSE),0),0) | Z33: =IF(T33>0,IFERROR(VLOOKUP(V33,ModelTable,11,FALSE),0)*208/2,0) | AA33: =IF(S33<=$S$9,1,0)
C34: DEMAND VA | F34: =F33*1.25 | H34: =H33*1.25 | J34: =J33*1.25 | L34: TOTAL DEMAND VA | N34: =N33*1.25 | S34: 23 | T34: =IF(S34<=$S$9,MATCH(S34-0.5,$T$3:$T$8,1),0) | U34: =IF(T34>0,S34-INDEX($T$3:$T$8,T34),0) | V34: =IF(T34>0,INDEX(Intake!$A$23:$A$28,T34),"") | W34: =IF(T34>0,IFERROR(VLOOKUP(V34,ModelTable,7,FALSE),1),1) | X34: =IF(T34>0,UPPER(V34)&" #"&ROUNDUP(U34/W34,0)&IF(W34>1,CHAR(64+U34-(ROUNDUP(U34/W34,0)-1)*W34),""),"") | Y34: =IF(T34>0,IFERROR(VLOOKUP(V34,ModelTable,6,FALSE),0),0) | Z34: =IF(T34>0,IFERROR(VLOOKUP(V34,ModelTable,11,FALSE),0)*208/2,0) | AA34: =IF(S34<=$S$9,1,0)
C35: HIGH PH VA | F35: =MAX($F$34,$H$34,$J$34) | H35: =MAX($F$34,$H$34,$J$34) | J35: =MAX($F$34,$H$34,$J$34) | L35: TOTAL AMP | N35: =N34/(208*SQRT(3)) | S35: 24 | T35: =IF(S35<=$S$9,MATCH(S35-0.5,$T$3:$T$8,1),0) | U35: =IF(T35>0,S35-INDEX($T$3:$T$8,T35),0) | V35: =IF(T35>0,INDEX(Intake!$A$23:$A$28,T35),"") | W35: =IF(T35>0,IFERROR(VLOOKUP(V35,ModelTable,7,FALSE),1),1) | X35: =IF(T35>0,UPPER(V35)&" #"&ROUNDUP(U35/W35,0)&IF(W35>1,CHAR(64+U35-(ROUNDUP(U35/W35,0)-1)*W35),""),"") | Y35: =IF(T35>0,IFERROR(VLOOKUP(V35,ModelTable,6,FALSE),0),0) | Z35: =IF(T35>0,IFERROR(VLOOKUP(V35,ModelTable,11,FALSE),0)*208/2,0) | AA35: =IF(S35<=$S$9,1,0)
C36: HIGH PH AMP | F36: =F35/120 | H36: =H35/120 | J36: =J35/120 | L36: MAIN BREAKER | N36: =Panel!$F$28
B38: =IF($S$9>24,"⚠ More than 24 circuits — grid truncated, use the app's Excel export","")

Sheet Estimate
A1: Budgetary Estimate (auto from Intake + Panel + RateCard)
A2: Structure mirrors the RFC_V18 Costs Internal → Summary chain. For the engineered takeoff use the app's Excel export.
A4: Construction labor days (derived) | B4: =IF(NTotal<=0,0,ROUNDUP((8+2.5*NDcfc+1*NumL2+TrenchFt/40)*VLOOKUP(Terrain,TerrainTable,3,FALSE),0))
A6: Electrical supply & construction
A7: Electrical make-ready (wire, conduit, install hardware) | B7: =SUM(Intake!E23:E28)
A8: Switchgear, panels & transformer (Panel sheet) | B8: =GearTotal
A9: Trenching / asphalt cut (terrain-adjusted) | B9: =TrenchFt*TrenchRate*VLOOKUP(Terrain,TerrainTable,2,FALSE)
A10: Civil (concrete, rebar, wheel stops) | B10: =IF(NTotal>0,CivilBase,0)+NDcfc*CivilDcfc+NumL2*CivilL2
A11: Signage, striping & bollards | B11: =NDcfc*SignageDcfc+NumL2*SignageL2
A12: Accessible EVCS stalls + ramp (ADA sheet) | B12: =AdaCost
A13: Spoils haul-off / dump | B13: =TrenchFt*VLOOKUP(Terrain,TerrainTable,5,FALSE)
A14: Private utility scan (GPR) | B14: =IF(IncGpr="Yes",MAX(1,ROUNDUP(TrenchFt/GprFtPerDay,0))*GprDayRate,0)
A15: Equipment rentals | B15: =IF(NTotal>0,EquipBase+EquipPerDay*LaborDays,0)
A16: Permit issuance (AHJ) | B16: =IF(IncPermits="Yes",200+60*NTotal,0)
A17: Utility application + transformer pad | B17: =IF(IncPermits="Yes",IF(NDcfc>0,2500+TransformerPad,800),0)
A18: Construction subtotal | B18: =SUM(B7:B17)
A19: Contingency | B19: =B18*ContingencyPct
A20: Construction total (loaded) | B20: =B18+B19
A22: Labor (days × rate, contingency-loaded) | B22: =LaborDays*LaborDayRate*(1+ContingencyPct)
A23: Sales tax on construction | B23: =ConstructionTotal*TaxPct
A24: Permit valuation (construction + labor) | B24: =ConstructionTotal+LaborCost
A26: Equipment purchase invoice
A27: Charger hardware (RateCard × price factor) | B27: =IF(IncHardware="Yes",SUM(Intake!F23:F28)*HardwareFactor,0)
A28: Commissioning | B28: =IF(IncHardware="Yes",CommDcfc*NDcfc+CommL2*NumL2,0)
A29: Network (EVOLV) fees — ports × $/mo × contract | B29: =IF(IncHardware="Yes",NPorts*NetworkFeeMo*12*ContractYears,0)
A30: Service plan over contract (post-warranty years) | B30: =IF(IncHardware="Yes",ServicePlanYr*ContractYears,0)
A31: Sales tax on charger hardware | B31: =B27*TaxPct
A33: Design invoice
A34: Site plan design (AutoCAD) | B34: =IF(IncSitePlan="Yes",2500+150*NTotal+IF(NDcfc>0,1000,0),0)
A35: SLD / electrical engineering (PE) | B35: =IF(IncSLD="Yes",IF(NDcfc>0,6000+900*NDcfc+150*NumL2,2500+150*NumL2),0)
A36: Construction PM — hours in col C | B36: =C36*PmRate | C36: =IF(IncCpm="Yes",MAX(24,ROUND(CpmPct*Valuation/PmRate,0)),0)
A37: Plan check (AHJ, % of valuation for DCFC) | B37: =IF(IncPermits="Yes",IF(NDcfc>0,500+0.02*Valuation,300),0)
A38: Design subtotal | B38: =SUM(B34:B37)
A40: TOTAL PROJECT COST | B40: =ConstructionTotal+LaborCost+B23+B27+B28+B29+B30+B31+B38
A41: Less: rebates / incentives (CALeVIP etc.) | B41: =-RebateAmt
A42: CUSTOMER TOTAL (after rebate) | B42: =TotalCost-RebateAmt

Sheet Revenue
A1: Revenue & Payback (the Hoopa RFC revenue model, formula-driven)
A2: kWh/day = ports × occupancy × operating hours × charging% × port kW × derate. Credits = LCFS $/kW/yr on DCFC.
A4: Retail price $/kWh | B4: 0.65
A5: Utility cost $/kWh | B5: 0.4
A6: Hours of operation / day | B6: 12
A7: Stall occupancy % | B7: 0.2
A8: Charging % per occupied hour | B8: 0.5
A9: Carbon credit $/kW/yr (DCFC, LCFS) | B9: 71.6667
A10: Charger derate factor | B10: 0.98
A12: Model | B12: Qty | C12: Ports | D12: kW/port | E12: kWh/day | F12: Rev $/day | G12: Net $/mo | H12: CC $/yr
A13: =IF(Intake!$B23>0,Intake!$A23,"") | B13: =IF(Intake!$B23>0,Intake!$B23,0) | C13: =Intake!$G23 | D13: =IF(B13>0,VLOOKUP(Intake!$A23,ModelTable,10,FALSE),0) | E13: =C13*OccPct*OpHours*ChargePct*D13*DerateF | F13: =E13*RetailKwh | G13: =E13*30*(RetailKwh-UtilityKwh) | H13: =IF(B13<=0,0,IF(VLOOKUP(Intake!$A23,ModelTable,4,FALSE)="DCFC",B13*D13*CcRate,0))
A14: =IF(Intake!$B24>0,Intake!$A24,"") | B14: =IF(Intake!$B24>0,Intake!$B24,0) | C14: =Intake!$G24 | D14: =IF(B14>0,VLOOKUP(Intake!$A24,ModelTable,10,FALSE),0) | E14: =C14*OccPct*OpHours*ChargePct*D14*DerateF | F14: =E14*RetailKwh | G14: =E14*30*(RetailKwh-UtilityKwh) | H14: =IF(B14<=0,0,IF(VLOOKUP(Intake!$A24,ModelTable,4,FALSE)="DCFC",B14*D14*CcRate,0))
A15: =IF(Intake!$B25>0,Intake!$A25,"") | B15: =IF(Intake!$B25>0,Intake!$B25,0) | C15: =Intake!$G25 | D15: =IF(B15>0,VLOOKUP(Intake!$A25,ModelTable,10,FALSE),0) | E15: =C15*OccPct*OpHours*ChargePct*D15*DerateF | F15: =E15*RetailKwh | G15: =E15*30*(RetailKwh-UtilityKwh) | H15: =IF(B15<=0,0,IF(VLOOKUP(Intake!$A25,ModelTable,4,FALSE)="DCFC",B15*D15*CcRate,0))
A16: =IF(Intake!$B26>0,Intake!$A26,"") | B16: =IF(Intake!$B26>0,Intake!$B26,0) | C16: =Intake!$G26 | D16: =IF(B16>0,VLOOKUP(Intake!$A26,ModelTable,10,FALSE),0) | E16: =C16*OccPct*OpHours*ChargePct*D16*DerateF | F16: =E16*RetailKwh | G16: =E16*30*(RetailKwh-UtilityKwh) | H16: =IF(B16<=0,0,IF(VLOOKUP(Intake!$A26,ModelTable,4,FALSE)="DCFC",B16*D16*CcRate,0))
A17: =IF(Intake!$B27>0,Intake!$A27,"") | B17: =IF(Intake!$B27>0,Intake!$B27,0) | C17: =Intake!$G27 | D17: =IF(B17>0,VLOOKUP(Intake!$A27,ModelTable,10,FALSE),0) | E17: =C17*OccPct*OpHours*ChargePct*D17*DerateF | F17: =E17*RetailKwh | G17: =E17*30*(RetailKwh-UtilityKwh) | H17: =IF(B17<=0,0,IF(VLOOKUP(Intake!$A27,ModelTable,4,FALSE)="DCFC",B17*D17*CcRate,0))
A18: =IF(Intake!$B28>0,Intake!$A28,"") | B18: =IF(Intake!$B28>0,Intake!$B28,0) | C18: =Intake!$G28 | D18: =IF(B18>0,VLOOKUP(Intake!$A28,ModelTable,10,FALSE),0) | E18: =C18*OccPct*OpHours*ChargePct*D18*DerateF | F18: =E18*RetailKwh | G18: =E18*30*(RetailKwh-UtilityKwh) | H18: =IF(B18<=0,0,IF(VLOOKUP(Intake!$A28,ModelTable,4,FALSE)="DCFC",B18*D18*CcRate,0))
A19: Totals | E19: =SUM(E13:E18) | G19: =SUM(G13:G18) | H19: =SUM(H13:H18)
A21: Charging net revenue / year | B21: =G19*12
A22: Carbon credits / year (DCFC) | B22: =H19
A23: Total annual benefit | B23: =RevenueYr+CcYr
A24: Benefit over the contract (flat, no escalation) | B24: =AnnualBenefit*ContractYears
A25: Simple payback (years) | B25: =IF(AnnualBenefit>0,ROUND(CustomerTotal/AnnualBenefit,1),"n/a")
A27: Assumptions from the Hoopa RFC 'standard-low' case (20% occupancy). Bump occupancy % for busier sites — their 'medium' case used 45-50%.

Sheet Financing
A1: Financing (DLL-style loan summary)
A3: Loan amount (customer total) | B3: =CustomerTotal
A4: Annual interest rate (Intake) | B4: =FinanceApr
A5: Term (years, Intake) | B5: =FinanceYears
A6: Monthly payment | B6: =IF(FinanceApr>0,-PMT(FinanceApr/12,FinanceYears*12,CustomerTotal),CustomerTotal/(FinanceYears*12))
A7: Total of payments | B7: =B6*FinanceYears*12
A8: Total interest | B8: =B7-B3
A10: Monthly revenue + credits (Revenue sheet) | B10: =AnnualBenefit/12
A11: Net monthly cashflow during the term | B11: =B10-B6
A13: Mirrors the DLL amortization summary in the Hoopa RFC (their deal: 8.39% APR × 60 months). Negative net cashflow = the site doesn't cover its own loan yet.

Sheet ADA
A1: Accessible EVCS — CBC 11B-812 (auto from Intake)
A3: Total chargers (from Intake) | B3: =NTotal
A4: Van accessible (12 ft + 5 ft aisle) | B4: =IF(NTotal<=0,0,IF(NTotal<=100,1,1+ROUNDUP((NTotal-100)/300,0)))
A5: Standard accessible (9 ft + 5 ft aisle) | B5: =IF(NTotal<=4,0,IF(NTotal<=50,1,IF(NTotal<=75,2,IF(NTotal<=100,3,3+ROUNDUP((NTotal-100)/60,0)))))
A6: Ambulatory (10 ft, no aisle) | B6: =IF(NTotal<=25,0,IF(NTotal<=50,1,IF(NTotal<=75,2,IF(NTotal<=100,3,3+ROUNDUP((NTotal-100)/50,0)))))
A7: Total accessible stalls | B7: =AdaVan+AdaStd+AdaAmb
A9: Terrain regrade factor (2% slope rule) | B9: =VLOOKUP(Terrain,TerrainTable,4,FALSE)
A10: ADA construction cost | B10: =(AdaVan*AdaVanCost+AdaStd*AdaStdCost+AdaAmb*AdaAmbCost)*VLOOKUP(Terrain,TerrainTable,4,FALSE)+IF(NTotal>0,AdaRampCost,0)
A13: CBC Table 11B-228.3.2.1 (2022 CBC — van divisor is 300; verify with your AHJ):
A14: Total EVCS | B14: Van | C14: Standard | D14: Ambulatory
A15: 1 – 4 | B15: 1 | C15: 0 | D15: 0
A16: 5 – 25 | B16: 1 | C16: 1 | D16: 0
A17: 26 – 50 | B17: 1 | C17: 1 | D17: 1
A18: 51 – 75 | B18: 1 | C18: 2 | D18: 2
A19: 76 – 100 | B19: 1 | C19: 3 | D19: 3
A20: 101+ | B20: 1 + 1/300 over 100 | C20: 3 + 1/60 over 100 | D20: 3 + 1/50 over 100
A22: • Slope ≤ 2% in every direction under stalls and aisles — regrading is the big cost on sloped lots.
A23: • EVCS markings must NOT be blue (11B-812.9); stencil 'EV CHARGING ONLY' in 12-in letters.
A24: • ISA signs: none if ≤4 EVCS; van space only for 5-25; all van + standard for 26+. Never on ambulatory.
A25: • Accessible EVCS do NOT count toward regular ADA parking minimums (11B-208.1).
A26: • Charger operable parts must sit 15-48 in from grade with 30×48 in clear floor space.

Sheet Timeline
A1: Schedule estimate (business days, auto from Intake)
A3: Phase | B3: Low | C3: High | D3: Note
A4: Site survey & utility scan | B4: =2 | C4: =4
A5: Site plan design (AutoCAD) | B5: =IF(IncSitePlan="Yes",5+ROUNDUP(NTotal/4,0),0) | C5: =IF(IncSitePlan="Yes",10+ROUNDUP(NTotal/4,0),0)
A6: SLD / electrical design (PE) | B6: =IF(IncSLD="Yes",IF(NDcfc>0,10+ROUNDUP(NDcfc/2,0),7),0) | C6: =IF(IncSLD="Yes",IF(NDcfc>0,17+ROUNDUP(NDcfc/2,0),14),0)
A7: Plan check & permits (AHJ) | B7: =IF(IncPermits="Yes",IF(NDcfc>0,20,5),0) | C7: =IF(IncPermits="Yes",IF(NDcfc>0,60,15),0) | D7: AB 970 clocks 20-40 days; real DCFC plan check 4-12 weeks
A8: Utility application & new service (PARALLEL) | B8: =IF(NDcfc>0,85,20) | C8: =IF(NDcfc>0,250,60) | D8: PG&E/SCE queues 4-12 months — usually the critical path on DCFC sites
A9: Construction | B9: =LaborDays | C9: =LaborDays+7
A10: Inspection & commissioning | B10: =5 | C10: =10
A12: End-to-end (sequential path vs parallel utility) | B12: =MAX(B4+B5+B6+B7+B9+B10,B8) | C12: =MAX(C4+C5+C6+C7+C9+C10,C8)
A13: ≈ months (21 business days/month) | B13: =ROUND(B12/21,1) | C13: =ROUND(C12/21,1)

Sheet RateCard
A1: Rate Card — every price the template uses. Edit the yellow cells; formulas follow.
A3: Model | B3: Hardware $/u | C3: Make-ready $/u | D3: Category | E3: Voltage | F3: Breaker A | G3: Circuits/u | H3: Unit input A | I3: Ports/u | J3: kW/port | K3: A/circuit | L3: Terrain | M3: Trench × | N3: Labor × | O3: ADA × | P3: Spoils $/ft
A4: L2 Single | B4: 3000 | C4: 795 | D4: L2 | E4: 208 | F4: 50 | G4: 1 | H4: 37 | I4: 1 | J4: 7.7 | K4: 37 | L4: flat | M4: 1 | N4: 1 | O4: 1 | P4: 5
A5: L2 Single 40A | B5: 4000 | C5: 879 | D5: L2 | E5: 208 | F5: 50 | G5: 1 | H5: 40 | I5: 1 | J5: 8.32 | K5: 40 | L5: sloped | M5: 1.2 | N5: 1.15 | O5: 1.4 | P5: 6
A6: L2 Dual | B6: 7500 | C6: 2367 | D6: L2 | E6: 208 | F6: 125 | G6: 2 | H6: 92.3 | I6: 2 | J6: 19.2 | K6: 92.3 | L6: hilly | M6: 1.5 | N6: 1.3 | O6: 1.7 | P6: 8
A7: L2 Dual 80A | B7: 6500 | C7: 1383 | D7: L2 | E7: 208 | F7: 50 | G7: 2 | H7: 80 | I7: 2 | J7: 8.32 | K7: 40 | L7: rocky | M7: 2.5 | N7: 1.5 | O7: 1.8 | P7: 12
A8: L2 Dual 32A | B8: 5500 | C8: 1198 | D8: L2 | E8: 208 | F8: 40 | G8: 2 | H8: 64 | I8: 2 | J8: 6.656 | K8: 32
A9: DCFC 50kW | B9: 32000 | C9: 1941 | D9: DCFC | E9: 480 | F9: 100 | G9: 1 | H9: 60.1 | I9: 1 | J9: 50 | K9: 60.1
A10: DCFC 60kW | B10: 38000 | C10: 1875 | D10: DCFC | E10: 480 | F10: 100 | G10: 1 | H10: 72.2 | I10: 1 | J10: 60 | K10: 72.2 | L10: Trenching $/ft (flat baseline) | M10: 40.81
A11: DCFC 100kW | B11: 52000 | C11: 2787 | D11: DCFC | E11: 480 | F11: 200 | G11: 1 | H11: 120.3 | I11: 1 | J11: 100 | K11: 120.3 | L11: Contingency % | M11: 0.1
A12: DCFC 120kW | B12: 60000 | C12: 2692 | D12: DCFC | E12: 480 | F12: 200 | G12: 1 | H12: 144.3 | I12: 1 | J12: 120 | K12: 144.3 | L12: Sales tax % | M12: 0.0725
A13: DCFC 160kW | B13: 72000 | C13: 4288 | D13: DCFC | E13: 480 | F13: 300 | G13: 1 | H13: 192.5 | I13: 1 | J13: 160 | K13: 192.5 | L13: Labor crew $/day | M13: 2250
